Workbook

Sheet Cobranza
A1: ITEM | B1: NOMBRES | C1: MZ | D1: LT | E1: TIPO CONVENIO | F1: MAYOR 65 | G1: NO COBRO | H1: Costo x m3 | I1: MARCACION ACTUAL | K1: M3 | L1: Mes actual | M1: MES ANTERIOR | N1: Corte y reconexión | O1: Convenio | P1: Mant. | Q1: Reunión | R1: faena | S1: Ajuste | T1: Total | U1: Estado | V1: Fecha | W1: Medio | X1: Mes anterior | Y1: Comentario | Z1: Estado del servicio | AA1: corte | AB1: Efectivo | AC1: Yape | AD1: contador yape
A2: 1 | B2: MARCELINA OBREGON DE AVILA | C2: A | D2: 1 | H2: 1 | I2: 2599 | J2: 2607 | K2: =J2-I2 -> 8 | L2: 8 | M2: 11 | N2: 0 | O2: 0 | P2: 3 | Q2: 0 | R2: 0 | T2: =SUM(L2:S2) -> 22 | U2: c | W2: y | AA2: =IF(AND(L2>0, M2>=8, NOT(OR(U2="C", U2="c"))), "CORTE", "") | AB2: =IF(AND(LEN(U2)>0,LEN(W2)=0),T2,0) -> 0 | AC2: =IF(AND(LEN(U2)>0,TRIM(W2)="Y"),T2,0) -> 22 | AD2: =IF(ISBLANK(W2),0,1) -> 1
A3: 2 | B3: ROSA AURORA ROCA VIDAL | C3: A | D3: 2 | H3: 1 | I3: 2575 | J3: 2600 | K3: =J3-I3 -> 25 | L3: 25 | M3: 0 | N3: 0 | O3: 0 | P3: 3 | Q3: 0 | R3: 0 | T3: =SUM(L3:S3) -> 28 | AA3: =IF(AND(L3>0, M3>=8, NOT(OR(U3="C", U3="c"))), "CORTE", "") | AB3: =IF(AND(LEN(U3)>0,LEN(W3)=0),T3,0) -> 0 | AC3: =IF(AND(LEN(U3)>0,TRIM(W3)="Y"),T3,0) -> 0
A4: 3 | B4: LINDA PAJUELO COCHACHÍN | C4: A | D4: 3 | H4: 1 | I4: 22 | J4: 22 | K4: =J4-I4 -> 0 | L4: 5 | M4: 0 | N4: 0 | O4: 0 | P4: 3 | Q4: 0 | R4: 30 | T4: =SUM(L4:S4) -> 38 | U4: c | W4: y | AA4: =IF(AND(L4>0, M4>=8, NOT(OR(U4="C", U4="c"))), "CORTE", "") | AB4: =IF(AND(LEN(U4)>0,LEN(W4)=0),T4,0) -> 0 | AC4: =IF(AND(LEN(U4)>0,TRIM(W4)="Y"),T4,0) -> 38 | AD4: =IF(ISBLANK(W4),0,1) -> 1
A5: 4 | B5: YOLANDA ESPINOZA JAIMES | C5: A | D5: 4 | H5: 1 | I5: 1765 | J5: 1767 | K5: =J5-I5 -> 2 | L5: 5 | M5: 137 | N5: 40 | O5: 0 | P5: 3 | Q5: 40 | R5: 30 | T5: =SUM(L5:S5) -> 255 | Y5: No pago | AA5: =IF(AND(L5>0, M5>=8, NOT(OR(U5="C", U5="c"))), "CORTE", "") -> CORTE | AB5: =IF(AND(LEN(U5)>0,LEN(W5)=0),T5,0) -> 0 | AC5: =IF(AND(LEN(U5)>0,TRIM(W5)="Y"),T5,0) -> 0
A6: 5 | B6: JULIA AGAMA CUZCO | C6: A | D6: 5 | H6: 1 | I6: 3369 | J6: 3383 | K6: =J6-I6 -> 14 | L6: 14 | M6: 0 | N6: 0 | O6: 0 | P6: 3 | Q6: 0 | R6: 0 | T6: =SUM(L6:S6) -> 17 | U6: c | AA6: =IF(AND(L6>0, M6>=8, NOT(OR(U6="C", U6="c"))), "CORTE", "") | AB6: =IF(AND(LEN(U6)>0,LEN(W6)=0),T6,0) -> 17 | AC6: =IF(AND(LEN(U6)>0,TRIM(W6)="Y"),T6,0) -> 0 | AD6: =IF(ISBLANK(W6),0,1) -> 0
A7: 6 | B7: ESTEBAN REYES SANCHEZ | C7: A | D7: 6 | H7: 1 | I7: 1860 | J7: 1883 | K7: =J7-I7 -> 23 | L7: 23 | M7: 0 | N7: 0 | O7: 0 | P7: 3 | Q7: 0 | R7: 30 | T7: =SUM(L7:S7) -> 56 | U7: c | W7: y | AA7: =IF(AND(L7>0, M7>=8, NOT(OR(U7="C", U7="c"))), "CORTE", "") | AB7: =IF(AND(LEN(U7)>0,LEN(W7)=0),T7,0) -> 0 | AC7: =IF(AND(LEN(U7)>0,TRIM(W7)="Y"),T7,0) -> 56 | AD7: =IF(ISBLANK(W7),0,1) -> 1
A8: 7 | B8: JUAN CARLOS MELGAREJO BEDON | C8: A | D8: 7 | H8: 1 | I8: 1703 | J8: 1713 | K8: =J8-I8 -> 10 | L8: 10 | M8: 11 | N8: 0 | O8: 0 | P8: 3 | Q8: 0 | T8: =SUM(L8:S8) -> 24 | U8: c | W8: y | Y8: debe 30 faena | AA8: =IF(AND(L8>0, M8>=8, NOT(OR(U8="C", U8="c"))), "CORTE", "") | AB8: =IF(AND(LEN(U8)>0,LEN(W8)=0),T8,0) -> 0 | AC8: =IF(AND(LEN(U8)>0,TRIM(W8)="Y"),T8,0) -> 24 | AD8: =IF(ISBLANK(W8),0,1) -> 1
A9: 8 | B9: VICTOR MELGAREJO CORCINO | C9: A | D9: 8 | H9: 1 | I9: 6304 | J9: 6324 | K9: =J9-I9 -> 20 | L9: 20 | M9: 20 | N9: 0 | O9: 0 | P9: 3 | Q9: 0 | R9: 30 | T9: =SUM(L9:S9) -> 73 | U9: c | W9: y | AA9: =IF(AND(L9>0, M9>=8, NOT(OR(U9="C", U9="c"))), "CORTE", "") | AB9: =IF(AND(LEN(U9)>0,LEN(W9)=0),T9,0) -> 0 | AC9: =IF(AND(LEN(U9)>0,TRIM(W9)="Y"),T9,0) -> 73 | AD9: =IF(ISBLANK(W9),0,1) -> 1
A10: 9 | B10: JHONI MELGAREJO BEDON | C10: A | D10: 8-A | H10: 1 | I10: 148 | J10: 159 | K10: =J10-I10 -> 11 | L10: 11 | M10: 0 | N10: 0 | O10: 0 | P10: 3 | Q10: 0 | R10: 30 | T10: =SUM(L10:S10) -> 44 | AA10: =IF(AND(L10>0, M10>=8, NOT(OR(U10="C", U10="c"))), "CORTE", "") | AB10: =IF(AND(LEN(U10)>0,LEN(W10)=0),T10,0) -> 0 | AC10: =IF(AND(LEN(U10)>0,TRIM(W10)="Y"),T10,0) -> 0 | AD10: =IF(ISBLANK(W10),0,1) -> 0
A11: 10 | B11: ALEJANDRO MELGAREJO ESPINOZA | C11: A | D11: 9 | H11: 1 | I11: 2062 | J11: 2092 | K11: =J11-I11 -> 30 | L11: 30 | M11: 0 | N11: 0 | O11: 0 | P11: 3 | Q11: 0 | R11: 30 | T11: =SUM(L11:S11) -> 63 | U11: c | W11: y | AA11: =IF(AND(L11>0, M11>=8, NOT(OR(U11="C", U11="c"))), "CORTE", "") | AB11: =IF(AND(LEN(U11)>0,LEN(W11)=0),T11,0) -> 0 | AC11: =IF(AND(LEN(U11)>0,TRIM(W11)="Y"),T11,0) -> 63
A12: 11 | B12: ISABEL PUNTILLO VEGA | C12: A | D12: 10 | H12: 1 | I12: 581 | J12: 616 | K12: =J12-I12 -> 35 | M12: 22 | N12: 0 | O12: 0 | P12: 3 | Q12: 0 | R12: 0 | T12: =SUM(L12:S12) -> 25 | U12: c | W12: y | Y12: debe 30 faena, mes actual 35 | AA12: =IF(AND(L12>0, M12>=8, NOT(OR(U12="C", U12="c"))), "CORTE", "") | AB12: =IF(AND(LEN(U12)>0,LEN(W12)=0),T12,0) -> 0 | AC12: =IF(AND(LEN(U12)>0,TRIM(W12)="Y"),T12,0) -> 25
A13: 12 | B13: FELIX POZO CASTRO | C13: A | D13: 11 | H13: 1 | I13: 357 | J13: 358 | K13: =J13-I13 -> 1 | L13: 5 | M13: 0 | N13: 0 | O13: 0 | P13: 3 | Q13: 0 | R13: 30 | T13: =SUM(L13:S13) -> 38 | U13: c | W13: y | AA13: =IF(AND(L13>0, M13>=8, NOT(OR(U13="C", U13="c"))), "CORTE", "") | AB13: =IF(AND(LEN(U13)>0,LEN(W13)=0),T13,0) -> 0 | AC13: =IF(AND(LEN(U13)>0,TRIM(W13)="Y"),T13,0) -> 38 | AD13: =IF(ISBLANK(W13),0,1) -> 1
A14: 13 | B14: BACILIO UTRILLA FRANCISCO | C14: B | D14: 1 | H14: 1 | I14: 2255 | J14: 2263 | K14: =J14-I14 -> 8 | L14: 8 | M14: 2 | N14: 0 | O14: 0 | P14: 3 | Q14: 0 | R14: 30 | T14: =SUM(L14:S14) -> 43 | U14: c | AA14: =IF(AND(L14>0, M14>=8, NOT(OR(U14="C", U14="c"))), "CORTE", "") | AB14: =IF(AND(LEN(U14)>0,LEN(W14)=0),T14,0) -> 43 | AC14: =IF(AND(LEN(U14)>0,TRIM(W14)="Y"),T14,0) -> 0 | AD14: =IF(ISBLANK(W14),0,1) -> 0
A15: 14 | B15: ESTEBAN REYNALDO ROSALES | C15: B | D15: 2 | H15: 1 | I15: 2260 | J15: 2271 | K15: =J15-I15 -> 11 | L15: 11 | M15: 0 | N15: 0 | O15: 0 | P15: 3 | Q15: 0 | R15: 30 | T15: =SUM(L15:S15) -> 44 | U15: c | AA15: =IF(AND(L15>0, M15>=8, NOT(OR(U15="C", U15="c"))), "CORTE", "") | AB15: =IF(AND(LEN(U15)>0,LEN(W15)=0),T15,0) -> 44 | AC15: =IF(AND(LEN(U15)>0,TRIM(W15)="Y"),T15,0) -> 0 | AD15: =IF(ISBLANK(W15),0,1) -> 0
A16: 15 | B16: EDUARDO REYNALDO ROSALES | C16: B | D16: 3 | H16: 1 | I16: 779 | J16: 786 | K16: =J16-I16 -> 7 | L16: 7 | M16: 0 | N16: 0 | O16: 0 | P16: 3 | Q16: 0 | R16: 30 | T16: =SUM(L16:S16) -> 40 | U16: c | AA16: =IF(AND(L16>0, M16>=8, NOT(OR(U16="C", U16="c"))), "CORTE", "") | AB16: =IF(AND(LEN(U16)>0,LEN(W16)=0),T16,0) -> 40 | AC16: =IF(AND(LEN(U16)>0,TRIM(W16)="Y"),T16,0) -> 0 | AD16: =IF(ISBLANK(W16),0,1) -> 0
A17: 16 | B17: MELINA J. JUAREZ TOLEDO DE MORENO | C17: B | D17: 4 | H17: 1 | I17: 567 | J17: 578 | K17: =J17-I17 -> 11 | L17: 11 | M17: 0 | N17: 0 | O17: 0 | P17: 3 | Q17: 0 | R17: 30 | T17: =SUM(L17:S17) -> 44 | U17: c | W17: y | AA17: =IF(AND(L17>0, M17>=8, NOT(OR(U17="C", U17="c"))), "CORTE", "") | AB17: =IF(AND(LEN(U17)>0,LEN(W17)=0),T17,0) -> 0 | AC17: =IF(AND(LEN(U17)>0,TRIM(W17)="Y"),T17,0) -> 44 | AD17: =IF(ISBLANK(W17),0,1) -> 1
A18: 17 | B18: POMPEYO CELESTINO LLIUYA | C18: B | D18: 5 | H18: 1 | I18: 5222 | J18: 5252 | K18: =J18-I18 -> 30 | L18: 30 | M18: -3 | N18: 0 | O18: 0 | P18: 3 | Q18: 0 | R18: 30 | T18: =SUM(L18:S18) -> 60 | AA18: =IF(AND(L18>0, M18>=8, NOT(OR(U18="C", U18="c"))), "CORTE", "") | AB18: =IF(AND(LEN(U18)>0,LEN(W18)=0),T18,0) -> 0 | AC18: =IF(AND(LEN(U18)>0,TRIM(W18)="Y"),T18,0) -> 0
A19: 18 | B19: ROSA VICTORIA MILLA MORALES | C19: B | D19: 6 | H19: 1 | I19: 3879 | J19: 3899 | K19: =J19-I19 -> 20 | L19: 20 | M19: 0 | N19: 0 | O19: 0 | P19: 3 | Q19: 0 | R19: 0 | T19: =SUM(L19:S19) -> 23 | U19: c | AA19: =IF(AND(L19>0, M19>=8, NOT(OR(U19="C", U19="c"))), "CORTE", "") | AB19: =IF(AND(LEN(U19)>0,LEN(W19)=0),T19,0) -> 23 | AC19: =IF(AND(LEN(U19)>0,TRIM(W19)="Y"),T19,0) -> 0 | AD19: =IF(ISBLANK(W19),0,1) -> 0
A20: 19 | B20: LIRIA PARIAMACHI DE PAZ | C20: B | D20: 7 | H20: 1 | I20: 2650 | J20: 2671 | K20: =J20-I20 -> 21 | L20: 21 | M20: 0 | N20: 0 | O20: 0 | P20: 3 | Q20: 0 | R20: 30 | T20: =SUM(L20:S20) -> 54 | AA20: =IF(AND(L20>0, M20>=8, NOT(OR(U20="C", U20="c"))), "CORTE", "") | AB20: =IF(AND(LEN(U20)>0,LEN(W20)=0),T20,0) -> 0 | AC20: =IF(AND(LEN(U20)>0,TRIM(W20)="Y"),T20,0) -> 0 | AD20: =IF(ISBLANK(W20),0,1) -> 0
A21: 20 | B21: ROSALINA OLIMPIA CIRIACO SOTELO | C21: B | D21: 8 | H21: 1 | I21: 6665 | J21: 6683 | K21: =J21-I21 -> 18 | L21: 18 | M21: 0 | N21: 0 | O21: 0 | P21: 3 | Q21: 0 | R21: 0 | T21: =SUM(L21:S21) -> 21 | AA21: =IF(AND(L21>0, M21>=8, NOT(OR(U21="C", U21="c"))), "CORTE", "") | AB21: =IF(AND(LEN(U21)>0,LEN(W21)=0),T21,0) -> 0 | AC21: =IF(AND(LEN(U21)>0,TRIM(W21)="Y"),T21,0) -> 0
A22: 21 | B22: ALEJANDRO RAPRAY VELASQUEZ | C22: B | D22: 9 | F22: 1 | H22: 1 | I22: 40 | J22: 48 | K22: =J22-I22 -> 8 | L22: 8 | M22: 0 | N22: 0 | O22: 0 | P22: 3 | Q22: 0 | R22: 30 | T22: =SUM(L22:S22) -> 41 | AA22: =IF(AND(L22>0, M22>=8, NOT(OR(U22="C", U22="c"))), "CORTE", "") | AB22: =IF(AND(LEN(U22)>0,LEN(W22)=0),T22,0) -> 0 | AC22: =IF(AND(LEN(U22)>0,TRIM(W22)="Y"),T22,0) -> 0
A23: 22 | B23: ELVIRA PASCUALA MINAYA TAHUA | C23: B | D23: 11 | H23: 1 | I23: 3031 | J23: 3050 | K23: =J23-I23 -> 19 | L23: 19 | M23: 16 | N23: 0 | O23: 0 | P23: 3 | Q23: 0 | R23: 0 | T23: =SUM(L23:S23) -> 38 | U23: c | AA23: =IF(AND(L23>0, M23>=8, NOT(OR(U23="C", U23="c"))), "CORTE", "") | AB23: =IF(AND(LEN(U23)>0,LEN(W23)=0),T23,0) -> 38 | AC23: =IF(AND(LEN(U23)>0,TRIM(W23)="Y"),T23,0) -> 0
A24: 23 | B24: MARCELINO FELIX VILLAFANA PALLACA | C24: B | D24: 10 | H24: 1 | I24: 355 | J24: 360 | K24: =J24-I24 -> 5 | L24: 5 | M24: 19 | N24: 0 | O24: 0 | P24: 3 | Q24: 0 | R24: 0 | T24: =SUM(L24:S24) -> 27 | U24: c | W24: y | AA24: =IF(AND(L24>0, M24>=8, NOT(OR(U24="C", U24="c"))), "CORTE", "") | AB24: =IF(AND(LEN(U24)>0,LEN(W24)=0),T24,0) -> 0 | AC24: =IF(AND(LEN(U24)>0,TRIM(W24)="Y"),T24,0) -> 27
A25: 24 | B25: TEOFILO BRUNO RAMOS DE LA CRUZ | C25: B | D25: 12 | H25: 1 | I25: 2369 | J25: 2374 | K25: =J25-I25 -> 5 | L25: 5 | M25: 0 | N25: 0 | O25: 0 | P25: 3 | Q25: 0 | R25: 30 | T25: =SUM(L25:S25) -> 38 | AA25: =IF(AND(L25>0, M25>=8, NOT(OR(U25="C", U25="c"))), "CORTE", "") | AB25: =IF(AND(LEN(U25)>0,LEN(W25)=0),T25,0) -> 0 | AC25: =IF(AND(LEN(U25)>0,TRIM(W25)="Y"),T25,0) -> 0 | AD25: =IF(ISBLANK(W25),0,1) -> 0
A26: 25 | B26: ROSMERI SANCHEZ ESPADA | C26: B | D26: 12-A | H26: 1 | I26: 333 | J26: 339 | K26: =J26-I26 -> 6 | L26: 6 | M26: 8 | N26: 0 | O26: 0 | P26: 3 | Q26: 0 | T26: =SUM(L26:S26) -> 17 | U26: c | W26: y | Y26: Debe 30 | AA26: =IF(AND(L26>0, M26>=8, NOT(OR(U26="C", U26="c"))), "CORTE", "") | AB26: =IF(AND(LEN(U26)>0,LEN(W26)=0),T26,0) -> 0 | AC26: =IF(AND(LEN(U26)>0,TRIM(W26)="Y"),T26,0) -> 17 | AD26: =IF(ISBLANK(W26),0,1) -> 1
A27: 26 | B27: SALOME AGUSTINA DIAZ VARGAS | C27: B | D27: 13 | H27: 1 | I27: 260 | J27: 268 | K27: =J27-I27 -> 8 | L27: 8 | M27: 0 | N27: 0 | O27: 0 | P27: 3 | Q27: 0 | R27: 15 | T27: =SUM(L27:S27) -> 26 | U27: c | W27: y | Y27: Debe 15 faena | AA27: =IF(AND(L27>0, M27>=8, NOT(OR(U27="C", U27="c"))), "CORTE", "") | AB27: =IF(AND(LEN(U27)>0,LEN(W27)=0),T27,0) -> 0 | AC27: =IF(AND(LEN(U27)>0,TRIM(W27)="Y"),T27,0) -> 26 | AD27: =IF(ISBLANK(W27),0,1) -> 1
A28: 27 | B28: MELISSA ISABEL PILLACA GARCIA | C28: B | D28: 15 | H28: 1 | I28: 1235 | J28: 1250 | K28: =J28-I28 -> 15 | L28: 15 | M28: 4 | N28: 0 | O28: 0 | P28: 3 | Q28: 0 | R28: 30 | T28: =SUM(L28:S28) -> 52 | U28: c | W28: y | AA28: =IF(AND(L28>0, M28>=8, NOT(OR(U28="C", U28="c"))), "CORTE", "") | AB28: =IF(AND(LEN(U28)>0,LEN(W28)=0),T28,0) -> 0 | AC28: =IF(AND(LEN(U28)>0,TRIM(W28)="Y"),T28,0) -> 52 | AD28: =IF(ISBLANK(W28),0,1) -> 1
A29: 28 | B29: ELEUTERIA DOMITILA PARIAMACHI DE PAZ | C29: B | D29: 16 | H29: 1 | I29: 32 | J29: 32 | K29: =J29-I29 -> 0 | L29: 5 | M29: 0 | N29: 0 | O29: 0 | P29: 3 | Q29: 0 | R29: 30 | T29: =SUM(L29:S29) -> 38 | AA29: =IF(AND(L29>0, M29>=8, NOT(OR(U29="C", U29="c"))), "CORTE", "") | AB29: =IF(AND(LEN(U29)>0,LEN(W29)=0),T29,0) -> 0 | AC29: =IF(AND(LEN(U29)>0,TRIM(W29)="Y"),T29,0) -> 0
A30: 29 | B30: LUZ DINA MIRAVAL HUERTA | C30: B | D30: 17 | H30: 1 | I30: 988 | J30: 1007 | K30: =J30-I30 -> 19 | L30: 19 | M30: 0 | N30: 0 | O30: 0 | P30: 3 | Q30: 0 | R30: 0 | T30: =SUM(L30:S30) -> 22 | U30: c | W30: y | AA30: =IF(AND(L30>0, M30>=8, NOT(OR(U30="C", U30="c"))), "CORTE", "") | AB30: =IF(AND(LEN(U30)>0,LEN(W30)=0),T30,0) -> 0 | AC30: =IF(AND(LEN(U30)>0,TRIM(W30)="Y"),T30,0) -> 22 | AD30: =IF(ISBLANK(W30),0,1) -> 1
A31: 30 | B31: CLETO TENORIO MORI | C31: B | D31: 18 | H31: 1 | I31: 545 | J31: 553 | K31: =J31-I31 -> 8 | L31: 8 | M31: 12 | N31: 0 | O31: 0 | P31: 3 | Q31: 0 | R31: 30 | T31: =SUM(L31:S31) -> 53 | U31: c | AA31: =IF(AND(L31>0, M31>=8, NOT(OR(U31="C", U31="c"))), "CORTE", "") | AB31: =IF(AND(LEN(U31)>0,LEN(W31)=0),T31,0) -> 53 | AC31: =IF(AND(LEN(U31)>0,TRIM(W31)="Y"),T31,0) -> 0 | AD31: =IF(ISBLANK(W31),0,1) -> 0
A32: 31 | B32: CAMILA HIDALGO | C32: B | D32: 21 | H32: 1 | I32: 166 | J32: 172 | K32: =J32-I32 -> 6 | L32: 6 | M32: 0 | N32: 0 | O32: 0 | P32: 3 | Q32: 0 | R32: 30 | T32: =SUM(L32:S32) -> 39 | AA32: =IF(AND(L32>0, M32>=8, NOT(OR(U32="C", U32="c"))), "CORTE", "") | AB32: =IF(AND(LEN(U32)>0,LEN(W32)=0),T32,0) -> 0 | AC32: =IF(AND(LEN(U32)>0,TRIM(W32)="Y"),T32,0) -> 0
A33: 32 | B33: JANET FERNANDEZ MINAYA | C33: B | D33: 29 | E33: N | H33: 1 | I33: 160 | J33: 161 | K33: =J33-I33 -> 1 | L33: 5 | M33: 0 | N33: 0 | O33: 20 | P33: 3 | Q33: 0 | R33: 0 | T33: =SUM(L33:S33) -> 28 | U33: c | Y33: Se le debe 0. Pago (8 consumo, 20 convenio) | AA33: =IF(AND(L33>0, M33>=8, NOT(OR(U33="C", U33="c"))), "CORTE", "") | AB33: =IF(AND(LEN(U33)>0,LEN(W33)=0),T33,0) -> 28 | AC33: =IF(AND(LEN(U33)>0,TRIM(W33)="Y"),T33,0) -> 0 | AD33: =IF(ISBLANK(W33),0,1) -> 0
A34: 33 | B34: ODILON CERNA ROMERO | C34: C | D34: 1 | H34: 1 | I34: 2019 | J34: 2041 | K34: =J34-I34 -> 22 | L34: 22 | M34: 0 | N34: 0 | O34: 0 | P34: 3 | Q34: 0 | T34: =SUM(L34:S34) -> 25 | U34: c | Y34: Se exonero faena. | AA34: =IF(AND(L34>0, M34>=8, NOT(OR(U34="C", U34="c"))), "CORTE", "") | AB34: =IF(AND(LEN(U34)>0,LEN(W34)=0),T34,0) -> 25 | AC34: =IF(AND(LEN(U34)>0,TRIM(W34)="Y"),T34,0) -> 0 | AD34: =IF(ISBLANK(W34),0,1) -> 0
A35: 34 | B35: OLGA FLORENTINA HUERTA AGAMA | C35: C | D35: 2 | H35: 1 | I35: 853 | J35: 856 | K35: =J35-I35 -> 3 | L35: 5 | M35: 0 | N35: 0 | O35: 0 | P35: 3 | Q35: 0 | R35: 30 | T35: =SUM(L35:S35) -> 38 | U35: c | AA35: =IF(AND(L35>0, M35>=8, NOT(OR(U35="C", U35="c"))), "CORTE", "") | AB35: =IF(AND(LEN(U35)>0,LEN(W35)=0),T35,0) -> 38 | AC35: =IF(AND(LEN(U35)>0,TRIM(W35)="Y"),T35,0) -> 0 | AD35: =IF(ISBLANK(W35),0,1) -> 0
A36: 35 | B36: TIMOTEO ROMERO JULCA | C36: C | D36: 4 | H36: 1 | I36: 3336 | J36: 3349 | K36: =J36-I36 -> 13 | L36: 13 | M36: 0 | N36: 0 | O36: 0 | P36: 3 | Q36: 0 | R36: 30 | T36: =SUM(L36:S36) -> 46 | U36: c | W36: y | AA36: =IF(AND(L36>0, M36>=8, NOT(OR(U36="C", U36="c"))), "CORTE", "") | AB36: =IF(AND(LEN(U36)>0,LEN(W36)=0),T36,0) -> 0 | AC36: =IF(AND(LEN(U36)>0,TRIM(W36)="Y"),T36,0) -> 46 | AD36: =IF(ISBLANK(W36),0,1) -> 1
A37: 36 | B37: AGAPITO PRINICIPE SALINAS | C37: C | D37: 5 | H37: 1 | I37: 4106 | J37: 4123 | K37: =J37-I37 -> 17 | L37: 17 | M37: 0 | N37: 0 | O37: 0 | P37: 3 | Q37: 0 | R37: 0 | T37: =SUM(L37:S37) -> 20 | AA37: =IF(AND(L37>0, M37>=8, NOT(OR(U37="C", U37="c"))), "CORTE", "") | AB37: =IF(AND(LEN(U37)>0,LEN(W37)=0),T37,0) -> 0 | AC37: =IF(AND(LEN(U37)>0,TRIM(W37)="Y"),T37,0) -> 0
A38: 37 | B38: DIANA JARA TRUJILLO | C38: C | D38: 6 | H38: 1 | I38: 544 | J38: 555 | K38: =J38-I38 -> 11 | L38: 11 | M38: 0 | N38: 0 | O38: 0 | P38: 3 | Q38: 0 | R38: 0 | T38: =SUM(L38:S38) -> 14 | AA38: =IF(AND(L38>0, M38>=8, NOT(OR(U38="C", U38="c"))), "CORTE", "") | AB38: =IF(AND(LEN(U38)>0,LEN(W38)=0),T38,0) -> 0 | AC38: =IF(AND(LEN(U38)>0,TRIM(W38)="Y"),T38,0) -> 0 | AD38: =IF(ISBLANK(W38),0,1) -> 0
A39: 38 | B39: VICTOR LOPEZ TRUJILLO | C39: C | D39: 7 | H39: 1 | I39: 2525 | J39: 2549 | K39: =J39-I39 -> 24 | L39: 24 | M39: 0 | N39: 0 | O39: 0 | P39: 3 | Q39: 0 | R39: 30 | T39: =SUM(L39:S39) -> 57 | AA39: =IF(AND(L39>0, M39>=8, NOT(OR(U39="C", U39="c"))), "CORTE", "") | AB39: =IF(AND(LEN(U39)>0,LEN(W39)=0),T39,0) -> 0 | AC39: =IF(AND(LEN(U39)>0,TRIM(W39)="Y"),T39,0) -> 0 | AD39: =IF(ISBLANK(W39),0,1) -> 0
A40: 39 | B40: JULISSA BARRETO QUITO | C40: C | D40: 8 | H40: 1 | I40: 248 | J40: 255 | K40: =J40-I40 -> 7 | L40: 7 | M40: 0 | N40: 0 | O40: 0 | P40: 3 | Q40: 0 | R40: 30 | T40: =SUM(L40:S40) -> 40 | AA40: =IF(AND(L40>0, M40>=8, NOT(OR(U40="C", U40="c"))), "CORTE", "") | AB40: =IF(AND(LEN(U40)>0,LEN(W40)=0),T40,0) -> 0 | AC40: =IF(AND(LEN(U40)>0,TRIM(W40)="Y"),T40,0) -> 0 | AD40: =IF(ISBLANK(W40),0,1) -> 0
...

Sheet INGRESOS Y EGRESOS
A1: 11 | B1: MONEDEROS | F1: EFECTIVO | J1: 3321 | K1: 8291
B2: AGUA | F2: AGUA
A3: FECHA | B3: CONCEPTO | C3: MONTO | F3: CONCEPTO | G3: MONTO
B4: JANET YAPE | C4: =Cobranza!AC498 -> 8291 | F4: YANET EFECTIVO | G4: =Cobranza!AB498 -> 3321
B6: Ingreso yape
B7: Salida yape
B8: Salida yape | C8: -6574.4
F9: Es del Efectivo | G9: 100 | J9: =SUM(J4:J5) -> 0
B10: Es del efectivo | C10: -100
B16: SALDO | C16: =SUM(C4:C15) -> 1616.6 | F16: SALDO | G16: =SUM(G4:G15) -> 3421
B17: Yanet tiene yape Este mes | C17: 1616.6 | F17: Yanet tiene efectivo | G17: 3421
B18: Sobra o falta | C18: =C16-C17 -> 0 | F18: Sobra o falta | G18: =G17-G16 -> 0
B19: El menos 8 nos indica que hay un Yape adelantado que
B20: nohe identificado su dueño
D21: TOTAL | E21: =C16+G16 -> 5037.6

Sheet Yape por MZ
A1: Recaudo por Manzana
A3: Mnz | B3: Reporte Yape-M | C3: Planilla-A | D3: Comentario | E3: Excesos y deudas-A
A4: A | B4: =SUMIF(Reporte!$F$2:$F$349, 'Yape por MZ'!A4, Reporte!$E$2:$E$349) -> 339 | C4: =SUMPRODUCT( (UPPER(Cobranza!C2:C497)=UPPER(A4))* (UPPER(Cobranza!U2:U497)="C")* (UPPER(Cobranza!W2:W497)="Y")* (Cobranza!T2:T497) ) -> 339 | D4: =B4-C4 -> 0 | E4: =SUMPRODUCT( (UPPER(Cobranza!C2:C497)=UPPER(A4))* (UPPER(Cobranza!U2:U497)="C")* (UPPER(Cobranza!W2:W497)="Y")* (Cobranza!X2:X497) ) -> 0 | F4: =IF(OR(C4=B4), 0, 1) -> 0
A5: B | B5: =SUMIF(Reporte!$F$2:$F$349, 'Yape por MZ'!A5, Reporte!$E$2:$E$349) -> 188 | C5: =SUMPRODUCT( (UPPER(Cobranza!C3:C498)=UPPER(A5))* (UPPER(Cobranza!U3:U498)="C")* (UPPER(Cobranza!W3:W498)="Y")* (Cobranza!T3:T498) ) -> 188 | D5: =B5-C5 -> 0 | E5: =SUMPRODUCT( (UPPER(Cobranza!C3:C498)=UPPER(A5))* (UPPER(Cobranza!U3:U498)="C")* (UPPER(Cobranza!W3:W498)="Y")* (Cobranza!X3:X498) ) -> 0 | F5: =IF(OR(C5=B5), 0, 1) -> 0
A6: C | B6: =SUMIF(Reporte!$F$2:$F$349, 'Yape por MZ'!A6, Reporte!$E$2:$E$349) -> 394 | C6: =SUMPRODUCT( (UPPER(Cobranza!C4:C498)=UPPER(A6))* (UPPER(Cobranza!U4:U498)="C")* (UPPER(Cobranza!W4:W498)="Y")* (Cobranza!T4:T498) ) -> 394 | D6: =B6-C6 -> 0 | E6: =SUMPRODUCT( (UPPER(Cobranza!C4:C498)=UPPER(A6))* (UPPER(Cobranza!U4:U498)="C")* (UPPER(Cobranza!W4:W498)="Y")* (Cobranza!X4:X498) ) -> 0 | F6: =IF(OR(C6=B6), 0, 1) -> 0
A7: D | B7: =SUMIF(Reporte!$F$2:$F$349, 'Yape por MZ'!A7, Reporte!$E$2:$E$349) -> 242 | C7: =SUMPRODUCT( (UPPER(Cobranza!C5:C500)=UPPER(A7))* (UPPER(Cobranza!U5:U500)="C")* (UPPER(Cobranza!W5:W500)="Y")* (Cobranza!T5:T500) ) -> 242 | D7: =B7-C7 -> 0 | E7: =SUMPRODUCT( (UPPER(Cobranza!C5:C500)=UPPER(A7))* (UPPER(Cobranza!U5:U500)="C")* (UPPER(Cobranza!W5:W500)="Y")* (Cobranza!X5:X500) ) -> 0 | F7: =IF(OR(C7=B7), 0, 1) -> 0
A8: E | B8: =SUMIF(Reporte!$F$2:$F$349, 'Yape por MZ'!A8, Reporte!$E$2:$E$349) -> 168 | C8: =SUMPRODUCT( (UPPER(Cobranza!C6:C501)=UPPER(A8))* (UPPER(Cobranza!U6:U501)="C")* (UPPER(Cobranza!W6:W501)="Y")* (Cobranza!T6:T501) ) -> 168 | D8: =B8-C8 -> 0 | E8: =SUMPRODUCT( (UPPER(Cobranza!C6:C501)=UPPER(A8))* (UPPER(Cobranza!U6:U501)="C")* (UPPER(Cobranza!W6:W501)="Y")* (Cobranza!X6:X501) ) -> 0 | F8: =IF(OR(C8=B8), 0, 1) -> 0
A9: F | B9: =SUMIF(Reporte!$F$2:$F$349, 'Yape por MZ'!A9, Reporte!$E$2:$E$349) -> 344 | C9: =SUMPRODUCT( (UPPER(Cobranza!C7:C502)=UPPER(A9))* (UPPER(Cobranza!U7:U502)="C")* (UPPER(Cobranza!W7:W502)="Y")* (Cobranza!T7:T502) ) -> 344 | D9: =B9-C9 -> 0 | E9: =SUMPRODUCT( (UPPER(Cobranza!C7:C502)=UPPER(A9))* (UPPER(Cobranza!U7:U502)="C")* (UPPER(Cobranza!W7:W502)="Y")* (Cobranza!X7:X502) ) -> 0 | F9: =IF(OR(C9=B9), 0, 1) -> 0
A10: G | B10: =SUMIF(Reporte!$F$2:$F$349, 'Yape por MZ'!A10, Reporte!$E$2:$E$349) -> 468 | C10: =SUMPRODUCT( (UPPER(Cobranza!C8:C503)=UPPER(A10))* (UPPER(Cobranza!U8:U503)="C")* (UPPER(Cobranza!W8:W503)="Y")* (Cobranza!T8:T503) ) -> 468 | D10: =B10-C10 -> 0 | F10: =IF(OR(C10=B10), 0, 1) -> 0
A11: H | B11: =SUMIF(Reporte!$F$2:$F$349, 'Yape por MZ'!A11, Reporte!$E$2:$E$349) -> 289 | C11: =SUMPRODUCT( (UPPER(Cobranza!C9:C504)=UPPER(A11))* (UPPER(Cobranza!U9:U504)="C")* (UPPER(Cobranza!W9:W504)="Y")* (Cobranza!T9:T504) ) -> 289 | D11: =B11-C11 -> 0 | F11: =IF(OR(C11=B11), 0, 1) -> 0
A12: I | B12: =SUMIF(Reporte!$F$2:$F$349, 'Yape por MZ'!A12, Reporte!$E$2:$E$349) -> 144 | C12: =SUMPRODUCT( (UPPER(Cobranza!C10:C505)=UPPER(A12))* (UPPER(Cobranza!U10:U505)="C")* (UPPER(Cobranza!W10:W505)="Y")* (Cobranza!T10:T505) ) -> 144 | D12: =B12-C12 -> 0 | E12: I10(8) Yape adelantado | F12: =IF(OR(C12=B12), 0, 1) -> 0
A13: J | B13: =SUMIF(Reporte!$F$2:$F$349, 'Yape por MZ'!A13, Reporte!$E$2:$E$349) -> 71 | C13: =SUMPRODUCT( (UPPER(Cobranza!C11:C506)=UPPER(A13))* (UPPER(Cobranza!U11:U506)="C")* (UPPER(Cobranza!W11:W506)="Y")* (Cobranza!T11:T506) ) -> 71 | D13: =B13-C13 -> 0 | F13: =IF(OR(C13=B13), 0, 1) -> 0
A14: K | B14: =SUMIF(Reporte!$F$2:$F$349, 'Yape por MZ'!A14, Reporte!$E$2:$E$349) -> 158 | C14: =SUMPRODUCT( (UPPER(Cobranza!C12:C507)=UPPER(A14))* (UPPER(Cobranza!U12:U507)="C")* (UPPER(Cobranza!W12:W507)="Y")* (Cobranza!T12:T507) ) -> 158 | D14: =B14-C14 -> 0 | E14: K11(13), K17(16) Yape Adelantado | F14: =IF(OR(C14=B14), 0, 1) -> 0
A15: L | B15: =SUMIF(Reporte!$F$2:$F$349, 'Yape por MZ'!A15, Reporte!$E$2:$E$349) -> 189 | C15: =SUMPRODUCT( (UPPER(Cobranza!C13:C508)=UPPER(A15))* (UPPER(Cobranza!U13:U508)="C")* (UPPER(Cobranza!W13:W508)="Y")* (Cobranza!T13:T508) ) -> 189 | D15: =B15-C15 -> 0 | F15: =IF(OR(C15=B15), 0, 1) -> 0
A16: M | B16: =SUMIF(Reporte!$F$2:$F$349, 'Yape por MZ'!A16, Reporte!$E$2:$E$349) -> 322 | C16: =SUMPRODUCT( (UPPER(Cobranza!C14:C509)=UPPER(A16))* (UPPER(Cobranza!U14:U509)="C")* (UPPER(Cobranza!W14:W509)="Y")* (Cobranza!T14:T509) ) -> 322 | D16: =B16-C16 -> 0 | F16: =IF(OR(C16=B16), 0, 1) -> 0
A17: N | B17: =SUMIF(Reporte!$F$2:$F$349, 'Yape por MZ'!A17, Reporte!$E$2:$E$349) -> 79 | C17: =SUMPRODUCT( (UPPER(Cobranza!C15:C510)=UPPER(A17))* (UPPER(Cobranza!U15:U510)="C")* (UPPER(Cobranza!W15:W510)="Y")* (Cobranza!T15:T510) ) -> 79 | D17: =B17-C17 -> 0 | F17: =IF(OR(C17=B17), 0, 1) -> 0
A18: O | B18: =SUMIF(Reporte!$F$2:$F$349, 'Yape por MZ'!A18, Reporte!$E$2:$E$349) -> 402 | C18: =SUMPRODUCT( (UPPER(Cobranza!C16:C511)=UPPER(A18))* (UPPER(Cobranza!U16:U511)="C")* (UPPER(Cobranza!W16:W511)="Y")* (Cobranza!T16:T511) ) -> 402 | D18: =B18-C18 -> 0 | F18: =IF(OR(C18=B18), 0, 1) -> 0
A19: P | B19: =SUMIF(Reporte!$F$2:$F$349, 'Yape por MZ'!A19, Reporte!$E$2:$E$349) -> 313 | C19: =SUMPRODUCT( (UPPER(Cobranza!C17:C512)=UPPER(A19))* (UPPER(Cobranza!U17:U512)="C")* (UPPER(Cobranza!W17:W512)="Y")* (Cobranza!T17:T512) ) -> 313 | D19: =B19-C19 -> 0 | E19: P18(12) Efectivo | F19: =IF(OR(C19=B19), 0, 1) -> 0
A20: Q | B20: =SUMIF(Reporte!$F$2:$F$349, 'Yape por MZ'!A20, Reporte!$E$2:$E$349) -> 255 | C20: =SUMPRODUCT( (UPPER(Cobranza!C18:C513)=UPPER(A20))* (UPPER(Cobranza!U18:U513)="C")* (UPPER(Cobranza!W18:W513)="Y")* (Cobranza!T18:T513) ) -> 255 | D20: =B20-C20 -> 0 | F20: =IF(OR(C20=B20), 0, 1) -> 0
A21: R | B21: =SUMIF(Reporte!$F$2:$F$349, 'Yape por MZ'!A21, Reporte!$E$2:$E$349) -> 72 | C21: =SUMPRODUCT( (UPPER(Cobranza!C19:C514)=UPPER(A21))* (UPPER(Cobranza!U19:U514)="C")* (UPPER(Cobranza!W19:W514)="Y")* (Cobranza!T19:T514) ) -> 72 | D21: =B21-C21 -> 0 | F21: =IF(OR(C21=B21), 0, 1) -> 0
A22: S | B22: =SUMIF(Reporte!$F$2:$F$349, 'Yape por MZ'!A22, Reporte!$E$2:$E$349) -> 352 | C22: =SUMPRODUCT( (UPPER(Cobranza!C20:C515)=UPPER(A22))* (UPPER(Cobranza!U20:U515)="C")* (UPPER(Cobranza!W20:W515)="Y")* (Cobranza!T20:T515) ) -> 352 | D22: =B22-C22 -> 0 | F22: =IF(OR(C22=B22), 0, 1) -> 0
A23: T | B23: =SUMIF(Reporte!$F$2:$F$349, 'Yape por MZ'!A23, Reporte!$E$2:$E$349) -> 365 | C23: =SUMPRODUCT( (UPPER(Cobranza!C21:C516)=UPPER(A23))* (UPPER(Cobranza!U21:U516)="C")* (UPPER(Cobranza!W21:W516)="Y")* (Cobranza!T21:T516) ) -> 365 | D23: =B23-C23 -> 0 | F23: =IF(OR(C23=B23), 0, 1) -> 0
A24: U | B24: =SUMIF(Reporte!$F$2:$F$349, 'Yape por MZ'!A24, Reporte!$E$2:$E$349) -> 77 | C24: =SUMPRODUCT( (UPPER(Cobranza!C22:C517)=UPPER(A24))* (UPPER(Cobranza!U22:U517)="C")* (UPPER(Cobranza!W22:W517)="Y")* (Cobranza!T22:T517) ) -> 77 | D24: =B24-C24 -> 0 | F24: =IF(OR(C24=B24), 0, 1) -> 0
A25: V | B25: =SUMIF(Reporte!$F$2:$F$349, 'Yape por MZ'!A25, Reporte!$E$2:$E$349) -> 180 | C25: =SUMPRODUCT( (UPPER(Cobranza!C23:C518)=UPPER(A25))* (UPPER(Cobranza!U23:U518)="C")* (UPPER(Cobranza!W23:W518)="Y")* (Cobranza!T23:T518) ) -> 180 | D25: =B25-C25 -> 0 | F25: =IF(OR(C25=B25), 0, 1) -> 0
A26: W | B26: =SUMIF(Reporte!$F$2:$F$349, 'Yape por MZ'!A26, Reporte!$E$2:$E$349) -> 244 | C26: =SUMPRODUCT( (UPPER(Cobranza!C24:C519)=UPPER(A26))* (UPPER(Cobranza!U24:U519)="C")* (UPPER(Cobranza!W24:W519)="Y")* (Cobranza!T24:T519) ) -> 244 | D26: =B26-C26 -> 0 | E26: W20(23) Yape adelantado | F26: =IF(OR(C26=B26), 0, 1) -> 0
A27: X | B27: =SUMIF(Reporte!$F$2:$F$349, 'Yape por MZ'!A27, Reporte!$E$2:$E$349) -> 310 | C27: =SUMPRODUCT( (UPPER(Cobranza!C25:C520)=UPPER(A27))* (UPPER(Cobranza!U25:U520)="C")* (UPPER(Cobranza!W25:W520)="Y")* (Cobranza!T25:T520) ) -> 310 | D27: =B27-C27 -> 0 | F27: =IF(OR(C27=B27), 0, 1) -> 0
A28: Y | B28: =SUMIF(Reporte!$F$2:$F$349, 'Yape por MZ'!A28, Reporte!$E$2:$E$349) -> 113 | C28: =SUMPRODUCT( (UPPER(Cobranza!C26:C521)=UPPER(A28))* (UPPER(Cobranza!U26:U521)="C")* (UPPER(Cobranza!W26:W521)="Y")* (Cobranza!T26:T521) ) -> 113 | D28: =B28-C28 -> 0 | F28: =IF(OR(C28=B28), 0, 1) -> 0
A29: Z | B29: =SUMIF(Reporte!$F$2:$F$349, 'Yape por MZ'!A29, Reporte!$E$2:$E$349) -> 282 | C29: =SUMPRODUCT( (UPPER(Cobranza!C27:C522)=UPPER(A29))* (UPPER(Cobranza!U27:U522)="C")* (UPPER(Cobranza!W27:W522)="Y")* (Cobranza!T27:T522) ) -> 282 | D29: =B29-C29 -> 0 | F29: =IF(OR(C29=B29), 0, 1) -> 0
A30: A1 | B30: =SUMIF(Reporte!$F$2:$F$349, 'Yape por MZ'!A30, Reporte!$E$2:$E$349) -> 284 | C30: =SUMPRODUCT( (UPPER(Cobranza!C28:C523)=UPPER(A30))* (UPPER(Cobranza!U28:U523)="C")* (UPPER(Cobranza!W28:W523)="Y")* (Cobranza!T28:T523) ) -> 284 | D30: =B30-C30 -> 0 | F30: =IF(OR(C30=B30), 0, 1) -> 0
A31: B1 | B31: =SUMIF(Reporte!$F$2:$F$349, 'Yape por MZ'!A31, Reporte!$E$2:$E$349) -> 332 | C31: =SUMPRODUCT( (UPPER(Cobranza!C29:C524)=UPPER(A31))* (UPPER(Cobranza!U29:U524)="C")* (UPPER(Cobranza!W29:W524)="Y")* (Cobranza!T29:T524) ) -> 332 | D31: =B31-C31 -> 0 | F31: =IF(OR(C31=B31), 0, 1) -> 0
A32: C1 | B32: =SUMIF(Reporte!$F$2:$F$349, 'Yape por MZ'!A32, Reporte!$E$2:$E$349) -> 309 | C32: =SUMPRODUCT( (UPPER(Cobranza!C30:C525)=UPPER(A32))* (UPPER(Cobranza!U30:U525)="C")* (UPPER(Cobranza!W30:W525)="Y")* (Cobranza!T30:T525) ) -> 309 | D32: =B32-C32 -> 0 | F32: =IF(OR(C32=B32), 0, 1) -> 0
A33: D1 | B33: =SUMIF(Reporte!$F$2:$F$349, 'Yape por MZ'!A33, Reporte!$E$2:$E$349) -> 102 | C33: =SUMPRODUCT( (UPPER(Cobranza!C31:C526)=UPPER(A33))* (UPPER(Cobranza!U31:U526)="C")* (UPPER(Cobranza!W31:W526)="Y")* (Cobranza!T31:T526) ) -> 102 | D33: =B33-C33 -> 0 | F33: =IF(OR(C33=B33), 0, 1) -> 0
A34: E1 | B34: =SUMIF(Reporte!$F$2:$F$349, 'Yape por MZ'!A34, Reporte!$E$2:$E$349) -> 139 | C34: =SUMPRODUCT( (UPPER(Cobranza!C32:C527)=UPPER(A34))* (UPPER(Cobranza!U32:U527)="C")* (UPPER(Cobranza!W32:W527)="Y")* (Cobranza!T32:T527) ) -> 139 | D34: =B34-C34 -> 0 | F34: =IF(OR(C34=B34), 0, 1) -> 0
A35: F1 | B35: =SUMIF(Reporte!$F$2:$F$349, 'Yape por MZ'!A35, Reporte!$E$2:$E$349) -> 193 | C35: =SUMPRODUCT( (UPPER(Cobranza!C33:C528)=UPPER(A35))* (UPPER(Cobranza!U33:U528)="C")* (UPPER(Cobranza!W33:W528)="Y")* (Cobranza!T33:T528) ) -> 193 | D35: =B35-C35 -> 0 | F35: =IF(OR(C35=B35), 0, 1) -> 0
A36: G1 | B36: =SUMIF(Reporte!$F$2:$F$349, 'Yape por MZ'!A36, Reporte!$E$2:$E$349) -> 75 | C36: =SUMPRODUCT( (UPPER(Cobranza!C34:C529)=UPPER(A36))* (UPPER(Cobranza!U34:U529)="C")* (UPPER(Cobranza!W34:W529)="Y")* (Cobranza!T34:T529) ) -> 75 | D36: =B36-C36 -> 0 | F36: =IF(OR(C36=B36), 0, 1) -> 0
A37: H1 | B37: =SUMIF(Reporte!$F$2:$F$349, 'Yape por MZ'!A37, Reporte!$E$2:$E$349) -> 397 | C37: =SUMPRODUCT( (UPPER(Cobranza!C35:C530)=UPPER(A37))* (UPPER(Cobranza!U35:U530)="C")* (UPPER(Cobranza!W35:W530)="Y")* (Cobranza!T35:T530) ) -> 497 | D37: =B37-C37 -> -100 | E37: Es del efectivo | F37: =IF(OR(C37=B37), 0, 1) -> 1
B39: =SUM(B4:B37) -> 8191 | C39: =SUM(C4:C37) -> 8291 | D39: =SUM(D4:D37) -> -100 | E39: =SUM(E4:E37) -> 0
D40: =B39-C39 -> -100
C42: h

Sheet Reporte
A1: Tipo de Transacción | B1: Origen | C1: Destino | D1: Monto | E1: Valor | F1: MZ | G1: LOTE | H1: Mensaje | I1: Fecha de operación | J1: Año | K1: Mes | L1: Dia | M1: Hora
A2: TE PAGÓ | B2: Washington Medrano M. | C2: Janet Villanueva A. | D2: 46.00 | E2: =VALUE(SUBSTITUTE(D2, ".", ",")) -> 46 | F2: W | G2: 5 | H2: MZ W LT 5 | I2: 07/12/2025 21:31:13 | J2: =MID(I2,7,4) -> 2025 | K2: =MID(I2,4,2) -> 12 | L2: =LEFT(I2,2) -> 07 | M2: =RIGHT(I2,8) -> 21:31:13
A3: TE PAGÓ | B3: William Trujillo R. | C3: Janet Villanueva A. | D3: 8.00 | E3: =VALUE(SUBSTITUTE(D3, ".", ",")) -> 8 | F3: E | G3: 7 | H3: mzE lt7 | I3: 07/12/2025 18:25:49 | J3: =MID(I3,7,4) -> 2025 | K3: =MID(I3,4,2) -> 12 | L3: =LEFT(I3,2) -> 07 | M3: =RIGHT(I3,8) -> 18:25:49
A4: TE PAGÓ | B4: Luis F. Paucar Q. | C4: Janet Villanueva A. | D4: 3.00 | E4: =VALUE(SUBSTITUTE(D4, ".", ",")) -> 3 | F4: B1 | G4: 5 | I4: 07/12/2025 14:57:33 | J4: =MID(I4,7,4) -> 2025 | K4: =MID(I4,4,2) -> 12 | L4: =LEFT(I4,2) -> 07 | M4: =RIGHT(I4,8) -> 14:57:33
A5: TE PAGÓ | B5: Mari Celidonio C. | C5: Janet Villanueva A. | D5: 36.00 | E5: =VALUE(SUBSTITUTE(D5, ".", ",")) -> 36 | F5: C1 | G5: 14 | I5: 07/12/2025 13:41:19 | J5: =MID(I5,7,4) -> 2025 | K5: =MID(I5,4,2) -> 12 | L5: =LEFT(I5,2) -> 07 | M5: =RIGHT(I5,8) -> 13:41:19
A6: TE PAGÓ | B6: Washington Medrano M. | C6: Janet Villanueva A. | D6: 47.00 | E6: =VALUE(SUBSTITUTE(D6, ".", ",")) -> 47 | F6: G | G6: 16 | H6: MZ G LT 16 | I6: 07/12/2025 10:14:53 | J6: =MID(I6,7,4) -> 2025 | K6: =MID(I6,4,2) -> 12 | L6: =LEFT(I6,2) -> 07 | M6: =RIGHT(I6,8) -> 10:14:53
A7: TE PAGÓ | B7: Luis F. Paucar Q. | C7: Janet Villanueva A. | D7: 7.00 | E7: =VALUE(SUBSTITUTE(D7, ".", ",")) -> 7 | F7: B1 | G7: 5 | I7: 07/12/2025 10:06:36 | J7: =MID(I7,7,4) -> 2025 | K7: =MID(I7,4,2) -> 12 | L7: =LEFT(I7,2) -> 07 | M7: =RIGHT(I7,8) -> 10:06:36
A8: TE PAGÓ | B8: Jimm P. Zapata M. | C8: Janet Villanueva A. | D8: 46.00 | E8: =VALUE(SUBSTITUTE(D8, ".", ",")) -> 46 | F8: H1 | G8: 8 | H8: Jimm zapata agua - lt 8 mz h1 | I8: 07/12/2025 09:51:28 | J8: =MID(I8,7,4) -> 2025 | K8: =MID(I8,4,2) -> 12 | L8: =LEFT(I8,2) -> 07 | M8: =RIGHT(I8,8) -> 09:51:28
A9: TE PAGÓ | B9: Yicson A. Zapata M. | C9: Janet Villanueva A. | D9: 42.00 | E9: =VALUE(SUBSTITUTE(D9, ".", ",")) -> 42 | F9: H1 | G9: 7 | H9: mz h1 lote 7 yicson Zapata Martinez | I9: 07/12/2025 09:47:58 | J9: =MID(I9,7,4) -> 2025 | K9: =MID(I9,4,2) -> 12 | L9: =LEFT(I9,2) -> 07 | M9: =RIGHT(I9,8) -> 09:47:58
A10: TE PAGÓ | B10: Dante R. Meza M. | C10: Janet Villanueva A. | D10: 42.00 | E10: =VALUE(SUBSTITUTE(D10, ".", ",")) -> 42 | F10: H1 | G10: 12 | H10: mz h1 LT 12 | I10: 07/12/2025 09:14:28 | J10: =MID(I10,7,4) -> 2025 | K10: =MID(I10,4,2) -> 12 | L10: =LEFT(I10,2) -> 07 | M10: =RIGHT(I10,8) -> 09:14:28
A11: TE PAGÓ | B11: Jessica Y. Morales V. | C11: Janet Villanueva A. | D11: 49.00 | E11: =VALUE(SUBSTITUTE(D11, ".", ",")) -> 49 | F11: Q | G11: 12 | H11: MZ.Q LT.12 | I11: 07/12/2025 06:03:01 | J11: =MID(I11,7,4) -> 2025 | K11: =MID(I11,4,2) -> 12 | L11: =LEFT(I11,2) -> 07 | M11: =RIGHT(I11,8) -> 06:03:01
A12: TE PAGÓ | B12: Elizabeth S. Regalado C. | C12: Janet Villanueva A. | D12: 27.00 | E12: =VALUE(SUBSTITUTE(D12, ".", ",")) -> 27 | F12: N | G12: 5 | H12: mz,N lt.5 | I12: 06/12/2025 23:34:14 | J12: =MID(I12,7,4) -> 2025 | K12: =MID(I12,4,2) -> 12 | L12: =LEFT(I12,2) -> 06 | M12: =RIGHT(I12,8) -> 23:34:14
A13: TE PAGÓ | B13: Nelly M. De-la-cruz H. | C13: Janet Villanueva A. | D13: 16.00 | E13: =VALUE(SUBSTITUTE(D13, ".", ",")) -> 16 | F13: O | G13: 15 | I13: 06/12/2025 22:43:26 | J13: =MID(I13,7,4) -> 2025 | K13: =MID(I13,4,2) -> 12 | L13: =LEFT(I13,2) -> 06 | M13: =RIGHT(I13,8) -> 22:43:26
A14: TE PAGÓ | B14: Raul R. Blas Q. | C14: Janet Villanueva A. | D14: 38.00 | E14: =VALUE(SUBSTITUTE(D14, ".", ",")) -> 38 | F14: M | G14: 17 | H14: Mz .M. Lt.17 | I14: 06/12/2025 22:37:43 | J14: =MID(I14,7,4) -> 2025 | K14: =MID(I14,4,2) -> 12 | L14: =LEFT(I14,2) -> 06 | M14: =RIGHT(I14,8) -> 22:37:43
A15: TE PAGÓ | B15: Janet Villanueva A. | C15: Janet Villanueva A. | D15: 36.00 | E15: =VALUE(SUBSTITUTE(D15, ".", ",")) -> 36 | F15: C | G15: 8B | H15: mz c lt 8 B | I15: 06/12/2025 22:36:34 | J15: =MID(I15,7,4) -> 2025 | K15: =MID(I15,4,2) -> 12 | L15: =LEFT(I15,2) -> 06 | M15: =RIGHT(I15,8) -> 22:36:34
A16: TE PAGÓ | B16: Janet Villanueva A. | C16: Janet Villanueva A. | D16: 6.00 | E16: =VALUE(SUBSTITUTE(D16, ".", ",")) -> 6 | F16: E | G16: 13 | H16: mz E lt 13 | I16: 06/12/2025 22:35:16 | J16: =MID(I16,7,4) -> 2025 | K16: =MID(I16,4,2) -> 12 | L16: =LEFT(I16,2) -> 06 | M16: =RIGHT(I16,8) -> 22:35:16
A17: TE PAGÓ | B17: Raul R. Blas Q. | C17: Janet Villanueva A. | D17: 17.00 | E17: =VALUE(SUBSTITUTE(D17, ".", ",")) -> 17 | F17: O | G17: 9 | I17: 06/12/2025 22:34:31 | J17: =MID(I17,7,4) -> 2025 | K17: =MID(I17,4,2) -> 12 | L17: =LEFT(I17,2) -> 06 | M17: =RIGHT(I17,8) -> 22:34:31
A18: TE PAGÓ | B18: Janet Villanueva A. | C18: Janet Villanueva A. | D18: 13.00 | E18: =VALUE(SUBSTITUTE(D18, ".", ",")) -> 13 | F18: E | G18: 13 | H18: mz E lt 13 | I18: 06/12/2025 22:34:08 | J18: =MID(I18,7,4) -> 2025 | K18: =MID(I18,4,2) -> 12 | L18: =LEFT(I18,2) -> 06 | M18: =RIGHT(I18,8) -> 22:34:08
A19: TE PAGÓ | B19: Janet Villanueva A. | C19: Janet Villanueva A. | D19: 22.00 | E19: =VALUE(SUBSTITUTE(D19, ".", ",")) -> 22 | F19: G | G19: 21A | H19: nz G lt 21 A | I19: 06/12/2025 22:33:03 | J19: =MID(I19,7,4) -> 2025 | K19: =MID(I19,4,2) -> 12 | L19: =LEFT(I19,2) -> 06 | M19: =RIGHT(I19,8) -> 22:33:03
A20: TE PAGÓ | B20: Janet Villanueva A. | C20: Janet Villanueva A. | D20: 39.00 | E20: =VALUE(SUBSTITUTE(D20, ".", ",")) -> 39 | F20: G | G20: 3 | H20: mz G lt 3 | I20: 06/12/2025 22:28:51 | J20: =MID(I20,7,4) -> 2025 | K20: =MID(I20,4,2) -> 12 | L20: =LEFT(I20,2) -> 06 | M20: =RIGHT(I20,8) -> 22:28:51
A21: TE PAGÓ | B21: Yolanda E. Sales B. | C21: Janet Villanueva A. | D21: 18.00 | E21: =VALUE(SUBSTITUTE(D21, ".", ",")) -> 18 | F21: B1 | G21: 11 | H21: mz B1 lote 11 | I21: 06/12/2025 22:28:22 | J21: =MID(I21,7,4) -> 2025 | K21: =MID(I21,4,2) -> 12 | L21: =LEFT(I21,2) -> 06 | M21: =RIGHT(I21,8) -> 22:28:22
A22: TE PAGÓ | B22: Vanessa A. Milla C. | C22: Janet Villanueva A. | D22: 43.00 | E22: =VALUE(SUBSTITUTE(D22, ".", ",")) -> 43 | F22: S | G22: 3 | H22: mzn s lt 3 vanessa milla | I22: 06/12/2025 22:27:55 | J22: =MID(I22,7,4) -> 2025 | K22: =MID(I22,4,2) -> 12 | L22: =LEFT(I22,2) -> 06 | M22: =RIGHT(I22,8) -> 22:27:55
A23: TE PAGÓ | B23: Mariluz Romero H. | C23: Janet Villanueva A. | D23: 43.00 | E23: =VALUE(SUBSTITUTE(D23, ".", ",")) -> 43 | F23: Q | G23: 3 | H23: mz Q lote 3 Pablo romero Garcilazo segunda etapa 💧💧💧 | I23: 06/12/2025 22:21:21 | J23: =MID(I23,7,4) -> 2025 | K23: =MID(I23,4,2) -> 12 | L23: =LEFT(I23,2) -> 06 | M23: =RIGHT(I23,8) -> 22:21:21
A24: TE PAGÓ | B24: Salome A. Diaz V. | C24: Janet Villanueva A. | D24: 26.00 | E24: =VALUE(SUBSTITUTE(D24, ".", ",")) -> 26 | F24: B | G24: 13 | H24: MZ:B Lt: 13 / 15 soles de multa | I24: 06/12/2025 21:52:18 | J24: =MID(I24,7,4) -> 2025 | K24: =MID(I24,4,2) -> 12 | L24: =LEFT(I24,2) -> 06 | M24: =RIGHT(I24,8) -> 21:52:18
A25: TE PAGÓ | B25: Juana S. Morales D. | C25: Janet Villanueva A. | D25: 42.00 | E25: =VALUE(SUBSTITUTE(D25, ".", ",")) -> 42 | F25: T | G25: 8 | H25: mz t lt 8 Miguel Meléndez julca | I25: 06/12/2025 21:50:26 | J25: =MID(I25,7,4) -> 2025 | K25: =MID(I25,4,2) -> 12 | L25: =LEFT(I25,2) -> 06 | M25: =RIGHT(I25,8) -> 21:50:26
A26: TE PAGÓ | B26: Leon R. Cosme C. | C26: Janet Villanueva A. | D26: 47.00 | E26: =VALUE(SUBSTITUTE(D26, ".", ",")) -> 47 | F26: S | G26: 13 | H26: Ana Garro Rojas, Mz. S Lt 13 | I26: 06/12/2025 21:27:53 | J26: =MID(I26,7,4) -> 2025 | K26: =MID(I26,4,2) -> 12 | L26: =LEFT(I26,2) -> 06 | M26: =RIGHT(I26,8) -> 21:27:53
A27: TE PAGÓ | B27: Leon R. Cosme C. | C27: Janet Villanueva A. | D27: 38.00 | E27: =VALUE(SUBSTITUTE(D27, ".", ",")) -> 38 | F27: W | G27: 9 | H27: Salma Roena Caballero Cosme Mz. W Lt 9 | I27: 06/12/2025 21:26:02 | J27: =MID(I27,7,4) -> 2025 | K27: =MID(I27,4,2) -> 12 | L27: =LEFT(I27,2) -> 06 | M27: =RIGHT(I27,8) -> 21:26:02
A28: TE PAGÓ | B28: Shelly R. Moreno C. | C28: Janet Villanueva A. | D28: 38.00 | E28: =VALUE(SUBSTITUTE(D28, ".", ",")) -> 38 | F28: S | G28: 7 | H28: rubi moreno cosme mz s lote 7 | I28: 06/12/2025 21:03:23 | J28: =MID(I28,7,4) -> 2025 | K28: =MID(I28,4,2) -> 12 | L28: =LEFT(I28,2) -> 06 | M28: =RIGHT(I28,8) -> 21:03:23
A29: TE PAGÓ | B29: Eloy E. Ramirez V. | C29: Janet Villanueva A. | D29: 41.00 | E29: =VALUE(SUBSTITUTE(D29, ".", ",")) -> 41 | F29: G | G29: 23 | H29: MzG Lt 23 Hipólito Ramírez | I29: 06/12/2025 20:44:33 | J29: =MID(I29,7,4) -> 2025 | K29: =MID(I29,4,2) -> 12 | L29: =LEFT(I29,2) -> 06 | M29: =RIGHT(I29,8) -> 20:44:33
A30: TE PAGÓ | B30: Sonia M. Arquino M. | C30: Janet Villanueva A. | D30: 14.00 | E30: =VALUE(SUBSTITUTE(D30, ".", ",")) -> 14 | F30: V | G30: 6 | H30: MZv LT6 | I30: 06/12/2025 19:46:26 | J30: =MID(I30,7,4) -> 2025 | K30: =MID(I30,4,2) -> 12 | L30: =LEFT(I30,2) -> 06 | M30: =RIGHT(I30,8) -> 19:46:26
A31: TE PAGÓ | B31: Olinda Ascurra C. | C31: Janet Villanueva A. | D31: 9.00 | E31: =VALUE(SUBSTITUTE(D31, ".", ",")) -> 9 | F31: H1 | G31: 35 | H31: pago de consumo de agua | I31: 06/12/2025 19:38:17 | J31: =MID(I31,7,4) -> 2025 | K31: =MID(I31,4,2) -> 12 | L31: =LEFT(I31,2) -> 06 | M31: =RIGHT(I31,8) -> 19:38:17
... A36: TE PAGÓ | B36: Carmen J. Rojas T. | C36: Janet Villanueva A. | D36: 9.00 | E36: =VALUE(SUBSTITUTE(D36, ".", ",")) -> 9 | F36: C1 | G36: 17 | H36: mz c1 lt 09 Roberto Martín marlapulu flores | I36: 06/12/2025 19:06:10 | J36: =MID(I36,7,4) -> 2025 | K36: =MID(I36,4,2) -> 12 | L36: =LEFT(I36,2) -> 06 | M36: =RIGHT(I36,8) -> 19:06:10
A37: TE PAGÓ | B37: Eugenia Utrilla F. | C37: Janet Villanueva A. | D37: 13.00 | E37: =VALUE(SUBSTITUTE(D37, ".", ",")) -> 13 | F37: A1 | G37: 2 | I37: 06/12/2025 19:00:32 | J37: =MID(I37,7,4) -> 2025 | K37: =MID(I37,4,2) -> 12 | L37: =LEFT(I37,2) -> 06 | M37: =RIGHT(I37,8) -> 19:00:32
A38: TE PAGÓ | B38: BCP - MAMANI REYES JOSE ANTONIO | C38: JANET VILLANUEVA ALEGRIA | D38: 38.00 | E38: =VALUE(SUBSTITUTE(D38, ".", ",")) -> 38 | F38: M | G38: 13 | I38: 06/12/2025 18:58:05 | J38: =MID(I38,7,4) -> 2025 | K38: =MID(I38,4,2) -> 12 | L38: =LEFT(I38,2) -> 06 | M38: =RIGHT(I38,8) -> 18:58:05
A39: TE PAGÓ | B39: Mayra C. Jara E. | C39: Janet Villanueva A. | D39: 69.00 | E39: =VALUE(SUBSTITUTE(D39, ".", ",")) -> 69 | F39: D | G39: 7 | H39: Mz.D. Lt.. 7... | I39: 06/12/2025 18:55:46 | J39: =MID(I39,7,4) -> 2025 | K39: =MID(I39,4,2) -> 12 | L39: =LEFT(I39,2) -> 06 | M39: =RIGHT(I39,8) -> 18:55:46
A40: TE PAGÓ | B40: Teodora T. Meza G. | C40: Janet Villanueva A. | D40: 10.00 | E40: =VALUE(SUBSTITUTE(D40, ".", ",")) -> 10 | F40: Q | G40: 14 | I40: 06/12/2025 18:50:17 | J40: =MID(I40,7,4) -> 2025 | K40: =MID(I40,4,2) -> 12 | L40: =LEFT(I40,2) -> 06 | M40: =RIGHT(I40,8) -> 18:50:17
A41: TE PAGÓ | B41: Clemente R. Palmadera M. | C41: Janet Villanueva A. | D41: 45.00 | E41: =VALUE(SUBSTITUTE(D41, ".", ",")) -> 45 | F41: T | G41: 7 | H41: MZ T lote 7 Roberto palmadera milla | I41: 06/12/2025 18:45:48 | J41: =MID(I41,7,4) -> 2025 | K41: =MID(I41,4,2) -> 12 | L41: =LEFT(I41,2) -> 06 | M41: =RIGHT(I41,8) -> 18:45:48
A42: TE PAGÓ | B42: Joneth G. Valladares L. | C42: Janet Villanueva A. | E42: 24 | F42: C | G42: 19 | I42: 06/12/2025 18:40:05 | J42: =MID(I42,7,4) -> 2025 | K42: =MID(I42,4,2) -> 12 | L42: =LEFT(I42,2) -> 06 | M42: =RIGHT(I42,8) -> 18:40:05
A43: TE PAGÓ | B43: Joneth G. Valladares L. | C43: Janet Villanueva A. | E43: 37 | F43: G | G43: 18 | I43: 06/12/2025 18:40:04 | J43: =MID(I43,7,4) -> 2025 | K43: =MID(I43,4,2) -> 12 | L43: =LEFT(I43,2) -> 06 | M43: =RIGHT(I43,8) -> 18:40:04
A44: TE PAGÓ | B44: Joneth G. Valladares L. | C44: Janet Villanueva A. | D44: 99.00 | E44: 38 | F44: E | G44: 8 | H44: Mz E Lt 8 (38 soles)Gertrudes Vidal Gonzales, | I44: 06/12/2025 18:40:03 | J44: =MID(I44,7,4) -> 2025 | K44: =MID(I44,4,2) -> 12 | L44: =LEFT(I44,2) -> 06 | M44: =RIGHT(I44,8) -> 18:40:03
...

Sheet PLANILLA
A1: ITEM | B1: NOMBRES | C1: MZ | D1: LT | E1: MARCACIÓN | F1: m3 | G1: MARCACIÓN | H1: M3 | I1: MARCACIÓN | J1: M3 | K1: MARCACIÓN | L1: M3 | M1: MARCACIÓN | N1: M3 | O1: MARCACIÓN | P1: M3 | Q1: MARCACIÓN | R1: M3 | S1: MARCACIÓN | T1: M3 | U1: MARCACION | V1: m3 | W1: MARCACION | X1: m3 | Y1: MARCACION | Z1: m3 | AA1: MARCACIÓN | AB1: M3 | AC1: Total mes actual | AD1: MES ANTERIOR | AE1: Corte y reconexión | AF1: Convenio | AG1: Manteniminiento | AH1: Multa | AI1: Total a pagar | AJ1: Estado | AK1: Fecha de pago | AL1: Medio de pago | AM1: Comentario
A2: 1 | B2: MARCELINA OBREGON DE AVILA | C2: A | D2: 1 | E2: 2445 | F2: 6 | G2: 2451 | H2: 7 | I2: 2458 | J2: 6 | K2: 2464 | L2: 5 | M2: 2469 | N2: 7 | O2: 2476 | P2: 5 | Q2: 2481 | R2: 5 | S2: 2486 | T2: 5 | U2: 2491 | V2: 5 | W2: 2496 | X2: 5 | Y2: 2502 | Z2: 6 | AA2: 2506 | AB2: 4 | AC2: 5 | AD2: 0 | AE2: 0 | AG2: 3 | AH2: 0 | AI2: 8
A3: 2 | B3: ROSA AURORA ROCA VIDAL | C3: A | D3: 2 | E3: 1975 | F3: 37 | G3: 2012 | H3: 23 | I3: 2035 | J3: 32 | K3: 2067 | L3: 27 | M3: 2094 | N3: 26 | O3: 2120 | P3: 22 | Q3: 2142 | R3: 22 | S3: 2168 | T3: 26 | U3: 2193 | V3: 25 | W3: 2225 | X3: 32 | Y3: 2248 | Z3: 23 | AA3: 2288 | AB3: 40 | AC3: 40 | AD3: 0 | AE3: 0 | AG3: 3 | AH3: 0 | AI3: 43
A4: 3 | B4: LINDA PAJUELO COCHACHÍN | C4: A | D4: 3 | K4: 0 | L4: 0 | M4: 0 | N4: 1 | O4: 1 | P4: 14 | Q4: 15 | R4: 14 | S4: 22 | T4: 7 | U4: 22 | V4: 0 | W4: 22 | X4: 0 | Y4: 22 | Z4: 0 | AA4: 22 | AB4: 0 | AC4: 5 | AD4: 0 | AE4: 0 | AG4: 3 | AH4: 0 | AI4: 8
A5: 4 | B5: YOLANDA ESPINOZA JAIMES | C5: A | D5: 4 | E5: 1759 | F5: 0 | G5: 1759 | H5: 0 | I5: 1759 | J5: 3 | K5: 1762 | L5: 0 | M5: 1762 | N5: 0 | O5: 1762 | P5: 0 | Q5: 1762 | R5: 0 | S5: 1762 | T5: 0 | U5: 1732 | V5: 0 | W5: 1762 | X5: 30 | Y5: 1763 | Z5: 1 | AA5: 1763 | AB5: 0 | AC5: 5 | AD5: 41 | AE5: 40 | AG5: 3 | AH5: 20 | AI5: 109
A6: 5 | B6: JULIA AGAMA CUZCO | C6: A | D6: 5 | E6: 2933 | F6: 35 | G6: 2968 | H6: 34 | I6: 3002 | J6: 23 | K6: 3025 | L6: 23 | M6: 3048 | N6: 16 | O6: 3064 | P6: 14 | Q6: 3078 | R6: 14 | S6: 3092 | T6: 14 | U6: 3108 | V6: 16 | W6: 3120 | X6: 12 | Y6: 3141 | Z6: 21 | AA6: 3162 | AB6: 21 | AC6: 21 | AD6: 0 | AE6: 0 | AG6: 3 | AH6: 0 | AI6: 24
A7: 6 | B7: ESTEBAN REYES SANCHEZ | C7: A | D7: 6 | E7: 1253 | F7: 45 | G7: 1298 | H7: 35 | I7: 1333 | J7: 25 | K7: 1358 | L7: 32 | M7: 1390 | N7: 22 | O7: 1412 | P7: 28 | Q7: 1440 | R7: 28 | S7: 1467 | T7: 27 | U7: 1491 | V7: 24 | W7: 1517 | X7: 26 | Y7: 1544 | Z7: 27 | AA7: 1571 | AB7: 27 | AC7: 27 | AD7: 0 | AE7: 0 | AG7: 3 | AH7: 0 | AI7: 30
A8: 7 | B8: JUAN CARLOS MELGAREJO BEDON | C8: A | D8: 7 | E8: 1358 | F8: 24 | G8: 1382 | H8: 25 | I8: 1407 | J8: 22 | K8: 1429 | L8: 23 | M8: 1452 | N8: 19 | O8: 1471 | P8: 22 | Q8: 1493 | R8: 22 | S8: 1512 | T8: 19 | U8: 1529 | V8: 17 | W8: 1546 | X8: 17 | Y8: 1562 | Z8: 16 | AA8: 1579 | AB8: 17 | AC8: 17 | AD8: 19 | AE8: 0 | AG8: 3 | AH8: 0 | AI8: 39
A9: 8 | B9: VICTOR MELGAREJO CORCINO | C9: A | D9: 8 | E9: 5882 | F9: 35 | G9: 5917 | H9: 33 | I9: 5950 | J9: 25 | K9: 5975 | L9: 36 | M9: 6011 | N9: 21 | O9: 6032 | P9: 13 | Q9: 6045 | R9: 13 | S9: 6055 | T9: 10 | U9: 6067 | V9: 12 | W9: 6078 | X9: 11 | Y9: 6088 | Z9: 10 | AA9: 6103 | AB9: 15 | AC9: 15 | AD9: 0 | AE9: 0 | AG9: 3 | AH9: 0 | AI9: 18
A10: 9 | B10: JHONI MELGAREJO BEDON | C10: A | D10: 8-A | P10: 18 | Q10: 18 | R10: 18 | S10: 26 | T10: 8 | U10: 32 | V10: 6 | W10: 46 | X10: 14 | Y10: 53 | Z10: 7 | AA10: 61 | AB10: 8 | AC10: 8 | AD10: 0 | AE10: 0 | AG10: 3 | AH10: 20 | AI10: 31
A11: 10 | B11: ALEJANDRO MELGAREJO ESPINOZA | C11: A | D11: 9 | E11: 1381 | F11: 32 | G11: 1413 | H11: 30 | I11: 1443 | J11: 40 | K11: 1483 | L11: 33 | M11: 1516 | N11: 33 | O11: 1549 | P11: 27 | Q11: 1576 | R11: 27 | S11: 1601 | T11: 25 | U11: 1624 | V11: 23 | W11: 1646 | X11: 22 | Y11: 1673 | Z11: 27 | AA11: 1703 | AB11: 30 | AC11: 30 | AD11: 0 | AE11: 0 | AG11: 3 | AH11: 0 | AI11: 33
A12: 11 | B12: ISABEL PUNTILLO VEGA | C12: A | D12: 10 | E12: 31 | F12: 10 | G12: 41 | H12: 29 | I12: 70 | J12: 18 | K12: 88 | L12: 29 | M12: 117 | N12: 20 | O12: 137 | P12: 163 | Q12: 300 | R12: 163 | S12: 371 | T12: 71 | U12: 379 | V12: 8 | W12: 384 | X12: 5 | Y12: 389 | Z12: 5 | AA12: 395 | AB12: 6 | AC12: 6 | AD12: 0 | AE12: 0 | AG12: 3 | AH12: 20 | AI12: 29
A13: 12 | B13: FELIX POZO CASTRO | C13: A | D13: 11 | E13: 341 | F13: 0 | G13: 341 | H13: 1 | I13: 342 | J13: 1 | K13: 343 | L13: 0 | M13: 343 | N13: 1 | O13: 344 | P13: 0 | Q13: 344 | R13: 0 | S13: 345 | T13: 1 | U13: 346 | V13: 1 | W13: 346 | X13: 0 | Y13: 346 | Z13: 0 | AA13: 346 | AB13: 0 | AC13: 5 | AD13: 0 | AE13: 0 | AG13: 3 | AH13: 20 | AI13: 28
A14: 13 | B14: BACILIO UTRILLA FRANCISCO | C14: B | D14: 1 | E14: 2078 | F14: 15 | G14: 2093 | H14: 0 | I14: 2093 | J14: 7 | K14: 2100 | L14: 10 | M14: 2110 | N14: 8 | O14: 2118 | P14: 5 | Q14: 2123 | R14: 5 | S14: 2131 | T14: 8 | U14: 2137 | V14: 6 | W14: 2141 | X14: 4 | Y14: 2147 | Z14: 6 | AA14: 2153 | AB14: 6 | AC14: 6 | AD14: 9 | AE14: 0 | AG14: 3 | AH14: 0 | AI14: 18
A15: 14 | B15: ESTEBAN REYNALDO ROSALES | C15: B | D15: 2 | E15: 2104 | F15: 6 | G15: 2110 | H15: 3 | I15: 2113 | J15: 2 | K15: 2115 | L15: 11 | M15: 2126 | N15: 9 | O15: 2135 | P15: 6 | Q15: 2141 | R15: 6 | S15: 2146 | T15: 5 | U15: 2152 | V15: 6 | W15: 2157 | X15: 5 | Y15: 2164 | Z15: 7 | AA15: 2171 | AB15: 7 | AC15: 7 | AD15: 0 | AE15: 0 | AG15: 3 | AH15: 20 | AI15: 30
A16: 15 | B16: EDUARDO REYNALDO ROSALES | C16: B | D16: 3 | E16: 602 | F16: 9 | G16: 611 | H16: 10 | I16: 621 | J16: 10 | K16: 631 | L16: 9 | M16: 640 | N16: 8 | O16: 648 | P16: 10 | Q16: 658 | R16: 10 | S16: 669 | T16: 11 | U16: 676 | V16: 7 | W16: 682 | X16: 6 | Y16: 689 | Z16: 7 | AA16: 695 | AB16: 6 | AC16: 6 | AD16: 0 | AE16: 0 | AG16: 3 | AH16: 0 | AI16: 9
A17: 16 | B17: MELINA J. JUAREZ TOLEDO DE MORENO | C17: B | D17: 4 | E17: 189 | F17: 10 | G17: 199 | H17: 12 | I17: 211 | J17: 15 | K17: 226 | L17: 13 | M17: 239 | N17: 13 | O17: 252 | P17: 21 | Q17: 273 | R17: 21 | S17: 291 | T17: 18 | U17: 311 | V17: 20 | W17: 331 | X17: 20 | Y17: 348 | Z17: 17 | AA17: 369 | AB17: 21 | AC17: 21 | AD17: 0 | AE17: 0 | AG17: 3 | AH17: 0 | AI17: 24
A18: 17 | B18: POMPEYO CELESTINO LLIUYA | C18: B | D18: 5 | E18: 4425 | F18: 58 | G18: 4483 | H18: 45 | I18: 4528 | J18: 39 | K18: 4567 | L18: 33 | M18: 4600 | N18: 39 | O18: 4639 | P18: 34 | Q18: 4673 | R18: 34 | S18: 4706 | T18: 33 | U18: 4742 | V18: 36 | W18: 4775 | X18: 33 | Y18: 4810 | Z18: 35 | AA18: 4848 | AB18: 38 | AC18: 38 | AD18: 0 | AE18: 0 | AG18: 3 | AH18: 20 | AI18: 61
A19: 18 | B19: ROSA VICTORIA MILLA MORALES | C19: B | D19: 6 | E19: 3385 | F19: 34 | G19: 3419 | H19: 35 | I19: 3454 | J19: 23 | K19: 3477 | L19: 23 | M19: 3500 | N19: 20 | O19: 3520 | P19: 26 | Q19: 3546 | R19: 26 | S19: 3570 | T19: 24 | U19: 3592 | V19: 22 | W19: 3612 | X19: 20 | Y19: 3634 | Z19: 22 | AA19: 3656 | AB19: 22 | AC19: 22 | AD19: 25 | AE19: 0 | AG19: 3 | AH19: 0 | AI19: 50
A20: 19 | B20: LIRIA PARIAMACHI DE PAZ | C20: B | D20: 7 | E20: 2289 | F20: 16 | G20: 2305 | H20: 17 | I20: 2322 | J20: 26 | K20: 2348 | L20: 16 | M20: 2364 | N20: 17 | O20: 2381 | P20: 16 | Q20: 2397 | R20: 16 | S20: 2414 | T20: 17 | U20: 2428 | V20: 14 | W20: 2443 | X20: 15 | Y20: 2455 | Z20: 12 | AA20: 2469 | AB20: 14 | AC20: 14 | AD20: 0 | AE20: 0 | AG20: 3 | AH20: 0 | AI20: 17
A21: 20 | B21: ROSALINA OLIMPIA CIRIACO SOTELO | C21: B | D21: 8 | E21: 6347 | F21: 14 | G21: 6361 | H21: 17 | I21: 6378 | J21: 18 | K21: 6396 | L21: 15 | M21: 6411 | N21: 14 | O21: 6425 | P21: 14 | Q21: 6439 | R21: 14 | S21: 6456 | T21: 17 | U21: 6470 | V21: 14 | W21: 6484 | X21: 14 | Y21: 6497 | Z21: 13 | AA21: 6510 | AB21: 13 | AC21: 13 | AD21: 16 | AE21: 0 | AG21: 3 | AH21: 0 | AI21: 32
A22: 21 | B22: ALEJANDRO RAPRAY VELASQUEZ | C22: B | D22: 9 | E22: 5905 | F22: 23 | G22: 5928 | H22: 25 | I22: 5953 | J22: 21 | K22: 5974 | L22: 16 | M22: 5990 | N22: 14 | O22: 6004 | P22: 14 | Q22: 6018 | R22: 14 | S22: 6045 | T22: 27 | U22: 6052 | V22: 7 | W22: 6058 | X22: 6 | Y22: 6062 | Z22: 4 | AA22: 6066 | AB22: 4 | AC22: 5 | AD22: 0 | AE22: 0 | AG22: 3 | AH22: 0 | AI22: 8
... A25: 24 | B25: TEOFILO BRUNO RAMOS DE LA CRUZ | C25: B | D25: 12 | E25: 2213 | F25: 8 | G25: 2221 | H25: 8 | I25: 2229 | J25: 10 | K25: 2239 | L25: 7 | M25: 2246 | N25: 9 | O25: 2255 | P25: 6 | Q25: 2261 | R25: 6 | S25: 2267 | T25: 6 | U25: 2273 | V25: 6 | W25: 2278 | X25: 5 | Y25: 2285 | Z25: 7 | AA25: 2292 | AB25: 7 | AC25: 7 | AD25: 10 | AE25: 0 | AG25: 3 | AH25: 0 | AI25: 20
A26: 25 | B26: ROSMERI SANCHEZ ESPADA | C26: B | D26: 12-A | E26: 198 | F26: 6 | G26: 204 | H26: 7 | I26: 211 | J26: 6 | K26: 217 | L26: 6 | M26: 223 | N26: 6 | O26: 229 | P26: 6 | Q26: 235 | R26: 6 | S26: 239 | T26: 4 | U26: 244 | V26: 5 | W26: 250 | X26: 6 | Y26: 256 | Z26: 6 | AA26: 262 | AB26: 6 | AC26: 6 | AD26: 0 | AE26: 0 | AG26: 3 | AH26: 0 | AI26: 9
A27: 26 | B27: SALOME AGUSTINA DIAZ VARGAS | C27: B | D27: 13 | E27: 90 | F27: 13 | G27: 103 | H27: 12 | I27: 115 | J27: 16 | K27: 131 | L27: 6 | M27: 137 | N27: 5 | O27: 142 | P27: 5 | Q27: 147 | R27: 5 | S27: 152 | T27: 5 | U27: 157 | V27: 5 | W27: 165 | X27: 8 | Y27: 173 | Z27: 8 | AA27: 180 | AB27: 7 | AC27: 7 | AD27: 0 | AE27: 0 | AG27: 3 | AH27: 0 | AI27: 10
A28: 27 | B28: MELISSA ISABEL PILLACA GARCIA | C28: B | D28: 15 | E28: 886 | F28: 12 | G28: 898 | H28: 18 | I28: 916 | J28: 13 | K28: 929 | L28: 18 | M28: 947 | N28: 18 | O28: 965 | P28: 20 | Q28: 985 | R28: 20 | S28: 1006 | T28: 21 | U28: 1028 | V28: 22 | W28: 1052 | X28: 24 | Y28: 1061 | Z28: 9 | AA28: 1105 | AB28: 44 | AC28: 44 | AD28: 0 | AE28: 0 | AG28: 3 | AH28: 0 | AI28: 47
A29: 28 | B29: CLETO TENORIO MORI | C29: B | D29: 16 | E29: 322 | F29: 13 | G29: 335 | H29: 21 | I29: 356 | J29: 16 | K29: 372 | L29: 17 | M29: 389 | N29: 15 | O29: 404 | P29: 10 | Q29: 414 | R29: 10 | S29: 422 | T29: 8 | U29: 428 | V29: 6 | W29: 435 | X29: 7 | Y29: 442 | Z29: 7 | AA29: 452 | AB29: 10 | AC29: 10 | AD29: 0 | AE29: 0 | AG29: 3 | AH29: 20 | AI29: 33
A30: 29 | B30: ELEUTERIA DOMITILA PARIAMACHI DE PAZ | C30: B | D30: 17 | E30: 16 | F30: 0 | G30: 16 | H30: 0 | I30: 16 | J30: 2 | K30: 18 | L30: 3 | M30: 21 | N30: 1 | O30: 22 | P30: 0 | Q30: 22 | R30: 0 | S30: 23 | T30: 1 | U30: 23 | V30: 0 | W30: 23 | X30: 0 | Y30: 24 | Z30: 1 | AA30: 24 | AB30: 0 | AC30: 5 | AD30: 0 | AE30: 0 | AG30: 3 | AH30: 0 | AI30: 8
A31: 30 | B31: LUZ DINA MIRAVAL HUERTA | C31: B | D31: 18 | E31: 632 | F31: 18 | G31: 650 | H31: 22 | I31: 672 | J31: 22 | K31: 694 | L31: 17 | M31: 711 | N31: 15 | O31: 726 | P31: 16 | Q31: 742 | R31: 16 | S31: 753 | T31: 11 | U31: 765 | V31: 12 | W31: 777 | X31: 12 | Y31: 790 | Z31: 13 | AA31: 803 | AB31: 13 | AC31: 13 | AD31: 0 | AE31: 0 | AG31: 3 | AH31: 0 | AI31: 16
A32: 31 | B32: CAMILA HIDALGO | C32: B | D32: 21 | E32: 0 | F32: 0 | G32: 0 | H32: 5 | I32: 5 | J32: 3 | K32: 3 | L32: 4 | M32: 7 | N32: 3 | O32: 10 | P32: 9 | Q32: 19 | R32: 9 | S32: 28 | T32: 9 | U32: 36 | V32: 8 | W32: 47 | X32: 11 | Y32: 60 | Z32: 13 | AA32: 72 | AB32: 12 | AC32: 12 | AD32: 0 | AE32: 0 | AG32: 3 | AH32: 0 | AI32: 15
A33: 32 | B33: JANET FERNANDEZ MINAYA | C33: B | D33: 29 | F33: 0 | H33: 0 | I33: 0 | J33: 19 | K33: 19 | L33: 9 | M33: 28 | N33: 4 | O33: 32 | P33: 5 | Q33: 37 | R33: 5 | S33: 45 | T33: 8 | U33: 52 | V33: 7 | W33: 66 | X33: 14 | Y33: 78 | Z33: 12 | AA33: 88 | AB33: 10 | AC33: 10 | AD33: 0 | AE33: 0 | AF33: 100 | AG33: 3 | AH33: 0 | AI33: 113
A34: 33 | B34: ODILON CERNA ROMERO | C34: C | D34: 1 | E34: 1726 | F34: 16 | G34: 1742 | H34: 15 | I34: 1757 | J34: 13 | K34: 1770 | L34: 14 | M34: 1784 | N34: 13 | O34: 1797 | P34: 12 | Q34: 1809 | R34: 12 | S34: 1819 | T34: 10 | U34: 1831 | V34: 12 | W34: 1845 | X34: 14 | Y34: 1859 | Z34: 14 | AA34: 1873 | AB34: 14 | AC34: 14 | AD34: 0 | AE34: 0 | AG34: 3 | AH34: 20 | AI34: 37
A35: 34 | B35: OLGA FLORENTINA HUERTA AGAMA | C35: C | D35: 2 | E35: 796 | F35: 5 | G35: 801 | H35: 17 | I35: 818 | J35: 2 | K35: 820 | L35: 2 | M35: 822 | N35: 1 | O35: 823 | P35: 2 | Q35: 825 | R35: 2 | S35: 826 | T35: 1 | U35: 827 | V35: 1 | W35: 829 | X35: 2 | Y35: 830 | Z35: 1 | AA35: 833 | AB35: 3 | AC35: 5 | AD35: 0 | AE35: 0 | AG35: 3 | AH35: 0 | AI35: 8
A36: 35 | B36: TIMOTEO ROMERO JULCA | C36: C | D36: 4 | E36: 2918 | F36: 20 | G36: 2938 | H36: 32 | I36: 2970 | J36: 30 | K36: 3000 | L36: 29 | M36: 3029 | N36: 22 | O36: 3051 | P36: 15 | Q36: 3066 | R36: 15 | S36: 3085 | T36: 19 | U36: 3106 | V36: 21 | W36: 3122 | X36: 16 | Y36: 3150 | Z36: 28 | AA36: 3175 | AB36: 25 | AC36: 25 | AD36: 0 | AE36: 0 | AG36: 3 | AH36: 0 | AI36: 28
A37: 36 | B37: AGAPITO PRINICIPE SALINAS | C37: C | D37: 5 | E37: 3725 | F37: 22 | G37: 3747 | H37: 21 | I37: 3768 | J37: 19 | K37: 3787 | L37: 19 | M37: 3806 | N37: 18 | O37: 3824 | P37: 11 | Q37: 3835 | R37: 11 | S37: 3845 | T37: 10 | U37: 3859 | V37: 14 | W37: 3869 | X37: 10 | Y37: 3884 | Z37: 15 | AA37: 3899 | AB37: 15 | AC37: 15 | AD37: 0 | AE37: 0 | AG37: 3 | AH37: 0 | AI37: 18
A38: 37 | B38: DIANA JARA TRUJILLO | C38: C | D38: 6 | E38: 150 | F38: 22 | G38: 172 | H38: 23 | I38: 195 | J38: 19 | K38: 214 | L38: 15 | M38: 229 | N38: 16 | O38: 245 | P38: 21 | Q38: 266 | R38: 21 | S38: 283 | T38: 17 | U38: 299 | V38: 16 | W38: 324 | X38: 25 | Y38: 350 | Z38: 26 | AA38: 370 | AB38: 20 | AC38: 20 | AD38: 0 | AE38: 0 | AG38: 3 | AH38: 40 | AI38: 63
A39: 38 | B39: VICTOR LOPEZ TRUJILLO | C39: C | D39: 7 | E39: 2096 | F39: 43 | G39: 2139 | H39: 27 | I39: 2166 | J39: 20 | K39: 2186 | L39: 15 | M39: 2201 | N39: 14 | O39: 2215 | P39: 11 | Q39: 2226 | R39: 11 | S39: 2236 | T39: 10 | U39: 2246 | V39: 10 | W39: 2260 | X39: 14 | Y39: 2276 | Z39: 16 | AA39: 2288 | AB39: 12 | AC39: 12 | AD39: 0 | AE39: 0 | AG39: 3 | AH39: 40 | AI39: 55
A40: 39 | B40: JULISSA BARRETO QUITO | C40: C | D40: 8 | E40: 156 | F40: 0 | G40: 156 | H40: 1 | I40: 157 | J40: 0 | K40: 157 | L40: 0 | M40: 157 | N40: 1 | O40: 158 | P40: 4 | Q40: 162 | R40: 4 | S40: 167 | T40: 5 | U40: 170 | V40: 3 | W40: 175 | X40: 5 | Y40: 179 | Z40: 4 | AA40: 184 | AB40: 5 | AC40: 5 | AD40: 8 | AE40: 0 | AG40: 3 | AH40: 20 | AI40: 36
A41: 40 | B41: JAZMIN QUITO SANCHEZ | C41: C | D41: 8-B | E41: 509 | F41: 16 | G41: 525 | H41: 22 | I41: 547 | J41: 16 | K41: 563 | L41: 15 | M41: 578 | N41: 14 | O41: 592 | P41: 14 | Q41: 606 | R41: 14 | S41: 618 | T41: 12 | U41: 631 | V41: 13 | W41: 645 | X41: 14 | Y41: 668 | Z41: 23 | AA41: 689 | AB41: 21 | AC41: 21 | AD41: 0 | AE41: 0 | AG41: 3 | AH41: 0 | AI41: 24
A42: 41 | B42: JUAN UCULMANA SANCHEZ | C42: C | D42: 9 | E42: 2002 | F42: 5 | G42: 2007 | H42: 3 | I42: 2010 | J42: 29 | K42: 2039 | L42: 6 | M42: 2045 | N42: 4 | O42: 2049 | P42: 1 | Q42: 2050 | R42: 1 | S42: 2050 | T42: 0 | U42: 2050 | V42: 0 | W42: 2060 | X42: 10 | Y42: 2062 | Z42: 2 | AA42: 2064 | AB42: 2 | AC42: 5 | AD42: 0 | AE42: 0 | AG42: 3 | AH42: 0 | AI42: 8
...
