Workbook

Sheet Cobranza
A1: n | B1: Nombres | C1: MZ | D1: LT | E1: TIPO CONVENIO | F1: MAYOR 65 | G1: NO COBRO | H1: Costo x m3 | I1: Marcación anterior | J1: Marcación actual | K1: m3 | L1: Total mes actual | M1: MES ANTERIOR | N1: Corte y reconexión | O1: Convenio | P1: Mant. | Q1: Reunion/Faena | R1: techado | S1: Devolucion | T1: blancos | U1: Ajuste | V1: Total | W1: Yape rep | X1: Monto Efectivo | Y1: Estado | Z1: Fecha | AA1: Medio | AB1: Comentario | AC1: Estado del servicio | AD1: corte por consumo | AE1: Corte por faena | AF1: Efectivo | AG1: Yape | AH1: Llave1 | AI1: LLAVE (Mz, Lt)
A2: 1 | B2: MARCELINA OBREGON DE AVILA | C2: A | D2: 1 | H2: 1 | I2: 2 | J2: 11 | K2: 9 | L2: 9 | N2: 0 | O2: 100 | P2: 3 | V2: =SUM(L2:U2) -> 112 | W2: =IFERROR(__xludf.DUMMYFUNCTION("IFERROR( SUM( FILTER( Reporte!$E:$E, REGEXMATCH(Reporte!$A:$A, ""(?i)(TE PAGÓ|PAGASTE)""), Reporte!$H:$H & """" = AH2 & """" ) ), 0 )"),112) -> 112 | X2: =IFERROR(__xludf.DUMMYFUNCTION("IFERROR( SUM( FILTER( Efectivo!$C:$C, Efectivo!$D:$D & """" = AH2 & """" ) ), 0 )"),0) -> 0 | Y2: c | AA2: y | AD2: =IF(AND(L2>0, M2>=8, NOT(OR(Y2="C", Y2="c"))), "CORTE", "") | AE2: =IF( OR( AND(#REF!>0, OR(Y2="C", Y2="c"), U2<0), AND(#REF!>0, Y2="") ), "CORTE", "" ) -> #REF! | AF2: =IF(AND(LEN(Y2)>0,LEN(AA2)=0),V2,0) -> 0 | AG2: =IF(AND(LEN(Y2)>0,TRIM(AA2)="Y"),V2,0) -> 112 | AH2: =TRIM(UPPER(C2)) -> A | AI2: =TRIM(UPPER(C2)) & "-" & TRIM(UPPER(D2)) -> A-1
A3: 2 | B3: ROSA AURORA ROCA VIDAL | C3: A | D3: 2 | H3: 1 | I3: 2678 | J3: 2703 | K3: 25 | L3: 25 | M3: 33 | N3: 0 | O3: 0 | P3: 3 | V3: =SUM(L3:Q3) -> 61 | W3: =IFERROR(__xludf.DUMMYFUNCTION("IFERROR( SUM( FILTER( Reporte!$E:$E, REGEXMATCH(Reporte!$A:$A, ""(?i)(TE PAGÓ|PAGASTE)""), Reporte!$H:$H & """" = AH3 & """" ) ), 0 )"),61) -> 61 | X3: =IFERROR(__xludf.DUMMYFUNCTION("IFERROR( SUM( FILTER( Efectivo!$C:$C, Efectivo!$D:$D & """" = AH3 & """" ) ), 0 )"),0) -> 0 | Y3: c | AA3: y | AD3: =IF(AND(L3>0, M3>=8, NOT(OR(Y3="C", Y3="c"))), "CORTE", "") | AE3: =IF( OR( AND(#REF!>0, OR(Y3="C", Y3="c"), U3<0), AND(#REF!>0, Y3="") ), "CORTE", "" ) -> #REF! | AF3: =IF(AND(LEN(Y3)>0,LEN(AA3)=0),V3,0) -> 0 | AG3: =IF(AND(LEN(Y3)>0,TRIM(AA3)="Y"),V3,0) -> 61 | AH3: =TRIM(UPPER(C3)) -> A | AI3: =TRIM(UPPER(C3)) & "-" & TRIM(UPPER(D3)) -> A-2
A4: 3 | B4: LINDA PAJUELO COCHACHIN | C4: A | D4: 3 | H4: 1 | I4: 22 | J4: 22 | K4: 5 | L4: 5 | N4: 0 | P4: 3 | V4: =SUM(L4:Q4) -> 8 | W4: =IFERROR(__xludf.DUMMYFUNCTION("IFERROR( SUM( FILTER( Reporte!$E:$E, REGEXMATCH(Reporte!$A:$A, ""(?i)(TE PAGÓ|PAGASTE)""), Reporte!$H:$H & """" = AH4 & """" ) ), 0 )"),8) -> 8 | X4: =IFERROR(__xludf.DUMMYFUNCTION("IFERROR( SUM( FILTER( Efectivo!$C:$C, Efectivo!$D:$D & """" = AH4 & """" ) ), 0 )"),0) -> 0 | Y4: c | AA4: y | AD4: =IF(AND(L4>0, M4>=8, NOT(OR(Y4="C", Y4="c"))), "CORTE", "") | AE4: =IF( OR( AND(#REF!>0, OR(Y4="C", Y4="c"), U4<0), AND(#REF!>0, Y4="") ), "CORTE", "" ) -> #REF! | AF4: =IF(AND(LEN(Y4)>0,LEN(AA4)=0),V4,0) -> 0 | AG4: =IF(AND(LEN(Y4)>0,TRIM(AA4)="Y"),V4,0) -> 8 | AH4: =TRIM(UPPER(C4)) -> A | AI4: =TRIM(UPPER(C4)) & "-" & TRIM(UPPER(D4)) -> A-3
A5: 4 | B5: YOLANDA ESPINOZA JAIMES | C5: A | D5: 4 | H5: 1 | I5: 0 | J5: 2 | K5: 2 | L5: 5 | N5: 0 | O5: 0 | P5: 3 | V5: =SUM(L5:Q5) -> 8 | W5: =IFERROR(__xludf.DUMMYFUNCTION("IFERROR( SUM( FILTER( Reporte!$E:$E, REGEXMATCH(Reporte!$A:$A, ""(?i)(TE PAGÓ|PAGASTE)""), Reporte!$H:$H & """" = AH5 & """" ) ), 0 )"),0) -> 0 | X5: =IFERROR(__xludf.DUMMYFUNCTION("IFERROR( SUM( FILTER( Efectivo!$C:$C, Efectivo!$D:$D & """" = AH5 & """" ) ), 0 )"),0) -> 0 | AD5: =IF(AND(L5>0, M5>=8, NOT(OR(Y5="C", Y5="c"))), "CORTE", "") | AE5: =IF( OR( AND(#REF!>0, OR(Y5="C", Y5="c"), U5<0), AND(#REF!>0, Y5="") ), "CORTE", "" ) -> #REF! | AF5: =IF(AND(LEN(Y5)>0,LEN(AA5)=0),V5,0) -> 0 | AG5: =IF(AND(LEN(Y5)>0,TRIM(AA5)="Y"),V5,0) -> 0 | AH5: =TRIM(UPPER(C5)) -> A | AI5: =TRIM(UPPER(C5)) & "-" & TRIM(UPPER(D5)) -> A-4
A6: 5 | B6: JULIA AGAMA CUZCO | C6: A | D6: 5 | H6: 1 | I6: 3441 | J6: 16 | K6: 16 | L6: 16 | N6: 0 | O6: 25 | P6: 3 | V6: =SUM(L6:Q6) -> 44 | W6: =IFERROR(__xludf.DUMMYFUNCTION("IFERROR( SUM( FILTER( Reporte!$E:$E, REGEXMATCH(Reporte!$A:$A, ""(?i)(TE PAGÓ|PAGASTE)""), Reporte!$H:$H & """" = AH6 & """" ) ), 0 )"),0) -> 0 | X6: =IFERROR(__xludf.DUMMYFUNCTION("IFERROR( SUM( FILTER( Efectivo!$C:$C, Efectivo!$D:$D & """" = AH6 & """" ) ), 0 )"),44) -> 44 | Y6: c | AD6: =IF(AND(L6>0, M6>=8, NOT(OR(Y6="C", Y6="c"))), "CORTE", "") | AE6: =IF( OR( AND(#REF!>0, OR(Y6="C", Y6="c"), U6<0), AND(#REF!>0, Y6="") ), "CORTE", "" ) -> #REF! | AF6: =IF(AND(LEN(Y6)>0,LEN(AA6)=0),V6,0) -> 44 | AG6: =IF(AND(LEN(Y6)>0,TRIM(AA6)="Y"),V6,0) -> 0 | AH6: =TRIM(UPPER(C6)) -> A | AI6: =TRIM(UPPER(C6)) & "-" & TRIM(UPPER(D6)) -> A-5
A7: 6 | B7: ESTEBAN REYES SANCHEZ | C7: A | D7: 6 | H7: 1 | I7: 2 | J7: 26 | K7: 24 | L7: 24 | N7: 0 | O7: 25 | P7: 3 | V7: =SUM(L7:Q7) -> 52 | W7: =IFERROR(__xludf.DUMMYFUNCTION("IFERROR( SUM( FILTER( Reporte!$E:$E, REGEXMATCH(Reporte!$A:$A, ""(?i)(TE PAGÓ|PAGASTE)""), Reporte!$H:$H & """" = AH7 & """" ) ), 0 )"),52) -> 52 | X7: =IFERROR(__xludf.DUMMYFUNCTION("IFERROR( SUM( FILTER( Efectivo!$C:$C, Efectivo!$D:$D & """" = AH7 & """" ) ), 0 )"),0) -> 0 | Y7: c | AA7: y | AD7: =IF(AND(L7>0, M7>=8, NOT(OR(Y7="C", Y7="c"))), "CORTE", "") | AE7: =IF( OR( AND(#REF!>0, OR(Y7="C", Y7="c"), U7<0), AND(#REF!>0, Y7="") ), "CORTE", "" ) -> #REF! | AF7: =IF(AND(LEN(Y7)>0,LEN(AA7)=0),V7,0) -> 0 | AG7: =IF(AND(LEN(Y7)>0,TRIM(AA7)="Y"),V7,0) -> 52 | AH7: =TRIM(UPPER(C7)) -> A | AI7: =TRIM(UPPER(C7)) & "-" & TRIM(UPPER(D7)) -> A-6
A8: 7 | B8: JUAN CARLOS MELGAREJO BEDON | C8: A | D8: 7 | H8: 1 | I8: 1752 | J8: 1766 | K8: 14 | L8: 14 | N8: 0 | P8: 3 | V8: =SUM(L8:U8) -> 17 | W8: =IFERROR(__xludf.DUMMYFUNCTION("IFERROR( SUM( FILTER( Reporte!$E:$E, REGEXMATCH(Reporte!$A:$A, ""(?i)(TE PAGÓ|PAGASTE)""), Reporte!$H:$H & """" = AH8 & """" ) ), 0 )"),17) -> 17 | X8: =IFERROR(__xludf.DUMMYFUNCTION("IFERROR( SUM( FILTER( Efectivo!$C:$C, Efectivo!$D:$D & """" = AH8 & """" ) ), 0 )"),0) -> 0 | Y8: c | AA8: y | AD8: =IF(AND(L8>0, M8>=8, NOT(OR(Y8="C", Y8="c"))), "CORTE", "") | AE8: =IF( OR( AND(#REF!>0, OR(Y8="C", Y8="c"), U8<0), AND(#REF!>0, Y8="") ), "CORTE", "" ) -> #REF! | AF8: =IF(AND(LEN(Y8)>0,LEN(AA8)=0),V8,0) -> 0 | AG8: =IF(AND(LEN(Y8)>0,TRIM(AA8)="Y"),V8,0) -> 17 | AH8: =TRIM(UPPER(C8)) -> A | AI8: =TRIM(UPPER(C8)) & "-" & TRIM(UPPER(D8)) -> A-7
A9: 8 | B9: VICTOR MELGAREJO CORCINO | C9: A | D9: 8 | H9: 1 | I9: 6395 | J9: 26 | K9: 26 | L9: 26 | M9: 27 | N9: 20 | O9: 25 | P9: 3 | V9: =SUM(L9:U9) -> 101 | W9: =IFERROR(__xludf.DUMMYFUNCTION("IFERROR( SUM( FILTER( Reporte!$E:$E, REGEXMATCH(Reporte!$A:$A, ""(?i)(TE PAGÓ|PAGASTE)""), Reporte!$H:$H & """" = AH9 & """" ) ), 0 )"),101) -> 101 | X9: =IFERROR(__xludf.DUMMYFUNCTION("IFERROR( SUM( FILTER( Efectivo!$C:$C, Efectivo!$D:$D & """" = AH9 & """" ) ), 0 )"),0) -> 0 | Y9: c | AA9: y | AD9: =IF(AND(L9>0, M9>=8, NOT(OR(Y9="C", Y9="c"))), "CORTE", "") | AE9: =IF( OR( AND(#REF!>0, OR(Y9="C", Y9="c"), U9<0), AND(#REF!>0, Y9="") ), "CORTE", "" ) -> #REF! | AF9: =IF(AND(LEN(Y9)>0,LEN(AA9)=0),V9,0) -> 0 | AG9: =IF(AND(LEN(Y9)>0,TRIM(AA9)="Y"),V9,0) -> 101 | AH9: =TRIM(UPPER(C9)) -> A | AI9: =TRIM(UPPER(C9)) & "-" & TRIM(UPPER(D9)) -> A-8
A10: 9 | B10: JHONI MELGAREJO BEDON | C10: A | D10: 8A | H10: 1 | I10: 182 | J10: 186 | K10: 4 | L10: 5 | N10: 0 | P10: 3 | V10: =SUM(L10:Q10) -> 8 | W10: =IFERROR(__xludf.DUMMYFUNCTION("IFERROR( SUM( FILTER( Reporte!$E:$E, REGEXMATCH(Reporte!$A:$A, ""(?i)(TE PAGÓ|PAGASTE)""), Reporte!$H:$H & """" = AH10 & """" ) ), 0 )"),8) -> 8 | X10: =IFERROR(__xludf.DUMMYFUNCTION("IFERROR( SUM( FILTER( Efectivo!$C:$C, Efectivo!$D:$D & """" = AH10 & """" ) ), 0 )"),0) -> 0 | Y10: c | AA10: y | AD10: =IF(AND(L10>0, M10>=8, NOT(OR(Y10="C", Y10="c"))), "CORTE", "") | AE10: =IF( OR( AND(#REF!>0, OR(Y10="C", Y10="c"), U10<0), AND(#REF!>0, Y10="") ), "CORTE", "" ) -> #REF! | AF10: =IF(AND(LEN(Y10)>0,LEN(AA10)=0),V10,0) -> 0 | AG10: =IF(AND(LEN(Y10)>0,TRIM(AA10)="Y"),V10,0) -> 8 | AH10: =TRIM(UPPER(C10)) -> A | AI10: =TRIM(UPPER(C10)) & "-" & TRIM(UPPER(D10)) -> A-8A
A11: 10 | B11: ALEJANDRO MELGAREJO ESPINOZA | C11: A | D11: 9 | H11: 1 | I11: 2198 | J11: 2240 | K11: 42 | L11: 42 | N11: 0 | P11: 3 | V11: =SUM(L11:Q11) -> 45 | W11: =IFERROR(__xludf.DUMMYFUNCTION("IFERROR( SUM( FILTER( Reporte!$E:$E, REGEXMATCH(Reporte!$A:$A, ""(?i)(TE PAGÓ|PAGASTE)""), Reporte!$H:$H & """" = AH11 & """" ) ), 0 )"),45) -> 45 | X11: =IFERROR(__xludf.DUMMYFUNCTION("IFERROR( SUM( FILTER( Efectivo!$C:$C, Efectivo!$D:$D & """" = AH11 & """" ) ), 0 )"),0) -> 0 | Y11: c | AA11: y | AD11: =IF(AND(L11>0, M11>=8, NOT(OR(Y11="C", Y11="c"))), "CORTE", "") | AE11: =IF( OR( AND(#REF!>0, OR(Y11="C", Y11="c"), U11<0), AND(#REF!>0, Y11="") ), "CORTE", "" ) -> #REF! | AF11: =IF(AND(LEN(Y11)>0,LEN(AA11)=0),V11,0) -> 0 | AG11: =IF(AND(LEN(Y11)>0,TRIM(AA11)="Y"),V11,0) -> 45 | AH11: =TRIM(UPPER(C11)) -> A | AI11: =TRIM(UPPER(C11)) & "-" & TRIM(UPPER(D11)) -> A-9
A12: 11 | B12: ISABEL PUNTILLO VEGA | C12: A | D12: 10 | H12: 1 | I12: 672 | J12: 679 | K12: 7 | L12: 7 | N12: 0 | P12: 3 | V12: =SUM(L12:Q12) -> 10 | W12: =IFERROR(__xludf.DUMMYFUNCTION("IFERROR( SUM( FILTER( Reporte!$E:$E, REGEXMATCH(Reporte!$A:$A, ""(?i)(TE PAGÓ|PAGASTE)""), Reporte!$H:$H & """" = AH12 & """" ) ), 0 )"),0) -> 0 | X12: =IFERROR(__xludf.DUMMYFUNCTION("IFERROR( SUM( FILTER( Efectivo!$C:$C, Efectivo!$D:$D & """" = AH12 & """" ) ), 0 )"),0) -> 0 | AD12: =IF(AND(L12>0, M12>=8, NOT(OR(Y12="C", Y12="c"))), "CORTE", "") | AE12: =IF( OR( AND(#REF!>0, OR(Y12="C", Y12="c"), U12<0), AND(#REF!>0, Y12="") ), "CORTE", "" ) -> #REF! | AF12: =IF(AND(LEN(Y12)>0,LEN(AA12)=0),V12,0) -> 0 | AG12: =IF(AND(LEN(Y12)>0,TRIM(AA12)="Y"),V12,0) -> 0 | AH12: =TRIM(UPPER(C12)) -> A | AI12: =TRIM(UPPER(C12)) & "-" & TRIM(UPPER(D12)) -> A-10
A13: 12 | B13: FELIX POZO CASTRO | C13: A | D13: 11 | H13: 1 | I13: 361 | J13: 363 | K13: 2 | L13: 5 | M13: 8 | N13: 0 | P13: 3 | V13: =SUM(L13:U13) -> 16 | W13: =IFERROR(__xludf.DUMMYFUNCTION("IFERROR( SUM( FILTER( Reporte!$E:$E, REGEXMATCH(Reporte!$A:$A, ""(?i)(TE PAGÓ|PAGASTE)""), Reporte!$H:$H & """" = AH13 & """" ) ), 0 )"),0) -> 0 | X13: =IFERROR(__xludf.DUMMYFUNCTION("IFERROR( SUM( FILTER( Efectivo!$C:$C, Efectivo!$D:$D & """" = AH13 & """" ) ), 0 )"),0) -> 0 | AD13: =IF(AND(L13>0, M13>=8, NOT(OR(Y13="C", Y13="c"))), "CORTE", "") -> CORTE | AE13: =IF( OR( AND(#REF!>0, OR(Y13="C", Y13="c"), U13<0), AND(#REF!>0, Y13="") ), "CORTE", "" ) -> #REF! | AF13: =IF(AND(LEN(Y13)>0,LEN(AA13)=0),V13,0) -> 0 | AG13: =IF(AND(LEN(Y13)>0,TRIM(AA13)="Y"),V13,0) -> 0 | AH13: =TRIM(UPPER(C13)) -> A | AI13: =TRIM(UPPER(C13)) & "-" & TRIM(UPPER(D13)) -> A-11
A14: 13 | B14: BACILIO UTRILLA FRANCISCO | C14: B | D14: 1 | H14: 1 | I14: 1 | J14: 13 | K14: 12 | L14: 12 | N14: 0 | P14: 3 | V14: =SUM(L14:Q14) -> 15 | W14: =IFERROR(__xludf.DUMMYFUNCTION("IFERROR( SUM( FILTER( Reporte!$E:$E, REGEXMATCH(Reporte!$A:$A, ""(?i)(TE PAGÓ|PAGASTE)""), Reporte!$H:$H & """" = AH14 & """" ) ), 0 )"),0) -> 0 | X14: =IFERROR(__xludf.DUMMYFUNCTION("IFERROR( SUM( FILTER( Efectivo!$C:$C, Efectivo!$D:$D & """" = AH14 & """" ) ), 0 )"),15) -> 15 | Y14: c | AD14: =IF(AND(L14>0, M14>=8, NOT(OR(Y14="C", Y14="c"))), "CORTE", "") | AE14: =IF( OR( AND(#REF!>0, OR(Y14="C", Y14="c"), U14<0), AND(#REF!>0, Y14="") ), "CORTE", "" ) -> #REF! | AF14: =IF(AND(LEN(Y14)>0,LEN(AA14)=0),V14,0) -> 15 | AG14: =IF(AND(LEN(Y14)>0,TRIM(AA14)="Y"),V14,0) -> 0 | AH14: =TRIM(UPPER(C14)) -> B | AI14: =TRIM(UPPER(C14)) & "-" & TRIM(UPPER(D14)) -> B-1
A15: 14 | B15: ESTEBAN REYNALDO ROSALES | C15: B | D15: 2 | H15: 1 | I15: 2294 | J15: 16 | K15: 16 | L15: 16 | N15: 0 | O15: 25 | P15: 3 | V15: =SUM(L15:Q15) -> 44 | W15: =IFERROR(__xludf.DUMMYFUNCTION("IFERROR( SUM( FILTER( Reporte!$E:$E, REGEXMATCH(Reporte!$A:$A, ""(?i)(TE PAGÓ|PAGASTE)""), Reporte!$H:$H & """" = AH15 & """" ) ), 0 )"),0) -> 0 | X15: =IFERROR(__xludf.DUMMYFUNCTION("IFERROR( SUM( FILTER( Efectivo!$C:$C, Efectivo!$D:$D & """" = AH15 & """" ) ), 0 )"),44) -> 44 | Y15: c | AD15: =IF(AND(L15>0, M15>=8, NOT(OR(Y15="C", Y15="c"))), "CORTE", "") | AE15: =IF( OR( AND(#REF!>0, OR(Y15="C", Y15="c"), U15<0), AND(#REF!>0, Y15="") ), "CORTE", "" ) -> #REF! | AF15: =IF(AND(LEN(Y15)>0,LEN(AA15)=0),V15,0) -> 44 | AG15: =IF(AND(LEN(Y15)>0,TRIM(AA15)="Y"),V15,0) -> 0 | AH15: =TRIM(UPPER(C15)) -> B | AI15: =TRIM(UPPER(C15)) & "-" & TRIM(UPPER(D15)) -> B-2
A16: 15 | B16: EDUARDO REYNALDO ROSALES | C16: B | D16: 3 | H16: 1 | I16: 822 | J16: 837 | K16: 15 | L16: 15 | N16: 0 | P16: 3 | V16: =SUM(L16:Q16) -> 18 | W16: =IFERROR(__xludf.DUMMYFUNCTION("IFERROR( SUM( FILTER( Reporte!$E:$E, REGEXMATCH(Reporte!$A:$A, ""(?i)(TE PAGÓ|PAGASTE)""), Reporte!$H:$H & """" = AH16 & """" ) ), 0 )"),0) -> 0 | X16: =IFERROR(__xludf.DUMMYFUNCTION("IFERROR( SUM( FILTER( Efectivo!$C:$C, Efectivo!$D:$D & """" = AH16 & """" ) ), 0 )"),18) -> 18 | Y16: c | AD16: =IF(AND(L16>0, M16>=8, NOT(OR(Y16="C", Y16="c"))), "CORTE", "") | AE16: =IF( OR( AND(#REF!>0, OR(Y16="C", Y16="c"), U16<0), AND(#REF!>0, Y16="") ), "CORTE", "" ) -> #REF! | AF16: =IF(AND(LEN(Y16)>0,LEN(AA16)=0),V16,0) -> 18 | AG16: =IF(AND(LEN(Y16)>0,TRIM(AA16)="Y"),V16,0) -> 0 | AH16: =TRIM(UPPER(C16)) -> B | AI16: =TRIM(UPPER(C16)) & "-" & TRIM(UPPER(D16)) -> B-3
A17: 16 | B17: MELINA J. JUAREZ TOLEDO DE MORENO | C17: B | D17: 4 | H17: 1 | I17: 626 | J17: 641 | K17: 15 | L17: 15 | N17: 0 | P17: 3 | V17: =SUM(L17:Q17) -> 18 | W17: =IFERROR(__xludf.DUMMYFUNCTION("IFERROR( SUM( FILTER( Reporte!$E:$E, REGEXMATCH(Reporte!$A:$A, ""(?i)(TE PAGÓ|PAGASTE)""), Reporte!$H:$H & """" = AH17 & """" ) ), 0 )"),0) -> 0 | X17: =IFERROR(__xludf.DUMMYFUNCTION("IFERROR( SUM( FILTER( Efectivo!$C:$C, Efectivo!$D:$D & """" = AH17 & """" ) ), 0 )"),0) -> 0 | AD17: =IF(AND(L17>0, M17>=8, NOT(OR(Y17="C", Y17="c"))), "CORTE", "") | AE17: =IF( OR( AND(#REF!>0, OR(Y17="C", Y17="c"), U17<0), AND(#REF!>0, Y17="") ), "CORTE", "" ) -> #REF! | AF17: =IF(AND(LEN(Y17)>0,LEN(AA17)=0),V17,0) -> 0 | AG17: =IF(AND(LEN(Y17)>0,TRIM(AA17)="Y"),V17,0) -> 0 | AH17: =TRIM(UPPER(C17)) -> B | AI17: =TRIM(UPPER(C17)) & "-" & TRIM(UPPER(D17)) -> B-4
A18: 17 | B18: POMPEYO CELESTINO LLIUYA | C18: B | D18: 5 | H18: 1 | I18: 23 | J18: 59 | K18: 36 | L18: 36 | N18: 0 | O18: 25 | P18: 3 | V18: =SUM(L18:Q18) -> 64 | W18: =IFERROR(__xludf.DUMMYFUNCTION("IFERROR( SUM( FILTER( Reporte!$E:$E, REGEXMATCH(Reporte!$A:$A, ""(?i)(TE PAGÓ|PAGASTE)""), Reporte!$H:$H & """" = AH18 & """" ) ), 0 )"),0) -> 0 | X18: =IFERROR(__xludf.DUMMYFUNCTION("IFERROR( SUM( FILTER( Efectivo!$C:$C, Efectivo!$D:$D & """" = AH18 & """" ) ), 0 )"),0) -> 0 | AD18: =IF(AND(L18>0, M18>=8, NOT(OR(Y18="C", Y18="c"))), "CORTE", "") | AE18: =IF( OR( AND(#REF!>0, OR(Y18="C", Y18="c"), U18<0), AND(#REF!>0, Y18="") ), "CORTE", "" ) -> #REF! | AF18: =IF(AND(LEN(Y18)>0,LEN(AA18)=0),V18,0) -> 0 | AG18: =IF(AND(LEN(Y18)>0,TRIM(AA18)="Y"),V18,0) -> 0 | AH18: =TRIM(UPPER(C18)) -> B | AI18: =TRIM(UPPER(C18)) & "-" & TRIM(UPPER(D18)) -> B-5
A19: 18 | B19: ROSA VICTORIA MILLA MORALES | C19: B | D19: 6 | H19: 1 | I19: 11 | J19: 32 | K19: 21 | L19: 21 | N19: 0 | O19: 25 | P19: 3 | V19: =SUM(L19:U19) -> 49 | W19: =IFERROR(__xludf.DUMMYFUNCTION("IFERROR( SUM( FILTER( Reporte!$E:$E, REGEXMATCH(Reporte!$A:$A, ""(?i)(TE PAGÓ|PAGASTE)""), Reporte!$H:$H & """" = AH19 & """" ) ), 0 )"),49) -> 49 | X19: =IFERROR(__xludf.DUMMYFUNCTION("IFERROR( SUM( FILTER( Efectivo!$C:$C, Efectivo!$D:$D & """" = AH19 & """" ) ), 0 )"),0) -> 0 | Y19: c | AA19: y | AD19: =IF(AND(L19>0, M19>=8, NOT(OR(Y19="C", Y19="c"))), "CORTE", "") | AE19: =IF( OR( AND(#REF!>0, OR(Y19="C", Y19="c"), U19<0), AND(#REF!>0, Y19="") ), "CORTE", "" ) -> #REF! | AF19: =IF(AND(LEN(Y19)>0,LEN(AA19)=0),V19,0) -> 0 | AG19: =IF(AND(LEN(Y19)>0,TRIM(AA19)="Y"),V19,0) -> 49 | AH19: =TRIM(UPPER(C19)) -> B | AI19: =TRIM(UPPER(C19)) & "-" & TRIM(UPPER(D19)) -> B-6
A20: 19 | B20: LIRIA PARIAMACHI DE PAZ | C20: B | D20: 7 | H20: 1 | I20: 2713 | J20: 99978 | K20: 14 | L20: 14 | N20: 0 | O20: 25 | P20: 3 | Q20: 30 | V20: =SUM(L20:Q20) -> 72 | W20: =IFERROR(__xludf.DUMMYFUNCTION("IFERROR( SUM( FILTER( Reporte!$E:$E, REGEXMATCH(Reporte!$A:$A, ""(?i)(TE PAGÓ|PAGASTE)""), Reporte!$H:$H & """" = AH20 & """" ) ), 0 )"),0) -> 0 | X20: =IFERROR(__xludf.DUMMYFUNCTION("IFERROR( SUM( FILTER( Efectivo!$C:$C, Efectivo!$D:$D & """" = AH20 & """" ) ), 0 )"),0) -> 0 | AD20: =IF(AND(L20>0, M20>=8, NOT(OR(Y20="C", Y20="c"))), "CORTE", "") | AE20: =IF( OR( AND(#REF!>0, OR(Y20="C", Y20="c"), U20<0), AND(#REF!>0, Y20="") ), "CORTE", "" ) -> #REF! | AF20: =IF(AND(LEN(Y20)>0,LEN(AA20)=0),V20,0) -> 0 | AG20: =IF(AND(LEN(Y20)>0,TRIM(AA20)="Y"),V20,0) -> 0 | AH20: =TRIM(UPPER(C20)) -> B | AI20: =TRIM(UPPER(C20)) & "-" & TRIM(UPPER(D20)) -> B-7
A21: 20 | B21: ROSALINA OLIMPIA CIRIACO SOTELO | C21: B | D21: 8 | H21: 1 | I21: 7 | J21: 21 | K21: 14 | L21: 14 | M21: 15 | N21: 0 | O21: 25 | P21: 3 | V21: =SUM(L21:Q21) -> 57 | W21: =IFERROR(__xludf.DUMMYFUNCTION("IFERROR( SUM( FILTER( Reporte!$E:$E, REGEXMATCH(Reporte!$A:$A, ""(?i)(TE PAGÓ|PAGASTE)""), Reporte!$H:$H & """" = AH21 & """" ) ), 0 )"),57) -> 57 | X21: =IFERROR(__xludf.DUMMYFUNCTION("IFERROR( SUM( FILTER( Efectivo!$C:$C, Efectivo!$D:$D & """" = AH21 & """" ) ), 0 )"),0) -> 0 | Y21: c | AA21: y | AD21: =IF(AND(L21>0, M21>=8, NOT(OR(Y21="C", Y21="c"))), "CORTE", "") | AE21: =IF( OR( AND(#REF!>0, OR(Y21="C", Y21="c"), U21<0), AND(#REF!>0, Y21="") ), "CORTE", "" ) -> #REF! | AF21: =IF(AND(LEN(Y21)>0,LEN(AA21)=0),V21,0) -> 0 | AG21: =IF(AND(LEN(Y21)>0,TRIM(AA21)="Y"),V21,0) -> 57 | AH21: =TRIM(UPPER(C21)) -> B | AI21: =TRIM(UPPER(C21)) & "-" & TRIM(UPPER(D21)) -> B-8
A22: 21 | B22: ALEJANDRO RAPRAY VELASQUEZ | C22: B | D22: 9 | F22: 1 | H22: 1 | I22: 65 | J22: 72 | K22: 7 | L22: 7 | N22: 0 | P22: 3 | V22: =SUM(L22:Q22) -> 10 | W22: =IFERROR(__xludf.DUMMYFUNCTION("IFERROR( SUM( FILTER( Reporte!$E:$E, REGEXMATCH(Reporte!$A:$A, ""(?i)(TE PAGÓ|PAGASTE)""), Reporte!$H:$H & """" = AH22 & """" ) ), 0 )"),0) -> 0 | X22: =IFERROR(__xludf.DUMMYFUNCTION("IFERROR( SUM( FILTER( Efectivo!$C:$C, Efectivo!$D:$D & """" = AH22 & """" ) ), 0 )"),0) -> 0 | AD22: =IF(AND(L22>0, M22>=8, NOT(OR(Y22="C", Y22="c"))), "CORTE", "") | AE22: =IF( OR( AND(#REF!>0, OR(Y22="C", Y22="c"), U22<0), AND(#REF!>0, Y22="") ), "CORTE", "" ) -> #REF! | AF22: =IF(AND(LEN(Y22)>0,LEN(AA22)=0),V22,0) -> 0 | AG22: =IF(AND(LEN(Y22)>0,TRIM(AA22)="Y"),V22,0) -> 0 | AH22: =TRIM(UPPER(C22)) -> B | AI22: =TRIM(UPPER(C22)) & "-" & TRIM(UPPER(D22)) -> B-9
A23: 22 | B23: ELVIRA PASCUALA MINAYA TAHUA | C23: B | D23: 11 | H23: 1 | I23: 10 | J23: 26 | K23: 16 | L23: 16 | N23: 0 | O23: 25 | P23: 3 | V23: =SUM(L23:Q23) -> 44 | W23: =IFERROR(__xludf.DUMMYFUNCTION("IFERROR( SUM( FILTER( Reporte!$E:$E, REGEXMATCH(Reporte!$A:$A, ""(?i)(TE PAGÓ|PAGASTE)""), Reporte!$H:$H & """" = AH23 & """" ) ), 0 )"),0) -> 0 | X23: =IFERROR(__xludf.DUMMYFUNCTION("IFERROR( SUM( FILTER( Efectivo!$C:$C, Efectivo!$D:$D & """" = AH23 & """" ) ), 0 )"),0) -> 0 | AD23: =IF(AND(L23>0, M23>=8, NOT(OR(Y23="C", Y23="c"))), "CORTE", "") | AE23: =IF( OR( AND(#REF!>0, OR(Y23="C", Y23="c"), U23<0), AND(#REF!>0, Y23="") ), "CORTE", "" ) -> #REF! | AF23: =IF(AND(LEN(Y23)>0,LEN(AA23)=0),V23,0) -> 0 | AG23: =IF(AND(LEN(Y23)>0,TRIM(AA23)="Y"),V23,0) -> 0 | AH23: =TRIM(UPPER(C23)) -> B | AI23: =TRIM(UPPER(C23)) & "-" & TRIM(UPPER(D23)) -> B-11
A24: 23 | B24: MARCELINO FELIX VILLAFANA PALLACA | C24: B | D24: 10 | H24: 1 | I24: 391 | J24: 399 | K24: 8 | L24: 8 | N24: 0 | P24: 3 | V24: =SUM(L24:Q24) -> 11 | W24: =IFERROR(__xludf.DUMMYFUNCTION("IFERROR( SUM( FILTER( Reporte!$E:$E, REGEXMATCH(Reporte!$A:$A, ""(?i)(TE PAGÓ|PAGASTE)""), Reporte!$H:$H & """" = AH24 & """" ) ), 0 )"),11) -> 11 | X24: =IFERROR(__xludf.DUMMYFUNCTION("IFERROR( SUM( FILTER( Efectivo!$C:$C, Efectivo!$D:$D & """" = AH24 & """" ) ), 0 )"),0) -> 0 | Y24: c | AA24: y | AD24: =IF(AND(L24>0, M24>=8, NOT(OR(Y24="C", Y24="c"))), "CORTE", "") | AE24: =IF( OR( AND(#REF!>0, OR(Y24="C", Y24="c"), U24<0), AND(#REF!>0, Y24="") ), "CORTE", "" ) -> #REF! | AF24: =IF(AND(LEN(Y24)>0,LEN(AA24)=0),V24,0) -> 0 | AG24: =IF(AND(LEN(Y24)>0,TRIM(AA24)="Y"),V24,0) -> 11 | AH24: =TRIM(UPPER(C24)) -> B | AI24: =TRIM(UPPER(C24)) & "-" & TRIM(UPPER(D24)) -> B-10
A25: 24 | B25: TEOFILO BRUNO RAMOS DE LA CRUZ | C25: B | D25: 12 | H25: 1 | I25: 2 | J25: 9 | K25: 7 | L25: 7 | M25: 11 | N25: 0 | P25: 3 | V25: =SUM(L25:U25) -> 21 | W25: =IFERROR(__xludf.DUMMYFUNCTION("IFERROR( SUM( FILTER( Reporte!$E:$E, REGEXMATCH(Reporte!$A:$A, ""(?i)(TE PAGÓ|PAGASTE)""), Reporte!$H:$H & """" = AH25 & """" ) ), 0 )"),0) -> 0 | X25: =IFERROR(__xludf.DUMMYFUNCTION("IFERROR( SUM( FILTER( Efectivo!$C:$C, Efectivo!$D:$D & """" = AH25 & """" ) ), 0 )"),21) -> 21 | Y25: c | AD25: =IF(AND(L25>0, M25>=8, NOT(OR(Y25="C", Y25="c"))), "CORTE", "") | AE25: =IF( OR( AND(#REF!>0, OR(Y25="C", Y25="c"), U25<0), AND(#REF!>0, Y25="") ), "CORTE", "" ) -> #REF! | AF25: =IF(AND(LEN(Y25)>0,LEN(AA25)=0),V25,0) -> 21 | AG25: =IF(AND(LEN(Y25)>0,TRIM(AA25)="Y"),V25,0) -> 0 | AH25: =TRIM(UPPER(C25)) -> B | AI25: =TRIM(UPPER(C25)) & "-" & TRIM(UPPER(D25)) -> B-12
A26: 25 | B26: ROSMERI SANCHEZ ESPADA | C26: B | D26: 12A | H26: 1 | I26: 359 | J26: 365 | K26: 6 | L26: 6 | N26: 0 | P26: 3 | V26: =SUM(L26:Q26) -> 9 | W26: =IFERROR(__xludf.DUMMYFUNCTION("IFERROR( SUM( FILTER( Reporte!$E:$E, REGEXMATCH(Reporte!$A:$A, ""(?i)(TE PAGÓ|PAGASTE)""), Reporte!$H:$H & """" = AH26 & """" ) ), 0 )"),0) -> 0 | X26: =IFERROR(__xludf.DUMMYFUNCTION("IFERROR( SUM( FILTER( Efectivo!$C:$C, Efectivo!$D:$D & """" = AH26 & """" ) ), 0 )"),0) -> 0 | AD26: =IF(AND(L26>0, M26>=8, NOT(OR(Y26="C", Y26="c"))), "CORTE", "") | AE26: =IF( OR( AND(#REF!>0, OR(Y26="C", Y26="c"), U26<0), AND(#REF!>0, Y26="") ), "CORTE", "" ) -> #REF! | AF26: =IF(AND(LEN(Y26)>0,LEN(AA26)=0),V26,0) -> 0 | AG26: =IF(AND(LEN(Y26)>0,TRIM(AA26)="Y"),V26,0) -> 0 | AH26: =TRIM(UPPER(C26)) -> B | AI26: =TRIM(UPPER(C26)) & "-" & TRIM(UPPER(D26)) -> B-12A
A27: 26 | B27: SALOME AGUSTINA DIAZ VARGAS | C27: B | D27: 13 | H27: 1 | I27: 293 | J27: 300 | K27: 7 | L27: 7 | N27: 0 | P27: 3 | V27: =SUM(L27:Q27) -> 10 | W27: =IFERROR(__xludf.DUMMYFUNCTION("IFERROR( SUM( FILTER( Reporte!$E:$E, REGEXMATCH(Reporte!$A:$A, ""(?i)(TE PAGÓ|PAGASTE)""), Reporte!$H:$H & """" = AH27 & """" ) ), 0 )"),10) -> 10 | X27: =IFERROR(__xludf.DUMMYFUNCTION("IFERROR( SUM( FILTER( Efectivo!$C:$C, Efectivo!$D:$D & """" = AH27 & """" ) ), 0 )"),0) -> 0 | Y27: c | AA27: y | AD27: =IF(AND(L27>0, M27>=8, NOT(OR(Y27="C", Y27="c"))), "CORTE", "") | AE27: =IF( OR( AND(#REF!>0, OR(Y27="C", Y27="c"), U27<0), AND(#REF!>0, Y27="") ), "CORTE", "" ) -> #REF! | AF27: =IF(AND(LEN(Y27)>0,LEN(AA27)=0),V27,0) -> 0 | AG27: =IF(AND(LEN(Y27)>0,TRIM(AA27)="Y"),V27,0) -> 10 | AH27: =TRIM(UPPER(C27)) -> B | AI27: =TRIM(UPPER(C27)) & "-" & TRIM(UPPER(D27)) -> B-13
A28: 27 | B28: MELISSA ISABEL PILLACA GARCIA | C28: B | D28: 15 | H28: 1 | I28: 1285 | J28: 1295 | K28: 10 | L28: 10 | N28: 0 | P28: 3 | V28: =SUM(L28:Q28) -> 13 | W28: =IFERROR(__xludf.DUMMYFUNCTION("IFERROR( SUM( FILTER( Reporte!$E:$E, REGEXMATCH(Reporte!$A:$A, ""(?i)(TE PAGÓ|PAGASTE)""), Reporte!$H:$H & """" = AH28 & """" ) ), 0 )"),13) -> 13 | X28: =IFERROR(__xludf.DUMMYFUNCTION("IFERROR( SUM( FILTER( Efectivo!$C:$C, Efectivo!$D:$D & """" = AH28 & """" ) ), 0 )"),0) -> 0 | Y28: c | AA28: y | AD28: =IF(AND(L28>0, M28>=8, NOT(OR(Y28="C", Y28="c"))), "CORTE", "") | AE28: =IF( OR( AND(#REF!>0, OR(Y28="C", Y28="c"), U28<0), AND(#REF!>0, Y28="") ), "CORTE", "" ) -> #REF! | AF28: =IF(AND(LEN(Y28)>0,LEN(AA28)=0),V28,0) -> 0 | AG28: =IF(AND(LEN(Y28)>0,TRIM(AA28)="Y"),V28,0) -> 13 | AH28: =TRIM(UPPER(C28)) -> B | AI28: =TRIM(UPPER(C28)) & "-" & TRIM(UPPER(D28)) -> B-15
A29: 28 | B29: ELEUTERIA DOMITILA PARIAMACHI DE PAZ | C29: B | D29: 16 | H29: 1 | I29: 34 | J29: 34 | K29: 5 | L29: 5 | N29: 0 | P29: 3 | V29: =SUM(L29:Q29) -> 8 | W29: =IFERROR(__xludf.DUMMYFUNCTION("IFERROR( SUM( FILTER( Reporte!$E:$E, REGEXMATCH(Reporte!$A:$A, ""(?i)(TE PAGÓ|PAGASTE)""), Reporte!$H:$H & """" = AH29 & """" ) ), 0 )"),0) -> 0 | X29: =IFERROR(__xludf.DUMMYFUNCTION("IFERROR( SUM( FILTER( Efectivo!$C:$C, Efectivo!$D:$D & """" = AH29 & """" ) ), 0 )"),0) -> 0 | AD29: =IF(AND(L29>0, M29>=8, NOT(OR(Y29="C", Y29="c"))), "CORTE", "") | AE29: =IF( OR( AND(#REF!>0, OR(Y29="C", Y29="c"), U29<0), AND(#REF!>0, Y29="") ), "CORTE", "" ) -> #REF! | AF29: =IF(AND(LEN(Y29)>0,LEN(AA29)=0),V29,0) -> 0 | AG29: =IF(AND(LEN(Y29)>0,TRIM(AA29)="Y"),V29,0) -> 0 | AH29: =TRIM(UPPER(C29)) -> B | AI29: =TRIM(UPPER(C29)) & "-" & TRIM(UPPER(D29)) -> B-16
A30: 29 | B30: LUZ DINA MIRAVAL HUERTA | C30: B | D30: 17 | H30: 1 | I30: 1065 | J30: 1093 | K30: 28 | L30: 28 | N30: 0 | P30: 3 | V30: =SUM(L30:Q30) -> 31 | W30: =IFERROR(__xludf.DUMMYFUNCTION("IFERROR( SUM( FILTER( Reporte!$E:$E, REGEXMATCH(Reporte!$A:$A, ""(?i)(TE PAGÓ|PAGASTE)""), Reporte!$H:$H & """" = AH30 & """" ) ), 0 )"),0) -> 0 | X30: =IFERROR(__xludf.DUMMYFUNCTION("IFERROR( SUM( FILTER( Efectivo!$C:$C, Efectivo!$D:$D & """" = AH30 & """" ) ), 0 )"),0) -> 0 | AD30: =IF(AND(L30>0, M30>=8, NOT(OR(Y30="C", Y30="c"))), "CORTE", "") | AE30: =IF( OR( AND(#REF!>0, OR(Y30="C", Y30="c"), U30<0), AND(#REF!>0, Y30="") ), "CORTE", "" ) -> #REF! | AF30: =IF(AND(LEN(Y30)>0,LEN(AA30)=0),V30,0) -> 0 | AG30: =IF(AND(LEN(Y30)>0,TRIM(AA30)="Y"),V30,0) -> 0 | AH30: =TRIM(UPPER(C30)) -> B | AI30: =TRIM(UPPER(C30)) & "-" & TRIM(UPPER(D30)) -> B-17
A31: 30 | B31: CLETO TENORIO MORI | C31: B | D31: 18 | H31: 1 | I31: 573 | J31: 577 | K31: 4 | L31: 5 | N31: 0 | P31: 3 | V31: =SUM(L31:Q31) -> 8 | W31: =IFERROR(__xludf.DUMMYFUNCTION("IFERROR( SUM( FILTER( Reporte!$E:$E, REGEXMATCH(Reporte!$A:$A, ""(?i)(TE PAGÓ|PAGASTE)""), Reporte!$H:$H & """" = AH31 & """" ) ), 0 )"),0) -> 0 | X31: =IFERROR(__xludf.DUMMYFUNCTION("IFERROR( SUM( FILTER( Efectivo!$C:$C, Efectivo!$D:$D & """" = AH31 & """" ) ), 0 )"),0) -> 0 | AD31: =IF(AND(L31>0, M31>=8, NOT(OR(Y31="C", Y31="c"))), "CORTE", "") | AE31: =IF( OR( AND(#REF!>0, OR(Y31="C", Y31="c"), U31<0), AND(#REF!>0, Y31="") ), "CORTE", "" ) -> #REF! | AF31: =IF(AND(LEN(Y31)>0,LEN(AA31)=0),V31,0) -> 0 | AG31: =IF(AND(LEN(Y31)>0,TRIM(AA31)="Y"),V31,0) -> 0 | AH31: =TRIM(UPPER(C31)) -> B | AI31: =TRIM(UPPER(C31)) & "-" & TRIM(UPPER(D31)) -> B-18
A32: 31 | B32: CAMILA HIDALGO | C32: B | D32: 21 | H32: 1 | I32: 187 | J32: 199 | K32: 12 | L32: 12 | P32: 3 | Q32: 0 | V32: =SUM(L32:Q32) -> 15 | W32: =IFERROR(__xludf.DUMMYFUNCTION("IFERROR( SUM( FILTER( Reporte!$E:$E, REGEXMATCH(Reporte!$A:$A, ""(?i)(TE PAGÓ|PAGASTE)""), Reporte!$H:$H & """" = AH32 & """" ) ), 0 )"),0) -> 0 | X32: =IFERROR(__xludf.DUMMYFUNCTION("IFERROR( SUM( FILTER( Efectivo!$C:$C, Efectivo!$D:$D & """" = AH32 & """" ) ), 0 )"),0) -> 0 | AB32: Pago | AD32: =IF(AND(L32>0, M32>=8, NOT(OR(Y32="C", Y32="c"))), "CORTE", "") | AE32: =IF( OR( AND(#REF!>0, OR(Y32="C", Y32="c"), U32<0), AND(#REF!>0, Y32="") ), "CORTE", "" ) -> #REF! | AF32: =IF(AND(LEN(Y32)>0,LEN(AA32)=0),V32,0) -> 0 | AG32: =IF(AND(LEN(Y32)>0,TRIM(AA32)="Y"),V32,0) -> 0 | AH32: =TRIM(UPPER(C32)) -> B | AI32: =TRIM(UPPER(C32)) & "-" & TRIM(UPPER(D32)) -> B-21
A33: 32 | B33: JANET FERNANDEZ MINAYA | C33: B | D33: 29 | E33: N | H33: 1 | I33: 183 | J33: 187 | K33: 4 | L33: 5 | M33: 8 | N33: 0 | O33: 40 | P33: 3 | V33: =SUM(L33:Q33) -> 56 | W33: =IFERROR(__xludf.DUMMYFUNCTION("IFERROR( SUM( FILTER( Reporte!$E:$E, REGEXMATCH(Reporte!$A:$A, ""(?i)(TE PAGÓ|PAGASTE)""), Reporte!$H:$H & """" = AH33 & """" ) ), 0 )"),56) -> 56 | X33: =IFERROR(__xludf.DUMMYFUNCTION("IFERROR( SUM( FILTER( Efectivo!$C:$C, Efectivo!$D:$D & """" = AH33 & """" ) ), 0 )"),0) -> 0 | Y33: c | AA33: y | AD33: =IF(AND(L33>0, M33>=8, NOT(OR(Y33="C", Y33="c"))), "CORTE", "") | AE33: =IF( OR( AND(#REF!>0, OR(Y33="C", Y33="c"), U33<0), AND(#REF!>0, Y33="") ), "CORTE", "" ) -> #REF! | AF33: =IF(AND(LEN(Y33)>0,LEN(AA33)=0),V33,0) -> 0 | AG33: =IF(AND(LEN(Y33)>0,TRIM(AA33)="Y"),V33,0) -> 56 | AH33: =TRIM(UPPER(C33)) -> B | AI33: =TRIM(UPPER(C33)) & "-" & TRIM(UPPER(D33)) -> B-29
A34: 33 | B34: ODILON CERNA ROMERO | C34: C | D34: 1 | H34: 1 | I34: 6 | J34: 21 | K34: 15 | L34: 15 | N34: 0 | O34: 25 | P34: 3 | V34: =SUM(L34:Q34) -> 43 | W34: =IFERROR(__xludf.DUMMYFUNCTION("IFERROR( SUM( FILTER( Reporte!$E:$E, REGEXMATCH(Reporte!$A:$A, ""(?i)(TE PAGÓ|PAGASTE)""), Reporte!$H:$H & """" = AH34 & """" ) ), 0 )"),0) -> 0 | X34: =IFERROR(__xludf.DUMMYFUNCTION("IFERROR( SUM( FILTER( Efectivo!$C:$C, Efectivo!$D:$D & """" = AH34 & """" ) ), 0 )"),0) -> 0 | AD34: =IF(AND(L34>0, M34>=8, NOT(OR(Y34="C", Y34="c"))), "CORTE", "") | AE34: =IF( OR( AND(#REF!>0, OR(Y34="C", Y34="c"), U34<0), AND(#REF!>0, Y34="") ), "CORTE", "" ) -> #REF! | AF34: =IF(AND(LEN(Y34)>0,LEN(AA34)=0),V34,0) -> 0 | AG34: =IF(AND(LEN(Y34)>0,TRIM(AA34)="Y"),V34,0) -> 0 | AH34: =TRIM(UPPER(C34)) -> C | AI34: =TRIM(UPPER(C34)) & "-" & TRIM(UPPER(D34)) -> C-1
A35: 34 | B35: OLGA FLORENTINA HUERTA AGAMA | C35: C | D35: 2 | H35: 1 | I35: 0 | J35: 6 | K35: 6 | L35: 6 | N35: 0 | O35: 25 | P35: 3 | V35: =SUM(L35:Q35) -> 34 | W35: =IFERROR(__xludf.DUMMYFUNCTION("IFERROR( SUM( FILTER( Reporte!$E:$E, REGEXMATCH(Reporte!$A:$A, ""(?i)(TE PAGÓ|PAGASTE)""), Reporte!$H:$H & """" = AH35 & """" ) ), 0 )"),0) -> 0 | X35: =IFERROR(__xludf.DUMMYFUNCTION("IFERROR( SUM( FILTER( Efectivo!$C:$C, Efectivo!$D:$D & """" = AH35 & """" ) ), 0 )"),34) -> 34 | Y35: c | AD35: =IF(AND(L35>0, M35>=8, NOT(OR(Y35="C", Y35="c"))), "CORTE", "") | AE35: =IF( OR( AND(#REF!>0, OR(Y35="C", Y35="c"), U35<0), AND(#REF!>0, Y35="") ), "CORTE", "" ) -> #REF! | AF35: =IF(AND(LEN(Y35)>0,LEN(AA35)=0),V35,0) -> 34 | AG35: =IF(AND(LEN(Y35)>0,TRIM(AA35)="Y"),V35,0) -> 0 | AH35: =TRIM(UPPER(C35)) -> C | AI35: =TRIM(UPPER(C35)) & "-" & TRIM(UPPER(D35)) -> C-2
A36: 35 | B36: TIMOTEO ROMERO JULCA | C36: C | D36: 4 | H36: 1 | I36: 4 | J36: 21 | K36: 17 | L36: 17 | N36: 0 | O36: 25 | P36: 3 | V36: =SUM(L36:Q36) -> 45 | W36: =IFERROR(__xludf.DUMMYFUNCTION("IFERROR( SUM( FILTER( Reporte!$E:$E, REGEXMATCH(Reporte!$A:$A, ""(?i)(TE PAGÓ|PAGASTE)""), Reporte!$H:$H & """" = AH36 & """" ) ), 0 )"),0) -> 0 | X36: =IFERROR(__xludf.DUMMYFUNCTION("IFERROR( SUM( FILTER( Efectivo!$C:$C, Efectivo!$D:$D & """" = AH36 & """" ) ), 0 )"),45) -> 45 | Y36: c | AD36: =IF(AND(L36>0, M36>=8, NOT(OR(Y36="C", Y36="c"))), "CORTE", "") | AE36: =IF( OR( AND(#REF!>0, OR(Y36="C", Y36="c"), U36<0), AND(#REF!>0, Y36="") ), "CORTE", "" ) -> #REF! | AF36: =IF(AND(LEN(Y36)>0,LEN(AA36)=0),V36,0) -> 45 | AG36: =IF(AND(LEN(Y36)>0,TRIM(AA36)="Y"),V36,0) -> 0 | AH36: =TRIM(UPPER(C36)) -> C | AI36: =TRIM(UPPER(C36)) & "-" & TRIM(UPPER(D36)) -> C-4
A37: 36 | B37: AGAPITO PRINCIPE SALINAS | C37: C | D37: 5 | H37: 1 | I37: 8 | J37: 26 | K37: 18 | L37: 18 | N37: 0 | O37: 25 | P37: 3 | V37: =SUM(L37:Q37) -> 46 | W37: =IFERROR(__xludf.DUMMYFUNCTION("IFERROR( SUM( FILTER( Reporte!$E:$E, REGEXMATCH(Reporte!$A:$A, ""(?i)(TE PAGÓ|PAGASTE)""), Reporte!$H:$H & """" = AH37 & """" ) ), 0 )"),46) -> 46 | X37: =IFERROR(__xludf.DUMMYFUNCTION("IFERROR( SUM( FILTER( Efectivo!$C:$C, Efectivo!$D:$D & """" = AH37 & """" ) ), 0 )"),0) -> 0 | Y37: c | AA37: y | AD37: =IF(AND(L37>0, M37>=8, NOT(OR(Y37="C", Y37="c"))), "CORTE", "") | AE37: =IF( OR( AND(#REF!>0, OR(Y37="C", Y37="c"), U37<0), AND(#REF!>0, Y37="") ), "CORTE", "" ) -> #REF! | AF37: =IF(AND(LEN(Y37)>0,LEN(AA37)=0),V37,0) -> 0 | AG37: =IF(AND(LEN(Y37)>0,TRIM(AA37)="Y"),V37,0) -> 46 | AH37: =TRIM(UPPER(C37)) -> C | AI37: =TRIM(UPPER(C37)) & "-" & TRIM(UPPER(D37)) -> C-5
A38: 37 | B38: DIANA JARA TRUJILLO | C38: C | D38: 6 | H38: 1 | I38: 592 | J38: 598 | K38: 6 | L38: 6 | M38: 16 | N38: 0 | P38: 3 | V38: =SUM(L38:Q38) -> 25 | W38: =IFERROR(__xludf.DUMMYFUNCTION("IFERROR( SUM( FILTER( Reporte!$E:$E, REGEXMATCH(Reporte!$A:$A, ""(?i)(TE PAGÓ|PAGASTE)""), Reporte!$H:$H & """" = AH38 & """" ) ), 0 )"),25) -> 25 | X38: =IFERROR(__xludf.DUMMYFUNCTION("IFERROR( SUM( FILTER( Efectivo!$C:$C, Efectivo!$D:$D & """" = AH38 & """" ) ), 0 )"),0) -> 0 | Y38: c | AA38: y | AD38: =IF(AND(L38>0, M38>=8, NOT(OR(Y38="C", Y38="c"))), "CORTE", "") | AE38: =IF( OR( AND(#REF!>0, OR(Y38="C", Y38="c"), U38<0), AND(#REF!>0, Y38="") ), "CORTE", "" ) -> #REF! | AF38: =IF(AND(LEN(Y38)>0,LEN(AA38)=0),V38,0) -> 0 | AG38: =IF(AND(LEN(Y38)>0,TRIM(AA38)="Y"),V38,0) -> 25 | AH38: =TRIM(UPPER(C38)) -> C | AI38: =TRIM(UPPER(C38)) & "-" & TRIM(UPPER(D38)) -> C-6
A39: 38 | B39: VICTOR LOPEZ TRUJILLO | C39: C | D39: 7 | H39: 1 | I39: 15 | J39: 53 | K39: 38 | L39: 38 | N39: 0 | O39: 25 | P39: 3 | V39: =SUM(L39:Q39) -> 66 | W39: =IFERROR(__xludf.DUMMYFUNCTION("IFERROR( SUM( FILTER( Reporte!$E:$E, REGEXMATCH(Reporte!$A:$A, ""(?i)(TE PAGÓ|PAGASTE)""), Reporte!$H:$H & """" = AH39 & """" ) ), 0 )"),66) -> 66 | X39: =IFERROR(__xludf.DUMMYFUNCTION("IFERROR( SUM( FILTER( Efectivo!$C:$C, Efectivo!$D:$D & """" = AH39 & """" ) ), 0 )"),0) -> 0 | Y39: c | AA39: y | AD39: =IF(AND(L39>0, M39>=8, NOT(OR(Y39="C", Y39="c"))), "CORTE", "") | AE39: =IF( OR( AND(#REF!>0, OR(Y39="C", Y39="c"), U39<0), AND(#REF!>0, Y39="") ), "CORTE", "" ) -> #REF! | AF39: =IF(AND(LEN(Y39)>0,LEN(AA39)=0),V39,0) -> 0 | AG39: =IF(AND(LEN(Y39)>0,TRIM(AA39)="Y"),V39,0) -> 66 | AH39: =TRIM(UPPER(C39)) -> C | AI39: =TRIM(UPPER(C39)) & "-" & TRIM(UPPER(D39)) -> C-7
A40: 39 | B40: JULISSA BARRETO QUITO | C40: C | D40: 8 | H40: 1 | I40: 279 | J40: 287 | K40: 8 | L40: 8 | M40: 11 | N40: 0 | P40: 3 | V40: =SUM(L40:Q40) -> 22 | W40: =IFERROR(__xludf.DUMMYFUNCTION("IFERROR( SUM( FILTER( Reporte!$E:$E, REGEXMATCH(Reporte!$A:$A, ""(?i)(TE PAGÓ|PAGASTE)""), Reporte!$H:$H & """" = AH40 & """" ) ), 0 )"),22) -> 22 | X40: =IFERROR(__xludf.DUMMYFUNCTION("IFERROR( SUM( FILTER( Efectivo!$C:$C, Efectivo!$D:$D & """" = AH40 & """" ) ), 0 )"),0) -> 0 | Y40: c | AA40: y | AD40: =IF(AND(L40>0, M40>=8, NOT(OR(Y40="C", Y40="c"))), "CORTE", "") | AE40: =IF( OR( AND(#REF!>0, OR(Y40="C", Y40="c"), U40<0), AND(#REF!>0, Y40="") ), "CORTE", "" ) -> #REF! | AF40: =IF(AND(LEN(Y40)>0,LEN(AA40)=0),V40,0) -> 0 | AG40: =IF(AND(LEN(Y40)>0,TRIM(AA40)="Y"),V40,0) -> 22 | AH40: =TRIM(UPPER(C40)) -> C | AI40: =TRIM(UPPER(C40)) & "-" & TRIM(UPPER(D40)) -> C-8
...

Sheet PLANILLA
A1: ITEM | B1: NOMBRES | C1: MZ | D1: LT | E1: MARCACIÓN | F1: m3 | G1: MARCACIÓN | H1: M3 | I1: MARCACIÓN | J1: M3 | K1: MARCACIÓN | L1: M3 | M1: MARCACIÓN | N1: M3 | O1: MARCACIÓN | P1: M3 | Q1: MARCACIÓN | R1: M3 | S1: MARCACIÓN | T1: M3 | U1: MARCACION | V1: m3 | W1: MARCACION | X1: m3 | Y1: MARCACION | Z1: m3 | AA1: MARCACIÓN | AB1: M3 | AC1: Total mes actual | AD1: MES ANTERIOR | AE1: Corte y reconexión | AF1: Convenio | AG1: Manteniminiento | AH1: Multa | AI1: Total a pagar | AJ1: Estado | AK1: Fecha de pago | AL1: Medio de pago | AM1: Comentario
A2: 1 | B2: MARCELINA OBREGON DE AVILA | C2: A | D2: 1 | E2: 2445 | F2: 6 | G2: 2451 | H2: 7 | I2: 2458 | J2: 6 | K2: 2464 | L2: 5 | M2: 2469 | N2: 7 | O2: 2476 | P2: 5 | Q2: 2481 | R2: 5 | S2: 2486 | T2: 5 | U2: 2491 | V2: 5 | W2: 2496 | X2: 5 | Y2: 2502 | Z2: 6 | AA2: 2506 | AB2: 4 | AC2: 5 | AD2: 0 | AE2: 0 | AG2: 3 | AH2: 0 | AI2: 8
A3: 2 | B3: ROSA AURORA ROCA VIDAL | C3: A | D3: 2 | E3: 1975 | F3: 37 | G3: 2012 | H3: 23 | I3: 2035 | J3: 32 | K3: 2067 | L3: 27 | M3: 2094 | N3: 26 | O3: 2120 | P3: 22 | Q3: 2142 | R3: 22 | S3: 2168 | T3: 26 | U3: 2193 | V3: 25 | W3: 2225 | X3: 32 | Y3: 2248 | Z3: 23 | AA3: 2288 | AB3: 40 | AC3: 40 | AD3: 0 | AE3: 0 | AG3: 3 | AH3: 0 | AI3: 43
A4: 3 | B4: LINDA PAJUELO COCHACHÍN | C4: A | D4: 3 | K4: 0 | L4: 0 | M4: 0 | N4: 1 | O4: 1 | P4: 14 | Q4: 15 | R4: 14 | S4: 22 | T4: 7 | U4: 22 | V4: 0 | W4: 22 | X4: 0 | Y4: 22 | Z4: 0 | AA4: 22 | AB4: 0 | AC4: 5 | AD4: 0 | AE4: 0 | AG4: 3 | AH4: 0 | AI4: 8
A5: 4 | B5: YOLANDA ESPINOZA JAIMES | C5: A | D5: 4 | E5: 1759 | F5: 0 | G5: 1759 | H5: 0 | I5: 1759 | J5: 3 | K5: 1762 | L5: 0 | M5: 1762 | N5: 0 | O5: 1762 | P5: 0 | Q5: 1762 | R5: 0 | S5: 1762 | T5: 0 | U5: 1732 | V5: 0 | W5: 1762 | X5: 30 | Y5: 1763 | Z5: 1 | AA5: 1763 | AB5: 0 | AC5: 5 | AD5: 41 | AE5: 40 | AG5: 3 | AH5: 20 | AI5: 109
A6: 5 | B6: JULIA AGAMA CUZCO | C6: A | D6: 5 | E6: 2933 | F6: 35 | G6: 2968 | H6: 34 | I6: 3002 | J6: 23 | K6: 3025 | L6: 23 | M6: 3048 | N6: 16 | O6: 3064 | P6: 14 | Q6: 3078 | R6: 14 | S6: 3092 | T6: 14 | U6: 3108 | V6: 16 | W6: 3120 | X6: 12 | Y6: 3141 | Z6: 21 | AA6: 3162 | AB6: 21 | AC6: 21 | AD6: 0 | AE6: 0 | AG6: 3 | AH6: 0 | AI6: 24
A7: 6 | B7: ESTEBAN REYES SANCHEZ | C7: A | D7: 6 | E7: 1253 | F7: 45 | G7: 1298 | H7: 35 | I7: 1333 | J7: 25 | K7: 1358 | L7: 32 | M7: 1390 | N7: 22 | O7: 1412 | P7: 28 | Q7: 1440 | R7: 28 | S7: 1467 | T7: 27 | U7: 1491 | V7: 24 | W7: 1517 | X7: 26 | Y7: 1544 | Z7: 27 | AA7: 1571 | AB7: 27 | AC7: 27 | AD7: 0 | AE7: 0 | AG7: 3 | AH7: 0 | AI7: 30
A8: 7 | B8: JUAN CARLOS MELGAREJO BEDON | C8: A | D8: 7 | E8: 1358 | F8: 24 | G8: 1382 | H8: 25 | I8: 1407 | J8: 22 | K8: 1429 | L8: 23 | M8: 1452 | N8: 19 | O8: 1471 | P8: 22 | Q8: 1493 | R8: 22 | S8: 1512 | T8: 19 | U8: 1529 | V8: 17 | W8: 1546 | X8: 17 | Y8: 1562 | Z8: 16 | AA8: 1579 | AB8: 17 | AC8: 17 | AD8: 19 | AE8: 0 | AG8: 3 | AH8: 0 | AI8: 39
A9: 8 | B9: VICTOR MELGAREJO CORCINO | C9: A | D9: 8 | E9: 5882 | F9: 35 | G9: 5917 | H9: 33 | I9: 5950 | J9: 25 | K9: 5975 | L9: 36 | M9: 6011 | N9: 21 | O9: 6032 | P9: 13 | Q9: 6045 | R9: 13 | S9: 6055 | T9: 10 | U9: 6067 | V9: 12 | W9: 6078 | X9: 11 | Y9: 6088 | Z9: 10 | AA9: 6103 | AB9: 15 | AC9: 15 | AD9: 0 | AE9: 0 | AG9: 3 | AH9: 0 | AI9: 18
A10: 9 | B10: JHONI MELGAREJO BEDON | C10: A | D10: 8-A | P10: 18 | Q10: 18 | R10: 18 | S10: 26 | T10: 8 | U10: 32 | V10: 6 | W10: 46 | X10: 14 | Y10: 53 | Z10: 7 | AA10: 61 | AB10: 8 | AC10: 8 | AD10: 0 | AE10: 0 | AG10: 3 | AH10: 20 | AI10: 31
A11: 10 | B11: ALEJANDRO MELGAREJO ESPINOZA | C11: A | D11: 9 | E11: 1381 | F11: 32 | G11: 1413 | H11: 30 | I11: 1443 | J11: 40 | K11: 1483 | L11: 33 | M11: 1516 | N11: 33 | O11: 1549 | P11: 27 | Q11: 1576 | R11: 27 | S11: 1601 | T11: 25 | U11: 1624 | V11: 23 | W11: 1646 | X11: 22 | Y11: 1673 | Z11: 27 | AA11: 1703 | AB11: 30 | AC11: 30 | AD11: 0 | AE11: 0 | AG11: 3 | AH11: 0 | AI11: 33
A12: 11 | B12: ISABEL PUNTILLO VEGA | C12: A | D12: 10 | E12: 31 | F12: 10 | G12: 41 | H12: 29 | I12: 70 | J12: 18 | K12: 88 | L12: 29 | M12: 117 | N12: 20 | O12: 137 | P12: 163 | Q12: 300 | R12: 163 | S12: 371 | T12: 71 | U12: 379 | V12: 8 | W12: 384 | X12: 5 | Y12: 389 | Z12: 5 | AA12: 395 | AB12: 6 | AC12: 6 | AD12: 0 | AE12: 0 | AG12: 3 | AH12: 20 | AI12: 29
A13: 12 | B13: FELIX POZO CASTRO | C13: A | D13: 11 | E13: 341 | F13: 0 | G13: 341 | H13: 1 | I13: 342 | J13: 1 | K13: 343 | L13: 0 | M13: 343 | N13: 1 | O13: 344 | P13: 0 | Q13: 344 | R13: 0 | S13: 345 | T13: 1 | U13: 346 | V13: 1 | W13: 346 | X13: 0 | Y13: 346 | Z13: 0 | AA13: 346 | AB13: 0 | AC13: 5 | AD13: 0 | AE13: 0 | AG13: 3 | AH13: 20 | AI13: 28
A14: 13 | B14: BACILIO UTRILLA FRANCISCO | C14: B | D14: 1 | E14: 2078 | F14: 15 | G14: 2093 | H14: 0 | I14: 2093 | J14: 7 | K14: 2100 | L14: 10 | M14: 2110 | N14: 8 | O14: 2118 | P14: 5 | Q14: 2123 | R14: 5 | S14: 2131 | T14: 8 | U14: 2137 | V14: 6 | W14: 2141 | X14: 4 | Y14: 2147 | Z14: 6 | AA14: 2153 | AB14: 6 | AC14: 6 | AD14: 9 | AE14: 0 | AG14: 3 | AH14: 0 | AI14: 18
A15: 14 | B15: ESTEBAN REYNALDO ROSALES | C15: B | D15: 2 | E15: 2104 | F15: 6 | G15: 2110 | H15: 3 | I15: 2113 | J15: 2 | K15: 2115 | L15: 11 | M15: 2126 | N15: 9 | O15: 2135 | P15: 6 | Q15: 2141 | R15: 6 | S15: 2146 | T15: 5 | U15: 2152 | V15: 6 | W15: 2157 | X15: 5 | Y15: 2164 | Z15: 7 | AA15: 2171 | AB15: 7 | AC15: 7 | AD15: 0 | AE15: 0 | AG15: 3 | AH15: 20 | AI15: 30
A16: 15 | B16: EDUARDO REYNALDO ROSALES | C16: B | D16: 3 | E16: 602 | F16: 9 | G16: 611 | H16: 10 | I16: 621 | J16: 10 | K16: 631 | L16: 9 | M16: 640 | N16: 8 | O16: 648 | P16: 10 | Q16: 658 | R16: 10 | S16: 669 | T16: 11 | U16: 676 | V16: 7 | W16: 682 | X16: 6 | Y16: 689 | Z16: 7 | AA16: 695 | AB16: 6 | AC16: 6 | AD16: 0 | AE16: 0 | AG16: 3 | AH16: 0 | AI16: 9
A17: 16 | B17: MELINA J. JUAREZ TOLEDO DE MORENO | C17: B | D17: 4 | E17: 189 | F17: 10 | G17: 199 | H17: 12 | I17: 211 | J17: 15 | K17: 226 | L17: 13 | M17: 239 | N17: 13 | O17: 252 | P17: 21 | Q17: 273 | R17: 21 | S17: 291 | T17: 18 | U17: 311 | V17: 20 | W17: 331 | X17: 20 | Y17: 348 | Z17: 17 | AA17: 369 | AB17: 21 | AC17: 21 | AD17: 0 | AE17: 0 | AG17: 3 | AH17: 0 | AI17: 24
A18: 17 | B18: POMPEYO CELESTINO LLIUYA | C18: B | D18: 5 | E18: 4425 | F18: 58 | G18: 4483 | H18: 45 | I18: 4528 | J18: 39 | K18: 4567 | L18: 33 | M18: 4600 | N18: 39 | O18: 4639 | P18: 34 | Q18: 4673 | R18: 34 | S18: 4706 | T18: 33 | U18: 4742 | V18: 36 | W18: 4775 | X18: 33 | Y18: 4810 | Z18: 35 | AA18: 4848 | AB18: 38 | AC18: 38 | AD18: 0 | AE18: 0 | AG18: 3 | AH18: 20 | AI18: 61
A19: 18 | B19: ROSA VICTORIA MILLA MORALES | C19: B | D19: 6 | E19: 3385 | F19: 34 | G19: 3419 | H19: 35 | I19: 3454 | J19: 23 | K19: 3477 | L19: 23 | M19: 3500 | N19: 20 | O19: 3520 | P19: 26 | Q19: 3546 | R19: 26 | S19: 3570 | T19: 24 | U19: 3592 | V19: 22 | W19: 3612 | X19: 20 | Y19: 3634 | Z19: 22 | AA19: 3656 | AB19: 22 | AC19: 22 | AD19: 25 | AE19: 0 | AG19: 3 | AH19: 0 | AI19: 50
A20: 19 | B20: LIRIA PARIAMACHI DE PAZ | C20: B | D20: 7 | E20: 2289 | F20: 16 | G20: 2305 | H20: 17 | I20: 2322 | J20: 26 | K20: 2348 | L20: 16 | M20: 2364 | N20: 17 | O20: 2381 | P20: 16 | Q20: 2397 | R20: 16 | S20: 2414 | T20: 17 | U20: 2428 | V20: 14 | W20: 2443 | X20: 15 | Y20: 2455 | Z20: 12 | AA20: 2469 | AB20: 14 | AC20: 14 | AD20: 0 | AE20: 0 | AG20: 3 | AH20: 0 | AI20: 17
A21: 20 | B21: ROSALINA OLIMPIA CIRIACO SOTELO | C21: B | D21: 8 | E21: 6347 | F21: 14 | G21: 6361 | H21: 17 | I21: 6378 | J21: 18 | K21: 6396 | L21: 15 | M21: 6411 | N21: 14 | O21: 6425 | P21: 14 | Q21: 6439 | R21: 14 | S21: 6456 | T21: 17 | U21: 6470 | V21: 14 | W21: 6484 | X21: 14 | Y21: 6497 | Z21: 13 | AA21: 6510 | AB21: 13 | AC21: 13 | AD21: 16 | AE21: 0 | AG21: 3 | AH21: 0 | AI21: 32
A22: 21 | B22: ALEJANDRO RAPRAY VELASQUEZ | C22: B | D22: 9 | E22: 5905 | F22: 23 | G22: 5928 | H22: 25 | I22: 5953 | J22: 21 | K22: 5974 | L22: 16 | M22: 5990 | N22: 14 | O22: 6004 | P22: 14 | Q22: 6018 | R22: 14 | S22: 6045 | T22: 27 | U22: 6052 | V22: 7 | W22: 6058 | X22: 6 | Y22: 6062 | Z22: 4 | AA22: 6066 | AB22: 4 | AC22: 5 | AD22: 0 | AE22: 0 | AG22: 3 | AH22: 0 | AI22: 8
... A25: 24 | B25: TEOFILO BRUNO RAMOS DE LA CRUZ | C25: B | D25: 12 | E25: 2213 | F25: 8 | G25: 2221 | H25: 8 | I25: 2229 | J25: 10 | K25: 2239 | L25: 7 | M25: 2246 | N25: 9 | O25: 2255 | P25: 6 | Q25: 2261 | R25: 6 | S25: 2267 | T25: 6 | U25: 2273 | V25: 6 | W25: 2278 | X25: 5 | Y25: 2285 | Z25: 7 | AA25: 2292 | AB25: 7 | AC25: 7 | AD25: 10 | AE25: 0 | AG25: 3 | AH25: 0 | AI25: 20
A26: 25 | B26: ROSMERI SANCHEZ ESPADA | C26: B | D26: 12-A | E26: 198 | F26: 6 | G26: 204 | H26: 7 | I26: 211 | J26: 6 | K26: 217 | L26: 6 | M26: 223 | N26: 6 | O26: 229 | P26: 6 | Q26: 235 | R26: 6 | S26: 239 | T26: 4 | U26: 244 | V26: 5 | W26: 250 | X26: 6 | Y26: 256 | Z26: 6 | AA26: 262 | AB26: 6 | AC26: 6 | AD26: 0 | AE26: 0 | AG26: 3 | AH26: 0 | AI26: 9
A27: 26 | B27: SALOME AGUSTINA DIAZ VARGAS | C27: B | D27: 13 | E27: 90 | F27: 13 | G27: 103 | H27: 12 | I27: 115 | J27: 16 | K27: 131 | L27: 6 | M27: 137 | N27: 5 | O27: 142 | P27: 5 | Q27: 147 | R27: 5 | S27: 152 | T27: 5 | U27: 157 | V27: 5 | W27: 165 | X27: 8 | Y27: 173 | Z27: 8 | AA27: 180 | AB27: 7 | AC27: 7 | AD27: 0 | AE27: 0 | AG27: 3 | AH27: 0 | AI27: 10
A28: 27 | B28: MELISSA ISABEL PILLACA GARCIA | C28: B | D28: 15 | E28: 886 | F28: 12 | G28: 898 | H28: 18 | I28: 916 | J28: 13 | K28: 929 | L28: 18 | M28: 947 | N28: 18 | O28: 965 | P28: 20 | Q28: 985 | R28: 20 | S28: 1006 | T28: 21 | U28: 1028 | V28: 22 | W28: 1052 | X28: 24 | Y28: 1061 | Z28: 9 | AA28: 1105 | AB28: 44 | AC28: 44 | AD28: 0 | AE28: 0 | AG28: 3 | AH28: 0 | AI28: 47
A29: 28 | B29: CLETO TENORIO MORI | C29: B | D29: 16 | E29: 322 | F29: 13 | G29: 335 | H29: 21 | I29: 356 | J29: 16 | K29: 372 | L29: 17 | M29: 389 | N29: 15 | O29: 404 | P29: 10 | Q29: 414 | R29: 10 | S29: 422 | T29: 8 | U29: 428 | V29: 6 | W29: 435 | X29: 7 | Y29: 442 | Z29: 7 | AA29: 452 | AB29: 10 | AC29: 10 | AD29: 0 | AE29: 0 | AG29: 3 | AH29: 20 | AI29: 33
A30: 29 | B30: ELEUTERIA DOMITILA PARIAMACHI DE PAZ | C30: B | D30: 17 | E30: 16 | F30: 0 | G30: 16 | H30: 0 | I30: 16 | J30: 2 | K30: 18 | L30: 3 | M30: 21 | N30: 1 | O30: 22 | P30: 0 | Q30: 22 | R30: 0 | S30: 23 | T30: 1 | U30: 23 | V30: 0 | W30: 23 | X30: 0 | Y30: 24 | Z30: 1 | AA30: 24 | AB30: 0 | AC30: 5 | AD30: 0 | AE30: 0 | AG30: 3 | AH30: 0 | AI30: 8
A31: 30 | B31: LUZ DINA MIRAVAL HUERTA | C31: B | D31: 18 | E31: 632 | F31: 18 | G31: 650 | H31: 22 | I31: 672 | J31: 22 | K31: 694 | L31: 17 | M31: 711 | N31: 15 | O31: 726 | P31: 16 | Q31: 742 | R31: 16 | S31: 753 | T31: 11 | U31: 765 | V31: 12 | W31: 777 | X31: 12 | Y31: 790 | Z31: 13 | AA31: 803 | AB31: 13 | AC31: 13 | AD31: 0 | AE31: 0 | AG31: 3 | AH31: 0 | AI31: 16
A32: 31 | B32: CAMILA HIDALGO | C32: B | D32: 21 | E32: 0 | F32: 0 | G32: 0 | H32: 5 | I32: 5 | J32: 3 | K32: 3 | L32: 4 | M32: 7 | N32: 3 | O32: 10 | P32: 9 | Q32: 19 | R32: 9 | S32: 28 | T32: 9 | U32: 36 | V32: 8 | W32: 47 | X32: 11 | Y32: 60 | Z32: 13 | AA32: 72 | AB32: 12 | AC32: 12 | AD32: 0 | AE32: 0 | AG32: 3 | AH32: 0 | AI32: 15
A33: 32 | B33: JANET FERNANDEZ MINAYA | C33: B | D33: 29 | F33: 0 | H33: 0 | I33: 0 | J33: 19 | K33: 19 | L33: 9 | M33: 28 | N33: 4 | O33: 32 | P33: 5 | Q33: 37 | R33: 5 | S33: 45 | T33: 8 | U33: 52 | V33: 7 | W33: 66 | X33: 14 | Y33: 78 | Z33: 12 | AA33: 88 | AB33: 10 | AC33: 10 | AD33: 0 | AE33: 0 | AF33: 100 | AG33: 3 | AH33: 0 | AI33: 113
A34: 33 | B34: ODILON CERNA ROMERO | C34: C | D34: 1 | E34: 1726 | F34: 16 | G34: 1742 | H34: 15 | I34: 1757 | J34: 13 | K34: 1770 | L34: 14 | M34: 1784 | N34: 13 | O34: 1797 | P34: 12 | Q34: 1809 | R34: 12 | S34: 1819 | T34: 10 | U34: 1831 | V34: 12 | W34: 1845 | X34: 14 | Y34: 1859 | Z34: 14 | AA34: 1873 | AB34: 14 | AC34: 14 | AD34: 0 | AE34: 0 | AG34: 3 | AH34: 20 | AI34: 37
A35: 34 | B35: OLGA FLORENTINA HUERTA AGAMA | C35: C | D35: 2 | E35: 796 | F35: 5 | G35: 801 | H35: 17 | I35: 818 | J35: 2 | K35: 820 | L35: 2 | M35: 822 | N35: 1 | O35: 823 | P35: 2 | Q35: 825 | R35: 2 | S35: 826 | T35: 1 | U35: 827 | V35: 1 | W35: 829 | X35: 2 | Y35: 830 | Z35: 1 | AA35: 833 | AB35: 3 | AC35: 5 | AD35: 0 | AE35: 0 | AG35: 3 | AH35: 0 | AI35: 8
A36: 35 | B36: TIMOTEO ROMERO JULCA | C36: C | D36: 4 | E36: 2918 | F36: 20 | G36: 2938 | H36: 32 | I36: 2970 | J36: 30 | K36: 3000 | L36: 29 | M36: 3029 | N36: 22 | O36: 3051 | P36: 15 | Q36: 3066 | R36: 15 | S36: 3085 | T36: 19 | U36: 3106 | V36: 21 | W36: 3122 | X36: 16 | Y36: 3150 | Z36: 28 | AA36: 3175 | AB36: 25 | AC36: 25 | AD36: 0 | AE36: 0 | AG36: 3 | AH36: 0 | AI36: 28
A37: 36 | B37: AGAPITO PRINICIPE SALINAS | C37: C | D37: 5 | E37: 3725 | F37: 22 | G37: 3747 | H37: 21 | I37: 3768 | J37: 19 | K37: 3787 | L37: 19 | M37: 3806 | N37: 18 | O37: 3824 | P37: 11 | Q37: 3835 | R37: 11 | S37: 3845 | T37: 10 | U37: 3859 | V37: 14 | W37: 3869 | X37: 10 | Y37: 3884 | Z37: 15 | AA37: 3899 | AB37: 15 | AC37: 15 | AD37: 0 | AE37: 0 | AG37: 3 | AH37: 0 | AI37: 18
A38: 37 | B38: DIANA JARA TRUJILLO | C38: C | D38: 6 | E38: 150 | F38: 22 | G38: 172 | H38: 23 | I38: 195 | J38: 19 | K38: 214 | L38: 15 | M38: 229 | N38: 16 | O38: 245 | P38: 21 | Q38: 266 | R38: 21 | S38: 283 | T38: 17 | U38: 299 | V38: 16 | W38: 324 | X38: 25 | Y38: 350 | Z38: 26 | AA38: 370 | AB38: 20 | AC38: 20 | AD38: 0 | AE38: 0 | AG38: 3 | AH38: 40 | AI38: 63
A39: 38 | B39: VICTOR LOPEZ TRUJILLO | C39: C | D39: 7 | E39: 2096 | F39: 43 | G39: 2139 | H39: 27 | I39: 2166 | J39: 20 | K39: 2186 | L39: 15 | M39: 2201 | N39: 14 | O39: 2215 | P39: 11 | Q39: 2226 | R39: 11 | S39: 2236 | T39: 10 | U39: 2246 | V39: 10 | W39: 2260 | X39: 14 | Y39: 2276 | Z39: 16 | AA39: 2288 | AB39: 12 | AC39: 12 | AD39: 0 | AE39: 0 | AG39: 3 | AH39: 40 | AI39: 55
A40: 39 | B40: JULISSA BARRETO QUITO | C40: C | D40: 8 | E40: 156 | F40: 0 | G40: 156 | H40: 1 | I40: 157 | J40: 0 | K40: 157 | L40: 0 | M40: 157 | N40: 1 | O40: 158 | P40: 4 | Q40: 162 | R40: 4 | S40: 167 | T40: 5 | U40: 170 | V40: 3 | W40: 175 | X40: 5 | Y40: 179 | Z40: 4 | AA40: 184 | AB40: 5 | AC40: 5 | AD40: 8 | AE40: 0 | AG40: 3 | AH40: 20 | AI40: 36
A41: 40 | B41: JAZMIN QUITO SANCHEZ | C41: C | D41: 8-B | E41: 509 | F41: 16 | G41: 525 | H41: 22 | I41: 547 | J41: 16 | K41: 563 | L41: 15 | M41: 578 | N41: 14 | O41: 592 | P41: 14 | Q41: 606 | R41: 14 | S41: 618 | T41: 12 | U41: 631 | V41: 13 | W41: 645 | X41: 14 | Y41: 668 | Z41: 23 | AA41: 689 | AB41: 21 | AC41: 21 | AD41: 0 | AE41: 0 | AG41: 3 | AH41: 0 | AI41: 24
A42: 41 | B42: JUAN UCULMANA SANCHEZ | C42: C | D42: 9 | E42: 2002 | F42: 5 | G42: 2007 | H42: 3 | I42: 2010 | J42: 29 | K42: 2039 | L42: 6 | M42: 2045 | N42: 4 | O42: 2049 | P42: 1 | Q42: 2050 | R42: 1 | S42: 2050 | T42: 0 | U42: 2050 | V42: 0 | W42: 2060 | X42: 10 | Y42: 2062 | Z42: 2 | AA42: 2064 | AB42: 2 | AC42: 5 | AD42: 0 | AE42: 0 | AG42: 3 | AH42: 0 | AI42: 8
...
