Workbook

Sheet Cobranza
A1: nª | B1: NOMBRES | C1: MZ | D1: LT | E1: TIPO CONVENIO | F1: MAYOR 65 | G1: NO COBRO | H1: Costo x m3 | I1: Marcación anterior | J1: Marcacion altual | K1: M3 | L1: Total mes actual | M1: MES ANTERIOR | N1: Corte y reconexion | O1: Convenio | P1: Mantenimiento | Q1: Multa (faena + reunión) | R1: Devoluciones | S1: Ajuste | T1: Total | U1: Yape rep | V1: Monto Efectivo | W1: Estado | X1: Fecha | Y1: Medio | Z1: Comentario | AA1: Estado del servicio | AB1: corte por consumo | AC1: Corte por faena | AD1: Efectivo | AE1: Yape | AF1: Llave1 | AG1: LLAVE (Mz, Lt)
A2: 1 | B2: MARCELINA OBREGON DE AVILA | C2: A | D2: 1 | H2: 1 | I2: 11 | J2: 19 | K2: 8 | L2: 8 | M2: 0 | N2: 0 | O2: 75 | P2: 3 | Q2: 0 | T2: =SUM(L2:S2) -> 86 | U2: =IFERROR(__xludf.DUMMYFUNCTION("IFERROR( SUM( FILTER( Reporte!$E:$E, REGEXMATCH(Reporte!$A:$A, ""(?i)(TE PAGÓ|PAGASTE)""), Reporte!$H:$H & """" = AG2 & """" ) ), 0 )"),11) -> 11 | V2: =IFERROR(__xludf.DUMMYFUNCTION("IFERROR( SUM( FILTER( Efectivo!$C:$C, Efectivo!$D:$D & """" = AG2 & """" ) ), 0 )"),75) -> 75 | W2: c | Y2: y | Z2: Debe 0. 75 esta en el efectivo | AB2: =IF(AND(L2>0, M2>=8, NOT(OR(W2="C", W2="c"))), "CORTE", "") | AC2: =IF( OR( AND(Q2>0, OR(W2="C", W2="c"), S2<0), AND(Q2>0, W2="") ), "CORTE", "" ) | AD2: =IF(AND(LEN(W2)>0,LEN(Y2)=0),T2,0) -> 0 | AE2: =IF(AND(LEN(W2)>0,TRIM(Y2)="Y"),T2,0) -> 86 | AF2: =TRIM(UPPER(C2)) -> A | AG2: =TRIM(UPPER(C2)) & "-" & TRIM(UPPER(D2)) -> A-1
A3: 2 | B3: ROSA AURORA ROCA VIDAL | C3: A | D3: 2 | H3: 1 | I3: 2703 | J3: 2723 | K3: 20 | L3: 20 | M3: 0 | N3: 0 | O3: 0 | P3: 3 | Q3: 0 | T3: =SUM(L3:S3) -> 23 | U3: =IFERROR(__xludf.DUMMYFUNCTION("IFERROR( SUM( FILTER( Reporte!$E:$E, REGEXMATCH(Reporte!$A:$A, ""(?i)(TE PAGÓ|PAGASTE)""), Reporte!$H:$H & """" = AG3 & """" ) ), 0 )"),0) -> 0 | V3: =IFERROR(__xludf.DUMMYFUNCTION("IFERROR( SUM( FILTER( Efectivo!$C:$C, Efectivo!$D:$D & """" = AG3 & """" ) ), 0 )"),0) -> 0 | AB3: =IF(AND(L3>0, M3>=8, NOT(OR(W3="C", W3="c"))), "CORTE", "") | AC3: =IF( OR( AND(Q3>0, OR(W3="C", W3="c"), S3<0), AND(Q3>0, W3="") ), "CORTE", "" ) | AD3: =IF(AND(LEN(W3)>0,LEN(Y3)=0),T3,0) -> 0 | AE3: =IF(AND(LEN(W3)>0,TRIM(Y3)="Y"),T3,0) -> 0 | AF3: =TRIM(UPPER(C3)) -> A | AG3: =TRIM(UPPER(C3)) & "-" & TRIM(UPPER(D3)) -> A-2
A4: 3 | B4: LINDA PAJUELO COCHACHIN | C4: A | D4: 3 | H4: 1 | I4: 22 | J4: 22 | K4: 5 | L4: 5 | M4: 0 | N4: 0 | O4: 0 | P4: 3 | Q4: 0 | T4: =SUM(L4:S4) -> 8 | U4: =IFERROR(__xludf.DUMMYFUNCTION("IFERROR( SUM( FILTER( Reporte!$E:$E, REGEXMATCH(Reporte!$A:$A, ""(?i)(TE PAGÓ|PAGASTE)""), Reporte!$H:$H & """" = AG4 & """" ) ), 0 )"),8) -> 8 | V4: =IFERROR(__xludf.DUMMYFUNCTION("IFERROR( SUM( FILTER( Efectivo!$C:$C, Efectivo!$D:$D & """" = AG4 & """" ) ), 0 )"),0) -> 0 | W4: c | Y4: y | AB4: =IF(AND(L4>0, M4>=8, NOT(OR(W4="C", W4="c"))), "CORTE", "") | AC4: =IF( OR( AND(Q4>0, OR(W4="C", W4="c"), S4<0), AND(Q4>0, W4="") ), "CORTE", "" ) | AD4: =IF(AND(LEN(W4)>0,LEN(Y4)=0),T4,0) -> 0 | AE4: =IF(AND(LEN(W4)>0,TRIM(Y4)="Y"),T4,0) -> 8 | AF4: =TRIM(UPPER(C4)) -> A | AG4: =TRIM(UPPER(C4)) & "-" & TRIM(UPPER(D4)) -> A-3
A5: 4 | B5: YOLANDA ESPINOZA JAIMES | C5: A | D5: 4 | H5: 1 | I5: 2 | J5: 2 | K5: 5 | N5: 40 | O5: 0 | P5: 1 | Q5: 0 | T5: =SUM(L5:S5) -> 41 | U5: =IFERROR(__xludf.DUMMYFUNCTION("IFERROR( SUM( FILTER( Reporte!$E:$E, REGEXMATCH(Reporte!$A:$A, ""(?i)(TE PAGÓ|PAGASTE)""), Reporte!$H:$H & """" = AG5 & """" ) ), 0 )"),41) -> 41 | V5: =IFERROR(__xludf.DUMMYFUNCTION("IFERROR( SUM( FILTER( Efectivo!$C:$C, Efectivo!$D:$D & """" = AG5 & """" ) ), 0 )"),0) -> 0 | W5: c | Y5: y | Z5: Debe 15 mes anterior | AB5: =IF(AND(L5>0, M5>=8, NOT(OR(W5="C", W5="c"))), "CORTE", "") | AC5: =IF( OR( AND(Q5>0, OR(W5="C", W5="c"), S5<0), AND(Q5>0, W5="") ), "CORTE", "" ) | AD5: =IF(AND(LEN(W5)>0,LEN(Y5)=0),T5,0) -> 0 | AE5: =IF(AND(LEN(W5)>0,TRIM(Y5)="Y"),T5,0) -> 41 | AF5: =TRIM(UPPER(C5)) -> A | AG5: =TRIM(UPPER(C5)) & "-" & TRIM(UPPER(D5)) -> A-4
A6: 5 | B6: JULIA AGAMA CUZCO | C6: A | D6: 5 | H6: 1 | I6: 16 | J6: 32 | K6: 16 | L6: 16 | M6: 0 | N6: 0 | O6: 25 | P6: 3 | Q6: 0 | T6: =SUM(L6:S6) -> 44 | U6: =IFERROR(__xludf.DUMMYFUNCTION("IFERROR( SUM( FILTER( Reporte!$E:$E, REGEXMATCH(Reporte!$A:$A, ""(?i)(TE PAGÓ|PAGASTE)""), Reporte!$H:$H & """" = AG6 & """" ) ), 0 )"),0) -> 0 | V6: =IFERROR(__xludf.DUMMYFUNCTION("IFERROR( SUM( FILTER( Efectivo!$C:$C, Efectivo!$D:$D & """" = AG6 & """" ) ), 0 )"),44) -> 44 | W6: c | AB6: =IF(AND(L6>0, M6>=8, NOT(OR(W6="C", W6="c"))), "CORTE", "") | AC6: =IF( OR( AND(Q6>0, OR(W6="C", W6="c"), S6<0), AND(Q6>0, W6="") ), "CORTE", "" ) | AD6: =IF(AND(LEN(W6)>0,LEN(Y6)=0),T6,0) -> 44 | AE6: =IF(AND(LEN(W6)>0,TRIM(Y6)="Y"),T6,0) -> 0 | AF6: =TRIM(UPPER(C6)) -> A | AG6: =TRIM(UPPER(C6)) & "-" & TRIM(UPPER(D6)) -> A-5
A7: 6 | B7: ESTEBAN REYES SANCHEZ | C7: A | D7: 6 | H7: 1 | I7: 26 | J7: 52 | K7: 26 | L7: 26 | M7: 0 | N7: 0 | O7: 25 | P7: 3 | Q7: 0 | T7: =SUM(L7:S7) -> 54 | U7: =IFERROR(__xludf.DUMMYFUNCTION("IFERROR( SUM( FILTER( Reporte!$E:$E, REGEXMATCH(Reporte!$A:$A, ""(?i)(TE PAGÓ|PAGASTE)""), Reporte!$H:$H & """" = AG7 & """" ) ), 0 )"),54) -> 54 | V7: =IFERROR(__xludf.DUMMYFUNCTION("IFERROR( SUM( FILTER( Efectivo!$C:$C, Efectivo!$D:$D & """" = AG7 & """" ) ), 0 )"),0) -> 0 | W7: c | Y7: y | AB7: =IF(AND(L7>0, M7>=8, NOT(OR(W7="C", W7="c"))), "CORTE", "") | AC7: =IF( OR( AND(Q7>0, OR(W7="C", W7="c"), S7<0), AND(Q7>0, W7="") ), "CORTE", "" ) | AD7: =IF(AND(LEN(W7)>0,LEN(Y7)=0),T7,0) -> 0 | AE7: =IF(AND(LEN(W7)>0,TRIM(Y7)="Y"),T7,0) -> 54 | AF7: =TRIM(UPPER(C7)) -> A | AG7: =TRIM(UPPER(C7)) & "-" & TRIM(UPPER(D7)) -> A-6
A8: 7 | B8: JUAN CARLOS MELGAREJO BEDON | C8: A | D8: 7 | H8: 1 | I8: 1766 | J8: 1777 | K8: 11 | L8: 11 | M8: 0 | N8: 0 | O8: 0 | P8: 3 | Q8: 0 | T8: =SUM(L8:S8) -> 14 | U8: =IFERROR(__xludf.DUMMYFUNCTION("IFERROR( SUM( FILTER( Reporte!$E:$E, REGEXMATCH(Reporte!$A:$A, ""(?i)(TE PAGÓ|PAGASTE)""), Reporte!$H:$H & """" = AG8 & """" ) ), 0 )"),14) -> 14 | V8: =IFERROR(__xludf.DUMMYFUNCTION("IFERROR( SUM( FILTER( Efectivo!$C:$C, Efectivo!$D:$D & """" = AG8 & """" ) ), 0 )"),0) -> 0 | W8: c | Y8: y | AB8: =IF(AND(L8>0, M8>=8, NOT(OR(W8="C", W8="c"))), "CORTE", "") | AC8: =IF( OR( AND(Q8>0, OR(W8="C", W8="c"), S8<0), AND(Q8>0, W8="") ), "CORTE", "" ) | AD8: =IF(AND(LEN(W8)>0,LEN(Y8)=0),T8,0) -> 0 | AE8: =IF(AND(LEN(W8)>0,TRIM(Y8)="Y"),T8,0) -> 14 | AF8: =TRIM(UPPER(C8)) -> A | AG8: =TRIM(UPPER(C8)) & "-" & TRIM(UPPER(D8)) -> A-7
A9: 8 | B9: VICTOR MELGAREJO CORCINO | C9: A | D9: 8 | H9: 1 | I9: 26 | J9: 49 | K9: 23 | L9: 23 | M9: 0 | N9: 0 | O9: 25 | P9: 3 | Q9: 0 | T9: =SUM(L9:S9) -> 51 | U9: =IFERROR(__xludf.DUMMYFUNCTION("IFERROR( SUM( FILTER( Reporte!$E:$E, REGEXMATCH(Reporte!$A:$A, ""(?i)(TE PAGÓ|PAGASTE)""), Reporte!$H:$H & """" = AG9 & """" ) ), 0 )"),0) -> 0 | V9: =IFERROR(__xludf.DUMMYFUNCTION("IFERROR( SUM( FILTER( Efectivo!$C:$C, Efectivo!$D:$D & """" = AG9 & """" ) ), 0 )"),0) -> 0 | AB9: =IF(AND(L9>0, M9>=8, NOT(OR(W9="C", W9="c"))), "CORTE", "") | AC9: =IF( OR( AND(Q9>0, OR(W9="C", W9="c"), S9<0), AND(Q9>0, W9="") ), "CORTE", "" ) | AD9: =IF(AND(LEN(W9)>0,LEN(Y9)=0),T9,0) -> 0 | AE9: =IF(AND(LEN(W9)>0,TRIM(Y9)="Y"),T9,0) -> 0 | AF9: =TRIM(UPPER(C9)) -> A | AG9: =TRIM(UPPER(C9)) & "-" & TRIM(UPPER(D9)) -> A-8
A10: 9 | B10: JHONI MELGAREJO BEDON | C10: A | D10: 8A | H10: 1 | I10: 186 | J10: 198 | K10: 12 | L10: 12 | M10: 0 | N10: 0 | O10: 0 | P10: 3 | Q10: 0 | T10: =SUM(L10:S10) -> 15 | U10: =IFERROR(__xludf.DUMMYFUNCTION("IFERROR( SUM( FILTER( Reporte!$E:$E, REGEXMATCH(Reporte!$A:$A, ""(?i)(TE PAGÓ|PAGASTE)""), Reporte!$H:$H & """" = AG10 & """" ) ), 0 )"),15) -> 15 | V10: =IFERROR(__xludf.DUMMYFUNCTION("IFERROR( SUM( FILTER( Efectivo!$C:$C, Efectivo!$D:$D & """" = AG10 & """" ) ), 0 )"),0) -> 0 | W10: c | Y10: y | AB10: =IF(AND(L10>0, M10>=8, NOT(OR(W10="C", W10="c"))), "CORTE", "") | AC10: =IF( OR( AND(Q10>0, OR(W10="C", W10="c"), S10<0), AND(Q10>0, W10="") ), "CORTE", "" ) | AD10: =IF(AND(LEN(W10)>0,LEN(Y10)=0),T10,0) -> 0 | AE10: =IF(AND(LEN(W10)>0,TRIM(Y10)="Y"),T10,0) -> 15 | AF10: =TRIM(UPPER(C10)) -> A | AG10: =TRIM(UPPER(C10)) & "-" & TRIM(UPPER(D10)) -> A-8A
A11: 10 | B11: ALEJANDRO MELGAREJO ESPINOZA | C11: A | D11: 9 | H11: 1 | I11: 2240 | J11: 2288 | K11: 48 | L11: 48 | M11: 0 | N11: 0 | O11: 0 | P11: 3 | Q11: 0 | T11: =SUM(L11:S11) -> 51 | U11: =IFERROR(__xludf.DUMMYFUNCTION("IFERROR( SUM( FILTER( Reporte!$E:$E, REGEXMATCH(Reporte!$A:$A, ""(?i)(TE PAGÓ|PAGASTE)""), Reporte!$H:$H & """" = AG11 & """" ) ), 0 )"),51) -> 51 | V11: =IFERROR(__xludf.DUMMYFUNCTION("IFERROR( SUM( FILTER( Efectivo!$C:$C, Efectivo!$D:$D & """" = AG11 & """" ) ), 0 )"),0) -> 0 | W11: c | Y11: y | AB11: =IF(AND(L11>0, M11>=8, NOT(OR(W11="C", W11="c"))), "CORTE", "") | AC11: =IF( OR( AND(Q11>0, OR(W11="C", W11="c"), S11<0), AND(Q11>0, W11="") ), "CORTE", "" ) | AD11: =IF(AND(LEN(W11)>0,LEN(Y11)=0),T11,0) -> 0 | AE11: =IF(AND(LEN(W11)>0,TRIM(Y11)="Y"),T11,0) -> 51 | AF11: =TRIM(UPPER(C11)) -> A | AG11: =TRIM(UPPER(C11)) & "-" & TRIM(UPPER(D11)) -> A-9
A12: 11 | B12: ISABEL PUNTILLO VEGA | C12: A | D12: 10 | H12: 1 | I12: 679 | J12: 683 | K12: 5 | L12: 5 | M12: 10 | N12: 0 | O12: 0 | P12: 3 | Q12: 0 | T12: =SUM(L12:S12) -> 18 | U12: =IFERROR(__xludf.DUMMYFUNCTION("IFERROR( SUM( FILTER( Reporte!$E:$E, REGEXMATCH(Reporte!$A:$A, ""(?i)(TE PAGÓ|PAGASTE)""), Reporte!$H:$H & """" = AG12 & """" ) ), 0 )"),18) -> 18 | V12: =IFERROR(__xludf.DUMMYFUNCTION("IFERROR( SUM( FILTER( Efectivo!$C:$C, Efectivo!$D:$D & """" = AG12 & """" ) ), 0 )"),0) -> 0 | W12: c | Y12: y | AB12: =IF(AND(L12>0, M12>=8, NOT(OR(W12="C", W12="c"))), "CORTE", "") | AC12: =IF( OR( AND(Q12>0, OR(W12="C", W12="c"), S12<0), AND(Q12>0, W12="") ), "CORTE", "" ) | AD12: =IF(AND(LEN(W12)>0,LEN(Y12)=0),T12,0) -> 0 | AE12: =IF(AND(LEN(W12)>0,TRIM(Y12)="Y"),T12,0) -> 18 | AF12: =TRIM(UPPER(C12)) -> A | AG12: =TRIM(UPPER(C12)) & "-" & TRIM(UPPER(D12)) -> A-10
A13: 12 | B13: FELIX POZO CASTRO | C13: A | D13: 11 | H13: 1 | I13: 363 | J13: 365 | K13: 5 | L13: 5 | M13: 8 | O13: 0 | P13: 3 | Q13: 0 | T13: =SUM(L13:S13) -> 16 | U13: =IFERROR(__xludf.DUMMYFUNCTION("IFERROR( SUM( FILTER( Reporte!$E:$E, REGEXMATCH(Reporte!$A:$A, ""(?i)(TE PAGÓ|PAGASTE)""), Reporte!$H:$H & """" = AG13 & """" ) ), 0 )"),16) -> 16 | V13: =IFERROR(__xludf.DUMMYFUNCTION("IFERROR( SUM( FILTER( Efectivo!$C:$C, Efectivo!$D:$D & """" = AG13 & """" ) ), 0 )"),0) -> 0 | W13: c | Y13: y | Z13: Debe 48. Corte reconexion 40, mes anterior 8 | AB13: =IF(AND(L13>0, M13>=8, NOT(OR(W13="C", W13="c"))), "CORTE", "") | AC13: =IF( OR( AND(Q13>0, OR(W13="C", W13="c"), S13<0), AND(Q13>0, W13="") ), "CORTE", "" ) | AD13: =IF(AND(LEN(W13)>0,LEN(Y13)=0),T13,0) -> 0 | AE13: =IF(AND(LEN(W13)>0,TRIM(Y13)="Y"),T13,0) -> 16 | AF13: =TRIM(UPPER(C13)) -> A | AG13: =TRIM(UPPER(C13)) & "-" & TRIM(UPPER(D13)) -> A-11
A14: 13 | B14: BACILIO UTRILLA FRANCISCO | C14: B | D14: 1 | H14: 1 | I14: 13 | J14: 23 | K14: 10 | L14: 10 | M14: 0 | N14: 0 | O14: 0 | P14: 3 | Q14: 0 | T14: =SUM(L14:S14) -> 13 | U14: =IFERROR(__xludf.DUMMYFUNCTION("IFERROR( SUM( FILTER( Reporte!$E:$E, REGEXMATCH(Reporte!$A:$A, ""(?i)(TE PAGÓ|PAGASTE)""), Reporte!$H:$H & """" = AG14 & """" ) ), 0 )"),13) -> 13 | V14: =IFERROR(__xludf.DUMMYFUNCTION("IFERROR( SUM( FILTER( Efectivo!$C:$C, Efectivo!$D:$D & """" = AG14 & """" ) ), 0 )"),0) -> 0 | W14: c | Y14: y | AB14: =IF(AND(L14>0, M14>=8, NOT(OR(W14="C", W14="c"))), "CORTE", "") | AC14: =IF( OR( AND(Q14>0, OR(W14="C", W14="c"), S14<0), AND(Q14>0, W14="") ), "CORTE", "" ) | AD14: =IF(AND(LEN(W14)>0,LEN(Y14)=0),T14,0) -> 0 | AE14: =IF(AND(LEN(W14)>0,TRIM(Y14)="Y"),T14,0) -> 13 | AF14: =TRIM(UPPER(C14)) -> B | AG14: =TRIM(UPPER(C14)) & "-" & TRIM(UPPER(D14)) -> B-1
A15: 14 | B15: ESTEBAN REYNALDO ROSALES | C15: B | D15: 2 | H15: 1 | I15: 16 | J15: 26 | K15: 10 | L15: 10 | M15: 0 | N15: 0 | O15: 25 | P15: 3 | Q15: 0 | T15: =SUM(L15:S15) -> 38 | U15: =IFERROR(__xludf.DUMMYFUNCTION("IFERROR( SUM( FILTER( Reporte!$E:$E, REGEXMATCH(Reporte!$A:$A, ""(?i)(TE PAGÓ|PAGASTE)""), Reporte!$H:$H & """" = AG15 & """" ) ), 0 )"),0) -> 0 | V15: =IFERROR(__xludf.DUMMYFUNCTION("IFERROR( SUM( FILTER( Efectivo!$C:$C, Efectivo!$D:$D & """" = AG15 & """" ) ), 0 )"),38) -> 38 | W15: c | AB15: =IF(AND(L15>0, M15>=8, NOT(OR(W15="C", W15="c"))), "CORTE", "") | AC15: =IF( OR( AND(Q15>0, OR(W15="C", W15="c"), S15<0), AND(Q15>0, W15="") ), "CORTE", "" ) | AD15: =IF(AND(LEN(W15)>0,LEN(Y15)=0),T15,0) -> 38 | AE15: =IF(AND(LEN(W15)>0,TRIM(Y15)="Y"),T15,0) -> 0 | AF15: =TRIM(UPPER(C15)) -> B | AG15: =TRIM(UPPER(C15)) & "-" & TRIM(UPPER(D15)) -> B-2
A16: 15 | B16: EDUARDO REYNALDO ROSALES | C16: B | D16: 3 | H16: 1 | I16: 837 | J16: 846 | K16: 9 | L16: 9 | M16: 0 | N16: 0 | O16: 0 | P16: 3 | Q16: 0 | T16: =SUM(L16:S16) -> 12 | U16: =IFERROR(__xludf.DUMMYFUNCTION("IFERROR( SUM( FILTER( Reporte!$E:$E, REGEXMATCH(Reporte!$A:$A, ""(?i)(TE PAGÓ|PAGASTE)""), Reporte!$H:$H & """" = AG16 & """" ) ), 0 )"),0) -> 0 | V16: =IFERROR(__xludf.DUMMYFUNCTION("IFERROR( SUM( FILTER( Efectivo!$C:$C, Efectivo!$D:$D & """" = AG16 & """" ) ), 0 )"),12) -> 12 | W16: c | AB16: =IF(AND(L16>0, M16>=8, NOT(OR(W16="C", W16="c"))), "CORTE", "") | AC16: =IF( OR( AND(Q16>0, OR(W16="C", W16="c"), S16<0), AND(Q16>0, W16="") ), "CORTE", "" ) | AD16: =IF(AND(LEN(W16)>0,LEN(Y16)=0),T16,0) -> 12 | AE16: =IF(AND(LEN(W16)>0,TRIM(Y16)="Y"),T16,0) -> 0 | AF16: =TRIM(UPPER(C16)) -> B | AG16: =TRIM(UPPER(C16)) & "-" & TRIM(UPPER(D16)) -> B-3
A17: 16 | B17: MELINA J. JUAREZ TOLEDO DE MORENO | C17: B | D17: 4 | H17: 1 | I17: 641 | J17: 655 | K17: 14 | L17: 14 | M17: 18 | N17: 0 | O17: 0 | P17: 3 | Q17: 0 | T17: =SUM(L17:S17) -> 35 | U17: =IFERROR(__xludf.DUMMYFUNCTION("IFERROR( SUM( FILTER( Reporte!$E:$E, REGEXMATCH(Reporte!$A:$A, ""(?i)(TE PAGÓ|PAGASTE)""), Reporte!$H:$H & """" = AG17 & """" ) ), 0 )"),35) -> 35 | V17: =IFERROR(__xludf.DUMMYFUNCTION("IFERROR( SUM( FILTER( Efectivo!$C:$C, Efectivo!$D:$D & """" = AG17 & """" ) ), 0 )"),0) -> 0 | W17: c | Y17: y | AB17: =IF(AND(L17>0, M17>=8, NOT(OR(W17="C", W17="c"))), "CORTE", "") | AC17: =IF( OR( AND(Q17>0, OR(W17="C", W17="c"), S17<0), AND(Q17>0, W17="") ), "CORTE", "" ) | AD17: =IF(AND(LEN(W17)>0,LEN(Y17)=0),T17,0) -> 0 | AE17: =IF(AND(LEN(W17)>0,TRIM(Y17)="Y"),T17,0) -> 35 | AF17: =TRIM(UPPER(C17)) -> B | AG17: =TRIM(UPPER(C17)) & "-" & TRIM(UPPER(D17)) -> B-4
A18: 17 | B18: POMPEYO CELESTINO LLIUYA | C18: B | D18: 5 | H18: 1 | I18: 59 | J18: 100 | K18: 41 | L18: 41 | M18: 39 | N18: 0 | O18: 25 | P18: 3 | Q18: 0 | T18: =SUM(L18:S18) -> 108 | U18: =IFERROR(__xludf.DUMMYFUNCTION("IFERROR( SUM( FILTER( Reporte!$E:$E, REGEXMATCH(Reporte!$A:$A, ""(?i)(TE PAGÓ|PAGASTE)""), Reporte!$H:$H & """" = AG18 & """" ) ), 0 )"),0) -> 0 | V18: =IFERROR(__xludf.DUMMYFUNCTION("IFERROR( SUM( FILTER( Efectivo!$C:$C, Efectivo!$D:$D & """" = AG18 & """" ) ), 0 )"),108) -> 108 | W18: c | AB18: =IF(AND(L18>0, M18>=8, NOT(OR(W18="C", W18="c"))), "CORTE", "") | AC18: =IF( OR( AND(Q18>0, OR(W18="C", W18="c"), S18<0), AND(Q18>0, W18="") ), "CORTE", "" ) | AD18: =IF(AND(LEN(W18)>0,LEN(Y18)=0),T18,0) -> 108 | AE18: =IF(AND(LEN(W18)>0,TRIM(Y18)="Y"),T18,0) -> 0 | AF18: =TRIM(UPPER(C18)) -> B | AG18: =TRIM(UPPER(C18)) & "-" & TRIM(UPPER(D18)) -> B-5
A19: 18 | B19: ROSA VICTORIA MILLA MORALES | C19: B | D19: 6 | H19: 1 | I19: 32 | J19: 62 | K19: 30 | L19: 30 | M19: 0 | N19: 0 | O19: 25 | P19: 3 | Q19: 0 | T19: =SUM(L19:S19) -> 58 | U19: =IFERROR(__xludf.DUMMYFUNCTION("IFERROR( SUM( FILTER( Reporte!$E:$E, REGEXMATCH(Reporte!$A:$A, ""(?i)(TE PAGÓ|PAGASTE)""), Reporte!$H:$H & """" = AG19 & """" ) ), 0 )"),58) -> 58 | V19: =IFERROR(__xludf.DUMMYFUNCTION("IFERROR( SUM( FILTER( Efectivo!$C:$C, Efectivo!$D:$D & """" = AG19 & """" ) ), 0 )"),0) -> 0 | W19: c | Y19: y | AB19: =IF(AND(L19>0, M19>=8, NOT(OR(W19="C", W19="c"))), "CORTE", "") | AC19: =IF( OR( AND(Q19>0, OR(W19="C", W19="c"), S19<0), AND(Q19>0, W19="") ), "CORTE", "" ) | AD19: =IF(AND(LEN(W19)>0,LEN(Y19)=0),T19,0) -> 0 | AE19: =IF(AND(LEN(W19)>0,TRIM(Y19)="Y"),T19,0) -> 58 | AF19: =TRIM(UPPER(C19)) -> B | AG19: =TRIM(UPPER(C19)) & "-" & TRIM(UPPER(D19)) -> B-6
A20: 19 | B20: LIRIA PARIAMACHI DE PAZ | C20: B | D20: 7 | H20: 1 | I20: 52 | J20: 65 | K20: 13 | L20: 13 | M20: 17 | N20: 0 | O20: 25 | P20: 3 | T20: =SUM(L20:S20) -> 58 | U20: =IFERROR(__xludf.DUMMYFUNCTION("IFERROR( SUM( FILTER( Reporte!$E:$E, REGEXMATCH(Reporte!$A:$A, ""(?i)(TE PAGÓ|PAGASTE)""), Reporte!$H:$H & """" = AG20 & """" ) ), 0 )"),58) -> 58 | V20: =IFERROR(__xludf.DUMMYFUNCTION("IFERROR( SUM( FILTER( Efectivo!$C:$C, Efectivo!$D:$D & """" = AG20 & """" ) ), 0 )"),0) -> 0 | W20: c | Y20: y | Z20: Debe 30. Faena | AB20: =IF(AND(L20>0, M20>=8, NOT(OR(W20="C", W20="c"))), "CORTE", "") | AC20: =IF( OR( AND(Q20>0, OR(W20="C", W20="c"), S20<0), AND(Q20>0, W20="") ), "CORTE", "" ) | AD20: =IF(AND(LEN(W20)>0,LEN(Y20)=0),T20,0) -> 0 | AE20: =IF(AND(LEN(W20)>0,TRIM(Y20)="Y"),T20,0) -> 58 | AF20: =TRIM(UPPER(C20)) -> B | AG20: =TRIM(UPPER(C20)) & "-" & TRIM(UPPER(D20)) -> B-7
A21: 20 | B21: ROSALINA OLIMPIA CIRIACO SOTELO | C21: B | D21: 8 | H21: 1 | I21: 21 | J21: 39 | K21: 18 | L21: 18 | M21: 0 | N21: 0 | O21: 25 | P21: 3 | Q21: 0 | T21: =SUM(L21:S21) -> 46 | U21: =IFERROR(__xludf.DUMMYFUNCTION("IFERROR( SUM( FILTER( Reporte!$E:$E, REGEXMATCH(Reporte!$A:$A, ""(?i)(TE PAGÓ|PAGASTE)""), Reporte!$H:$H & """" = AG21 & """" ) ), 0 )"),0) -> 0 | V21: =IFERROR(__xludf.DUMMYFUNCTION("IFERROR( SUM( FILTER( Efectivo!$C:$C, Efectivo!$D:$D & """" = AG21 & """" ) ), 0 )"),0) -> 0 | AB21: =IF(AND(L21>0, M21>=8, NOT(OR(W21="C", W21="c"))), "CORTE", "") | AC21: =IF( OR( AND(Q21>0, OR(W21="C", W21="c"), S21<0), AND(Q21>0, W21="") ), "CORTE", "" ) | AD21: =IF(AND(LEN(W21)>0,LEN(Y21)=0),T21,0) -> 0 | AE21: =IF(AND(LEN(W21)>0,TRIM(Y21)="Y"),T21,0) -> 0 | AF21: =TRIM(UPPER(C21)) -> B | AG21: =TRIM(UPPER(C21)) & "-" & TRIM(UPPER(D21)) -> B-8
A22: 21 | B22: ALEJANDRO RAPRAY VELASQUEZ | C22: B | D22: 9 | F22: 1 | H22: 1 | I22: 72 | J22: 78 | K22: 6 | L22: 6 | M22: 10 | N22: 40 | O22: 0 | P22: 3 | Q22: 0 | T22: =SUM(L22:S22) -> 59 | U22: =IFERROR(__xludf.DUMMYFUNCTION("IFERROR( SUM( FILTER( Reporte!$E:$E, REGEXMATCH(Reporte!$A:$A, ""(?i)(TE PAGÓ|PAGASTE)""), Reporte!$H:$H & """" = AG22 & """" ) ), 0 )"),0) -> 0 | V22: =IFERROR(__xludf.DUMMYFUNCTION("IFERROR( SUM( FILTER( Efectivo!$C:$C, Efectivo!$D:$D & """" = AG22 & """" ) ), 0 )"),59) -> 59 | W22: c | AB22: =IF(AND(L22>0, M22>=8, NOT(OR(W22="C", W22="c"))), "CORTE", "") | AC22: =IF( OR( AND(Q22>0, OR(W22="C", W22="c"), S22<0), AND(Q22>0, W22="") ), "CORTE", "" ) | AD22: =IF(AND(LEN(W22)>0,LEN(Y22)=0),T22,0) -> 59 | AE22: =IF(AND(LEN(W22)>0,TRIM(Y22)="Y"),T22,0) -> 0 | AF22: =TRIM(UPPER(C22)) -> B | AG22: =TRIM(UPPER(C22)) & "-" & TRIM(UPPER(D22)) -> B-9
A23: 22 | B23: ELVIRA PASCUALA MINAYA TAHUA | C23: B | D23: 11 | H23: 1 | I23: 26 | J23: 48 | K23: 22 | L23: 22 | M23: 19 | N23: 0 | O23: 25 | P23: 3 | Q23: 0 | T23: =SUM(L23:S23) -> 69 | U23: =IFERROR(__xludf.DUMMYFUNCTION("IFERROR( SUM( FILTER( Reporte!$E:$E, REGEXMATCH(Reporte!$A:$A, ""(?i)(TE PAGÓ|PAGASTE)""), Reporte!$H:$H & """" = AG23 & """" ) ), 0 )"),0) -> 0 | V23: =IFERROR(__xludf.DUMMYFUNCTION("IFERROR( SUM( FILTER( Efectivo!$C:$C, Efectivo!$D:$D & """" = AG23 & """" ) ), 0 )"),69) -> 69 | W23: c | AB23: =IF(AND(L23>0, M23>=8, NOT(OR(W23="C", W23="c"))), "CORTE", "") | AC23: =IF( OR( AND(Q23>0, OR(W23="C", W23="c"), S23<0), AND(Q23>0, W23="") ), "CORTE", "" ) | AD23: =IF(AND(LEN(W23)>0,LEN(Y23)=0),T23,0) -> 69 | AE23: =IF(AND(LEN(W23)>0,TRIM(Y23)="Y"),T23,0) -> 0 | AF23: =TRIM(UPPER(C23)) -> B | AG23: =TRIM(UPPER(C23)) & "-" & TRIM(UPPER(D23)) -> B-11
A24: 23 | B24: MARCELINO FELIX VILLAFANA PALLACA | C24: B | D24: 10 | H24: 1 | I24: 399 | J24: 421 | K24: 22 | L24: 22 | M24: 0 | N24: 0 | O24: 0 | P24: 3 | Q24: 0 | T24: =SUM(L24:S24) -> 25 | U24: =IFERROR(__xludf.DUMMYFUNCTION("IFERROR( SUM( FILTER( Reporte!$E:$E, REGEXMATCH(Reporte!$A:$A, ""(?i)(TE PAGÓ|PAGASTE)""), Reporte!$H:$H & """" = AG24 & """" ) ), 0 )"),0) -> 0 | V24: =IFERROR(__xludf.DUMMYFUNCTION("IFERROR( SUM( FILTER( Efectivo!$C:$C, Efectivo!$D:$D & """" = AG24 & """" ) ), 0 )"),0) -> 0 | AB24: =IF(AND(L24>0, M24>=8, NOT(OR(W24="C", W24="c"))), "CORTE", "") | AC24: =IF( OR( AND(Q24>0, OR(W24="C", W24="c"), S24<0), AND(Q24>0, W24="") ), "CORTE", "" ) | AD24: =IF(AND(LEN(W24)>0,LEN(Y24)=0),T24,0) -> 0 | AE24: =IF(AND(LEN(W24)>0,TRIM(Y24)="Y"),T24,0) -> 0 | AF24: =TRIM(UPPER(C24)) -> B | AG24: =TRIM(UPPER(C24)) & "-" & TRIM(UPPER(D24)) -> B-10
A25: 24 | B25: TEOFILO BRUNO RAMOS DE LA CRUZ | C25: B | D25: 12 | H25: 1 | I25: 9 | J25: 14 | K25: 5 | L25: 5 | M25: 0 | N25: 0 | O25: 0 | P25: 3 | Q25: 0 | T25: =SUM(L25:S25) -> 8 | U25: =IFERROR(__xludf.DUMMYFUNCTION("IFERROR( SUM( FILTER( Reporte!$E:$E, REGEXMATCH(Reporte!$A:$A, ""(?i)(TE PAGÓ|PAGASTE)""), Reporte!$H:$H & """" = AG25 & """" ) ), 0 )"),0) -> 0 | V25: =IFERROR(__xludf.DUMMYFUNCTION("IFERROR( SUM( FILTER( Efectivo!$C:$C, Efectivo!$D:$D & """" = AG25 & """" ) ), 0 )"),0) -> 0 | AB25: =IF(AND(L25>0, M25>=8, NOT(OR(W25="C", W25="c"))), "CORTE", "") | AC25: =IF( OR( AND(Q25>0, OR(W25="C", W25="c"), S25<0), AND(Q25>0, W25="") ), "CORTE", "" ) | AD25: =IF(AND(LEN(W25)>0,LEN(Y25)=0),T25,0) -> 0 | AE25: =IF(AND(LEN(W25)>0,TRIM(Y25)="Y"),T25,0) -> 0 | AF25: =TRIM(UPPER(C25)) -> B | AG25: =TRIM(UPPER(C25)) & "-" & TRIM(UPPER(D25)) -> B-12
A26: 25 | B26: ROSMERI SANCHEZ ESPADA | C26: B | D26: 12A | H26: 1 | I26: 365 | J26: 371 | K26: 6 | L26: 6 | M26: 9 | N26: 20 | O26: 0 | P26: 3 | Q26: 0 | T26: =SUM(L26:S26) -> 38 | U26: =IFERROR(__xludf.DUMMYFUNCTION("IFERROR( SUM( FILTER( Reporte!$E:$E, REGEXMATCH(Reporte!$A:$A, ""(?i)(TE PAGÓ|PAGASTE)""), Reporte!$H:$H & """" = AG26 & """" ) ), 0 )"),38) -> 38 | V26: =IFERROR(__xludf.DUMMYFUNCTION("IFERROR( SUM( FILTER( Efectivo!$C:$C, Efectivo!$D:$D & """" = AG26 & """" ) ), 0 )"),0) -> 0 | W26: c | Y26: y | Z26: Debe 20. Corte y reconexion | AB26: =IF(AND(L26>0, M26>=8, NOT(OR(W26="C", W26="c"))), "CORTE", "") | AC26: =IF( OR( AND(Q26>0, OR(W26="C", W26="c"), S26<0), AND(Q26>0, W26="") ), "CORTE", "" ) | AD26: =IF(AND(LEN(W26)>0,LEN(Y26)=0),T26,0) -> 0 | AE26: =IF(AND(LEN(W26)>0,TRIM(Y26)="Y"),T26,0) -> 38 | AF26: =TRIM(UPPER(C26)) -> B | AG26: =TRIM(UPPER(C26)) & "-" & TRIM(UPPER(D26)) -> B-12A
A27: 26 | B27: SALOME AGUSTINA DIAZ VARGAS | C27: B | D27: 13 | H27: 1 | I27: 300 | J27: 306 | K27: 6 | L27: 6 | M27: 0 | N27: 0 | O27: 0 | P27: 3 | Q27: 0 | T27: =SUM(L27:S27) -> 9 | U27: =IFERROR(__xludf.DUMMYFUNCTION("IFERROR( SUM( FILTER( Reporte!$E:$E, REGEXMATCH(Reporte!$A:$A, ""(?i)(TE PAGÓ|PAGASTE)""), Reporte!$H:$H & """" = AG27 & """" ) ), 0 )"),9) -> 9 | V27: =IFERROR(__xludf.DUMMYFUNCTION("IFERROR( SUM( FILTER( Efectivo!$C:$C, Efectivo!$D:$D & """" = AG27 & """" ) ), 0 )"),0) -> 0 | W27: c | Y27: y | AB27: =IF(AND(L27>0, M27>=8, NOT(OR(W27="C", W27="c"))), "CORTE", "") | AC27: =IF( OR( AND(Q27>0, OR(W27="C", W27="c"), S27<0), AND(Q27>0, W27="") ), "CORTE", "" ) | AD27: =IF(AND(LEN(W27)>0,LEN(Y27)=0),T27,0) -> 0 | AE27: =IF(AND(LEN(W27)>0,TRIM(Y27)="Y"),T27,0) -> 9 | AF27: =TRIM(UPPER(C27)) -> B | AG27: =TRIM(UPPER(C27)) & "-" & TRIM(UPPER(D27)) -> B-13
A28: 27 | B28: MELISSA ISABEL PILLACA GARCIA | C28: B | D28: 15 | H28: 1 | I28: 1295 | J28: 1311 | K28: 16 | L28: 16 | M28: 0 | N28: 0 | O28: 0 | P28: 3 | Q28: 0 | T28: =SUM(L28:S28) -> 19 | U28: =IFERROR(__xludf.DUMMYFUNCTION("IFERROR( SUM( FILTER( Reporte!$E:$E, REGEXMATCH(Reporte!$A:$A, ""(?i)(TE PAGÓ|PAGASTE)""), Reporte!$H:$H & """" = AG28 & """" ) ), 0 )"),19) -> 19 | V28: =IFERROR(__xludf.DUMMYFUNCTION("IFERROR( SUM( FILTER( Efectivo!$C:$C, Efectivo!$D:$D & """" = AG28 & """" ) ), 0 )"),0) -> 0 | W28: c | Y28: y | AB28: =IF(AND(L28>0, M28>=8, NOT(OR(W28="C", W28="c"))), "CORTE", "") | AC28: =IF( OR( AND(Q28>0, OR(W28="C", W28="c"), S28<0), AND(Q28>0, W28="") ), "CORTE", "" ) | AD28: =IF(AND(LEN(W28)>0,LEN(Y28)=0),T28,0) -> 0 | AE28: =IF(AND(LEN(W28)>0,TRIM(Y28)="Y"),T28,0) -> 19 | AF28: =TRIM(UPPER(C28)) -> B | AG28: =TRIM(UPPER(C28)) & "-" & TRIM(UPPER(D28)) -> B-15
A29: 28 | B29: ELEUTERIA DOMITILA PARIAMACHI DE PAZ | C29: B | D29: 16 | H29: 1 | I29: 34 | J29: 35 | K29: 5 | L29: 5 | M29: 8 | N29: 40 | O29: 0 | P29: 3 | Q29: 0 | T29: =SUM(L29:S29) -> 56 | U29: =IFERROR(__xludf.DUMMYFUNCTION("IFERROR( SUM( FILTER( Reporte!$E:$E, REGEXMATCH(Reporte!$A:$A, ""(?i)(TE PAGÓ|PAGASTE)""), Reporte!$H:$H & """" = AG29 & """" ) ), 0 )"),0) -> 0 | V29: =IFERROR(__xludf.DUMMYFUNCTION("IFERROR( SUM( FILTER( Efectivo!$C:$C, Efectivo!$D:$D & """" = AG29 & """" ) ), 0 )"),0) -> 0 | AB29: =IF(AND(L29>0, M29>=8, NOT(OR(W29="C", W29="c"))), "CORTE", "") -> CORTE | AC29: =IF( OR( AND(Q29>0, OR(W29="C", W29="c"), S29<0), AND(Q29>0, W29="") ), "CORTE", "" ) | AD29: =IF(AND(LEN(W29)>0,LEN(Y29)=0),T29,0) -> 0 | AE29: =IF(AND(LEN(W29)>0,TRIM(Y29)="Y"),T29,0) -> 0 | AF29: =TRIM(UPPER(C29)) -> B | AG29: =TRIM(UPPER(C29)) & "-" & TRIM(UPPER(D29)) -> B-16
A30: 29 | B30: LUZ DINA MIRAVAL HUERTA | C30: B | D30: 17 | H30: 1 | I30: 1093 | J30: 1122 | K30: 29 | L30: 29 | M30: 31 | O30: 0 | P30: 3 | Q30: 0 | T30: =SUM(L30:S30) -> 63 | U30: =IFERROR(__xludf.DUMMYFUNCTION("IFERROR( SUM( FILTER( Reporte!$E:$E, REGEXMATCH(Reporte!$A:$A, ""(?i)(TE PAGÓ|PAGASTE)""), Reporte!$H:$H & """" = AG30 & """" ) ), 0 )"),63) -> 63 | V30: =IFERROR(__xludf.DUMMYFUNCTION("IFERROR( SUM( FILTER( Efectivo!$C:$C, Efectivo!$D:$D & """" = AG30 & """" ) ), 0 )"),0) -> 0 | W30: c | Y30: y | Z30: Debe 40. Corte y reconexion | AB30: =IF(AND(L30>0, M30>=8, NOT(OR(W30="C", W30="c"))), "CORTE", "") | AC30: =IF( OR( AND(Q30>0, OR(W30="C", W30="c"), S30<0), AND(Q30>0, W30="") ), "CORTE", "" ) | AD30: =IF(AND(LEN(W30)>0,LEN(Y30)=0),T30,0) -> 0 | AE30: =IF(AND(LEN(W30)>0,TRIM(Y30)="Y"),T30,0) -> 63 | AF30: =TRIM(UPPER(C30)) -> B | AG30: =TRIM(UPPER(C30)) & "-" & TRIM(UPPER(D30)) -> B-17
A31: 30 | B31: CLETO TENORIO MORI | C31: B | D31: 18 | H31: 1 | I31: 577 | J31: 584 | K31: 7 | L31: 7 | M31: 8 | N31: 0 | O31: 0 | P31: 3 | Q31: 0 | T31: =SUM(L31:S31) -> 18 | U31: =IFERROR(__xludf.DUMMYFUNCTION("IFERROR( SUM( FILTER( Reporte!$E:$E, REGEXMATCH(Reporte!$A:$A, ""(?i)(TE PAGÓ|PAGASTE)""), Reporte!$H:$H & """" = AG31 & """" ) ), 0 )"),0) -> 0 | V31: =IFERROR(__xludf.DUMMYFUNCTION("IFERROR( SUM( FILTER( Efectivo!$C:$C, Efectivo!$D:$D & """" = AG31 & """" ) ), 0 )"),18) -> 18 | W31: c | AB31: =IF(AND(L31>0, M31>=8, NOT(OR(W31="C", W31="c"))), "CORTE", "") | AC31: =IF( OR( AND(Q31>0, OR(W31="C", W31="c"), S31<0), AND(Q31>0, W31="") ), "CORTE", "" ) | AD31: =IF(AND(LEN(W31)>0,LEN(Y31)=0),T31,0) -> 18 | AE31: =IF(AND(LEN(W31)>0,TRIM(Y31)="Y"),T31,0) -> 0 | AF31: =TRIM(UPPER(C31)) -> B | AG31: =TRIM(UPPER(C31)) & "-" & TRIM(UPPER(D31)) -> B-18
A32: 31 | B32: CAMILA HIDALGO | C32: B | D32: 21 | H32: 1 | I32: 199 | J32: 206 | K32: 7 | L32: 7 | M32: 15 | N32: 20 | O32: 0 | P32: 3 | T32: =SUM(L32:S32) -> 45 | U32: =IFERROR(__xludf.DUMMYFUNCTION("IFERROR( SUM( FILTER( Reporte!$E:$E, REGEXMATCH(Reporte!$A:$A, ""(?i)(TE PAGÓ|PAGASTE)""), Reporte!$H:$H & """" = AG32 & """" ) ), 0 )"),45) -> 45 | V32: =IFERROR(__xludf.DUMMYFUNCTION("IFERROR( SUM( FILTER( Efectivo!$C:$C, Efectivo!$D:$D & """" = AG32 & """" ) ), 0 )"),0) -> 0 | W32: c | Y32: y | Z32: Debe 20. Corte y reconexion. | AB32: =IF(AND(L32>0, M32>=8, NOT(OR(W32="C", W32="c"))), "CORTE", "") | AC32: =IF( OR( AND(Q32>0, OR(W32="C", W32="c"), S32<0), AND(Q32>0, W32="") ), "CORTE", "" ) | AD32: =IF(AND(LEN(W32)>0,LEN(Y32)=0),T32,0) -> 0 | AE32: =IF(AND(LEN(W32)>0,TRIM(Y32)="Y"),T32,0) -> 45 | AF32: =TRIM(UPPER(C32)) -> B | AG32: =TRIM(UPPER(C32)) & "-" & TRIM(UPPER(D32)) -> B-21
T33: =SUM(L33:S33) -> 0 | U33: =IFERROR(__xludf.DUMMYFUNCTION("IFERROR( SUM( FILTER( Reporte!$E:$E, REGEXMATCH(Reporte!$A:$A, ""(?i)(TE PAGÓ|PAGASTE)""), Reporte!$H:$H & """" = AG33 & """" ) ), 0 )"),-8203.9) -> -8203.9 | V33: =IFERROR(__xludf.DUMMYFUNCTION("IFERROR( SUM( FILTER( Efectivo!$C:$C, Efectivo!$D:$D & """" = AG33 & """" ) ), 0 )"),0) -> 0 | AB33: =IF(AND(L33>0, M33>=8, NOT(OR(W33="C", W33="c"))), "CORTE", "") | AC33: =IF( OR( AND(Q33>0, OR(W33="C", W33="c"), S33<0), AND(Q33>0, W33="") ), "CORTE", "" ) | AD33: =IF(AND(LEN(W33)>0,LEN(Y33)=0),T33,0) -> 0 | AE33: =IF(AND(LEN(W33)>0,TRIM(Y33)="Y"),T33,0) -> 0 | AF33: =TRIM(UPPER(C33)) | AG33: =TRIM(UPPER(C33)) & "-" & TRIM(UPPER(D33)) -> -
A34: 32 | B34: JANET FERNANDEZ MINAYA | C34: B | D34: 29 | E34: N | H34: 1 | I34: 187 | J34: 195 | K34: 8 | L34: 8 | M34: 0 | N34: 0 | O34: 283 | P34: 3 | Q34: 0 | T34: =SUM(L34:S34) -> 294 | U34: =IFERROR(__xludf.DUMMYFUNCTION("IFERROR( SUM( FILTER( Reporte!$E:$E, REGEXMATCH(Reporte!$A:$A, ""(?i)(TE PAGÓ|PAGASTE)""), Reporte!$H:$H & """" = AG34 & """" ) ), 0 )"),0) -> 0 | V34: =IFERROR(__xludf.DUMMYFUNCTION("IFERROR( SUM( FILTER( Efectivo!$C:$C, Efectivo!$D:$D & """" = AG34 & """" ) ), 0 )"),0) -> 0 | AB34: =IF(AND(L34>0, M34>=8, NOT(OR(W34="C", W34="c"))), "CORTE", "") | AC34: =IF( OR( AND(Q34>0, OR(W34="C", W34="c"), S34<0), AND(Q34>0, W34="") ), "CORTE", "" ) | AD34: =IF(AND(LEN(W34)>0,LEN(Y34)=0),T34,0) -> 0 | AE34: =IF(AND(LEN(W34)>0,TRIM(Y34)="Y"),T34,0) -> 0 | AF34: =TRIM(UPPER(C34)) -> B | AG34: =TRIM(UPPER(C34)) & "-" & TRIM(UPPER(D34)) -> B-29
A35: 33 | B35: ODILON CERNA ROMERO | C35: C | D35: 1 | H35: 1 | I35: 21 | J35: 37 | K35: 16 | L35: 16 | M35: 18 | N35: 0 | O35: 25 | P35: 3 | Q35: 0 | T35: =SUM(L35:S35) -> 62 | U35: =IFERROR(__xludf.DUMMYFUNCTION("IFERROR( SUM( FILTER( Reporte!$E:$E, REGEXMATCH(Reporte!$A:$A, ""(?i)(TE PAGÓ|PAGASTE)""), Reporte!$H:$H & """" = AG35 & """" ) ), 0 )"),62) -> 62 | V35: =IFERROR(__xludf.DUMMYFUNCTION("IFERROR( SUM( FILTER( Efectivo!$C:$C, Efectivo!$D:$D & """" = AG35 & """" ) ), 0 )"),0) -> 0 | W35: c | Y35: y | AB35: =IF(AND(L35>0, M35>=8, NOT(OR(W35="C", W35="c"))), "CORTE", "") | AC35: =IF( OR( AND(Q35>0, OR(W35="C", W35="c"), S35<0), AND(Q35>0, W35="") ), "CORTE", "" ) | AD35: =IF(AND(LEN(W35)>0,LEN(Y35)=0),T35,0) -> 0 | AE35: =IF(AND(LEN(W35)>0,TRIM(Y35)="Y"),T35,0) -> 62 | AF35: =TRIM(UPPER(C35)) -> C | AG35: =TRIM(UPPER(C35)) & "-" & TRIM(UPPER(D35)) -> C-1
A36: 34 | B36: OLGA FLORENTINA HUERTA AGAMA | C36: C | D36: 2 | H36: 1 | I36: 6 | J36: 11 | K36: 5 | L36: 5 | M36: 0 | N36: 0 | O36: 25 | P36: 3 | Q36: 0 | T36: =SUM(L36:S36) -> 33 | U36: =IFERROR(__xludf.DUMMYFUNCTION("IFERROR( SUM( FILTER( Reporte!$E:$E, REGEXMATCH(Reporte!$A:$A, ""(?i)(TE PAGÓ|PAGASTE)""), Reporte!$H:$H & """" = AG36 & """" ) ), 0 )"),0) -> 0 | V36: =IFERROR(__xludf.DUMMYFUNCTION("IFERROR( SUM( FILTER( Efectivo!$C:$C, Efectivo!$D:$D & """" = AG36 & """" ) ), 0 )"),33) -> 33 | W36: c | AB36: =IF(AND(L36>0, M36>=8, NOT(OR(W36="C", W36="c"))), "CORTE", "") | AC36: =IF( OR( AND(Q36>0, OR(W36="C", W36="c"), S36<0), AND(Q36>0, W36="") ), "CORTE", "" ) | AD36: =IF(AND(LEN(W36)>0,LEN(Y36)=0),T36,0) -> 33 | AE36: =IF(AND(LEN(W36)>0,TRIM(Y36)="Y"),T36,0) -> 0 | AF36: =TRIM(UPPER(C36)) -> C | AG36: =TRIM(UPPER(C36)) & "-" & TRIM(UPPER(D36)) -> C-2
A37: 35 | B37: TIMOTEO ROMERO JULCA | C37: C | D37: 4 | H37: 1 | I37: 21 | J37: 31 | K37: 10 | L37: 10 | M37: 0 | N37: 0 | O37: 25 | P37: 3 | Q37: 0 | T37: =SUM(L37:S37) -> 38 | U37: =IFERROR(__xludf.DUMMYFUNCTION("IFERROR( SUM( FILTER( Reporte!$E:$E, REGEXMATCH(Reporte!$A:$A, ""(?i)(TE PAGÓ|PAGASTE)""), Reporte!$H:$H & """" = AG37 & """" ) ), 0 )"),0) -> 0 | V37: =IFERROR(__xludf.DUMMYFUNCTION("IFERROR( SUM( FILTER( Efectivo!$C:$C, Efectivo!$D:$D & """" = AG37 & """" ) ), 0 )"),38) -> 38 | W37: c | AB37: =IF(AND(L37>0, M37>=8, NOT(OR(W37="C", W37="c"))), "CORTE", "") | AC37: =IF( OR( AND(Q37>0, OR(W37="C", W37="c"), S37<0), AND(Q37>0, W37="") ), "CORTE", "" ) | AD37: =IF(AND(LEN(W37)>0,LEN(Y37)=0),T37,0) -> 38 | AE37: =IF(AND(LEN(W37)>0,TRIM(Y37)="Y"),T37,0) -> 0 | AF37: =TRIM(UPPER(C37)) -> C | AG37: =TRIM(UPPER(C37)) & "-" & TRIM(UPPER(D37)) -> C-4
A38: 36 | B38: AGAPITO PRINCIPE SALINAS | C38: C | D38: 5 | H38: 1 | I38: 26 | J38: 49 | K38: 23 | L38: 23 | M38: 0 | N38: 0 | O38: 25 | P38: 3 | Q38: 0 | T38: =SUM(L38:S38) -> 51 | U38: =IFERROR(__xludf.DUMMYFUNCTION("IFERROR( SUM( FILTER( Reporte!$E:$E, REGEXMATCH(Reporte!$A:$A, ""(?i)(TE PAGÓ|PAGASTE)""), Reporte!$H:$H & """" = AG38 & """" ) ), 0 )"),51) -> 51 | V38: =IFERROR(__xludf.DUMMYFUNCTION("IFERROR( SUM( FILTER( Efectivo!$C:$C, Efectivo!$D:$D & """" = AG38 & """" ) ), 0 )"),0) -> 0 | W38: c | Y38: y | AB38: =IF(AND(L38>0, M38>=8, NOT(OR(W38="C", W38="c"))), "CORTE", "") | AC38: =IF( OR( AND(Q38>0, OR(W38="C", W38="c"), S38<0), AND(Q38>0, W38="") ), "CORTE", "" ) | AD38: =IF(AND(LEN(W38)>0,LEN(Y38)=0),T38,0) -> 0 | AE38: =IF(AND(LEN(W38)>0,TRIM(Y38)="Y"),T38,0) -> 51 | AF38: =TRIM(UPPER(C38)) -> C | AG38: =TRIM(UPPER(C38)) & "-" & TRIM(UPPER(D38)) -> C-5
A39: 37 | B39: DIANA JARA TRUJILLO | C39: C | D39: 6 | H39: 1 | I39: 598 | J39: 605 | K39: 7 | L39: 7 | M39: 0 | N39: 0 | O39: 0 | P39: 3 | Q39: 0 | T39: =SUM(L39:S39) -> 10 | U39: =IFERROR(__xludf.DUMMYFUNCTION("IFERROR( SUM( FILTER( Reporte!$E:$E, REGEXMATCH(Reporte!$A:$A, ""(?i)(TE PAGÓ|PAGASTE)""), Reporte!$H:$H & """" = AG39 & """" ) ), 0 )"),10) -> 10 | V39: =IFERROR(__xludf.DUMMYFUNCTION("IFERROR( SUM( FILTER( Efectivo!$C:$C, Efectivo!$D:$D & """" = AG39 & """" ) ), 0 )"),0) -> 0 | W39: c | Y39: y | AB39: =IF(AND(L39>0, M39>=8, NOT(OR(W39="C", W39="c"))), "CORTE", "") | AC39: =IF( OR( AND(Q39>0, OR(W39="C", W39="c"), S39<0), AND(Q39>0, W39="") ), "CORTE", "" ) | AD39: =IF(AND(LEN(W39)>0,LEN(Y39)=0),T39,0) -> 0 | AE39: =IF(AND(LEN(W39)>0,TRIM(Y39)="Y"),T39,0) -> 10 | AF39: =TRIM(UPPER(C39)) -> C | AG39: =TRIM(UPPER(C39)) & "-" & TRIM(UPPER(D39)) -> C-6
A40: 38 | B40: VICTOR LOPEZ TRUJILLO | C40: C | D40: 7 | H40: 1 | I40: 53 | J40: 79 | K40: 26 | L40: 26 | M40: 0 | N40: 0 | O40: 25 | P40: 3 | Q40: 0 | T40: =SUM(L40:S40) -> 54 | U40: =IFERROR(__xludf.DUMMYFUNCTION("IFERROR( SUM( FILTER( Reporte!$E:$E, REGEXMATCH(Reporte!$A:$A, ""(?i)(TE PAGÓ|PAGASTE)""), Reporte!$H:$H & """" = AG40 & """" ) ), 0 )"),0) -> 0 | V40: =IFERROR(__xludf.DUMMYFUNCTION("IFERROR( SUM( FILTER( Efectivo!$C:$C, Efectivo!$D:$D & """" = AG40 & """" ) ), 0 )"),0) -> 0 | AB40: =IF(AND(L40>0, M40>=8, NOT(OR(W40="C", W40="c"))), "CORTE", "") | AC40: =IF( OR( AND(Q40>0, OR(W40="C", W40="c"), S40<0), AND(Q40>0, W40="") ), "CORTE", "" ) | AD40: =IF(AND(LEN(W40)>0,LEN(Y40)=0),T40,0) -> 0 | AE40: =IF(AND(LEN(W40)>0,TRIM(Y40)="Y"),T40,0) -> 0 | AF40: =TRIM(UPPER(C40)) -> C | AG40: =TRIM(UPPER(C40)) & "-" & TRIM(UPPER(D40)) -> C-7
...

Sheet INGRESOS Y EGRESOS
B1: MONEDEROS | F1: EFECTIVO
B2: AGUA | F2: AGUA
A3: FECHA | B3: CONCEPTO | C3: MONTO | F3: CONCEPTO | G3: MONTO
B4: JANET | C4: =Cobranza!AE503 -> 8654.5 | F4: RECAUDADO PLANILLA | G4: =Cobranza!AD503 -> 3105
B5: Yape blanco | C5: 30
B6: Dinero que es del efectivo de planilla | C6: -83 | F6: Dinero que esta en el Yape Planilla | G6: 83
B7: Entrada de Yape | C7: 150
B8: Salida Yape | C8: -8775.9
B20: SALDO | C20: =SUM(C4:C16) -> -24.4 | F20: SALDO | G20: =SUM(G4:G19) -> 3188
B21: Yanet tiene yape Este mes | C21: -24.4 | F21: Yanet tiene efectivo | G21: 3176
B22: Sobra o falta | C22: =C21-C20 -> -3.623768e-13 | F22: Sobra o falta | G22: =G21-G20 -> -12
F24: NOTA
F25: G21 sobra dinero. Se espera su dueño | G25: 18
Z26: 2064

Sheet Techado
A1: Nª | B1: NOMBRE | C1: MZ | D1: LT | E1: MONTO
A2: 54 | B2: ALFREDO CARLOS VENTURO CAPCHA | C2: C | D2: 24 | E2: 25

Sheet Yape por MZ
A1: Yape por Manzana
A3: Mnz | B3: Llave1 | C3: Reporte Yape-M | D3: Planilla-A | E3: Saldos | F3: Comentario
A4: A | B4: =TRIM(UPPER(A4)) -> A | C4: =SUMIF(Reporte!$F$2:$F$632, 'Yape por MZ'!A4, Reporte!$E$2:$E$632) -> 228 | D4: =SUMPRODUCT((UPPER(Cobranza!$C$2:$C$500)=UPPER(A4))*(UPPER(Cobranza!$W$2:$W$500)="C")*(UPPER(Cobranza!$Y$2:$Y$500)="Y")*(Cobranza!$T$2:$T$500)) -> 303 | E4: =C4-D4 -> -75 | G4: =IF(OR(D4=C4), 0, 1) -> 1
A5: B | B5: =TRIM(UPPER(A5)) -> B | C5: =SUMIF(Reporte!$F$2:$F$632, 'Yape por MZ'!A5, Reporte!$E$2:$E$632) -> 338 | D5: =SUMPRODUCT((UPPER(Cobranza!$C$2:$C$500)=UPPER(A5))*(UPPER(Cobranza!$W$2:$W$500)="C")*(UPPER(Cobranza!$Y$2:$Y$500)="Y")*(Cobranza!$T$2:$T$500)) -> 338 | E5: =C5-D5 -> 0 | G5: =IF(OR(D5=C5), 0, 1) -> 0
A6: C | B6: =TRIM(UPPER(A6)) -> C | C6: =SUMIF(Reporte!$F$2:$F$632, 'Yape por MZ'!A6, Reporte!$E$2:$E$632) -> 624 | D6: =SUMPRODUCT((UPPER(Cobranza!$C$2:$C$500)=UPPER(A6))*(UPPER(Cobranza!$W$2:$W$500)="C")*(UPPER(Cobranza!$Y$2:$Y$500)="Y")*(Cobranza!$T$2:$T$500)) -> 624 | E6: =C6-D6 -> 0 | G6: =IF(OR(D6=C6), 0, 1) -> 0
A7: D | B7: =TRIM(UPPER(A7)) -> D | C7: =SUMIF(Reporte!$F$2:$F$632, 'Yape por MZ'!A7, Reporte!$E$2:$E$632) -> 726 | D7: =SUMPRODUCT((UPPER(Cobranza!$C$2:$C$500)=UPPER(A7))*(UPPER(Cobranza!$W$2:$W$500)="C")*(UPPER(Cobranza!$Y$2:$Y$500)="Y")*(Cobranza!$T$2:$T$500)) -> 726 | E7: =C7-D7 -> 0 | G7: =IF(OR(D7=C7), 0, 1) -> 0
A8: E | B8: =TRIM(UPPER(A8)) -> E | C8: =SUMIF(Reporte!$F$2:$F$632, 'Yape por MZ'!A8, Reporte!$E$2:$E$632) -> 244 | D8: =SUMPRODUCT((UPPER(Cobranza!$C$2:$C$500)=UPPER(A8))*(UPPER(Cobranza!$W$2:$W$500)="C")*(UPPER(Cobranza!$Y$2:$Y$500)="Y")*(Cobranza!$T$2:$T$500)) -> 244 | E8: =C8-D8 -> 0 | G8: =IF(OR(D8=C8), 0, 1) -> 0
A9: F | B9: =TRIM(UPPER(A9)) -> F | C9: =SUMIF(Reporte!$F$2:$F$632, 'Yape por MZ'!A9, Reporte!$E$2:$E$632) -> 466 | D9: =SUMPRODUCT((UPPER(Cobranza!$C$2:$C$500)=UPPER(A9))*(UPPER(Cobranza!$W$2:$W$500)="C")*(UPPER(Cobranza!$Y$2:$Y$500)="Y")*(Cobranza!$T$2:$T$500)) -> 466 | E9: =C9-D9 -> 0 | G9: =IF(OR(D9=C9), 0, 1) -> 0
A10: G | B10: =TRIM(UPPER(A10)) -> G | C10: =SUMIF(Reporte!$F$2:$F$632, 'Yape por MZ'!A10, Reporte!$E$2:$E$632) -> 470 | D10: =SUMPRODUCT((UPPER(Cobranza!$C$2:$C$500)=UPPER(A10))*(UPPER(Cobranza!$W$2:$W$500)="C")*(UPPER(Cobranza!$Y$2:$Y$500)="Y")*(Cobranza!$T$2:$T$500)) -> 470 | E10: =C10-D10 -> 0 | G10: =IF(OR(D10=C10), 0, 1) -> 0
A11: H | B11: =TRIM(UPPER(A11)) -> H | C11: =SUMIF(Reporte!$F$2:$F$632, 'Yape por MZ'!A11, Reporte!$E$2:$E$632) -> 438 | D11: =SUMPRODUCT((UPPER(Cobranza!$C$2:$C$500)=UPPER(A11))*(UPPER(Cobranza!$W$2:$W$500)="C")*(UPPER(Cobranza!$Y$2:$Y$500)="Y")*(Cobranza!$T$2:$T$500)) -> 438 | E11: =C11-D11 -> 0 | G11: =IF(OR(D11=C11), 0, 1) -> 0
A12: I | B12: =TRIM(UPPER(A12)) -> I | C12: =SUMIF(Reporte!$F$2:$F$632, 'Yape por MZ'!A12, Reporte!$E$2:$E$632) -> 491 | D12: =SUMPRODUCT((UPPER(Cobranza!$C$2:$C$500)=UPPER(A12))*(UPPER(Cobranza!$W$2:$W$500)="C")*(UPPER(Cobranza!$Y$2:$Y$500)="Y")*(Cobranza!$T$2:$T$500)) -> 491 | E12: =C12-D12 -> 0 | G12: =IF(OR(D12=C12), 0, 1) -> 0
A13: J | B13: =TRIM(UPPER(A13)) -> J | C13: =SUMIF(Reporte!$F$2:$F$632, 'Yape por MZ'!A13, Reporte!$E$2:$E$632) -> 206 | D13: =SUMPRODUCT((UPPER(Cobranza!$C$2:$C$500)=UPPER(A13))*(UPPER(Cobranza!$W$2:$W$500)="C")*(UPPER(Cobranza!$Y$2:$Y$500)="Y")*(Cobranza!$T$2:$T$500)) -> 206 | E13: =C13-D13 -> 0 | G13: =IF(OR(D13=C13), 0, 1) -> 0
A14: K | B14: =TRIM(UPPER(A14)) -> K | C14: =SUMIF(Reporte!$F$2:$F$632, 'Yape por MZ'!A14, Reporte!$E$2:$E$632) -> 372 | D14: =SUMPRODUCT((UPPER(Cobranza!$C$2:$C$500)=UPPER(A14))*(UPPER(Cobranza!$W$2:$W$500)="C")*(UPPER(Cobranza!$Y$2:$Y$500)="Y")*(Cobranza!$T$2:$T$500)) -> 372 | E14: =C14-D14 -> 0 | G14: =IF(OR(D14=C14), 0, 1) -> 0
A15: L | B15: =TRIM(UPPER(A15)) -> L | C15: =SUMIF(Reporte!$F$2:$F$632, 'Yape por MZ'!A15, Reporte!$E$2:$E$632) -> 350 | D15: =SUMPRODUCT((UPPER(Cobranza!$C$2:$C$500)=UPPER(A15))*(UPPER(Cobranza!$W$2:$W$500)="C")*(UPPER(Cobranza!$Y$2:$Y$500)="Y")*(Cobranza!$T$2:$T$500)) -> 350 | E15: =C15-D15 -> 0 | G15: =IF(OR(D15=C15), 0, 1) -> 0
... A20: Q | B20: =TRIM(UPPER(A20)) -> Q | C20: =SUMIF(Reporte!$F$2:$F$632, 'Yape por MZ'!A20, Reporte!$E$2:$E$632) -> 306 | D20: =SUMPRODUCT((UPPER(Cobranza!$C$2:$C$500)=UPPER(A20))*(UPPER(Cobranza!$W$2:$W$500)="C")*(UPPER(Cobranza!$Y$2:$Y$500)="Y")*(Cobranza!$T$2:$T$500)) -> 306 | E20: =C20-D20 -> 0 | G20: =IF(OR(D20=C20), 0, 1) -> 0
A21: R | B21: =TRIM(UPPER(A21)) -> R | C21: =SUMIF(Reporte!$F$2:$F$632, 'Yape por MZ'!A21, Reporte!$E$2:$E$632) -> 93 | D21: =SUMPRODUCT((UPPER(Cobranza!$C$2:$C$500)=UPPER(A21))*(UPPER(Cobranza!$W$2:$W$500)="C")*(UPPER(Cobranza!$Y$2:$Y$500)="Y")*(Cobranza!$T$2:$T$500)) -> 93 | E21: =C21-D21 -> 0 | G21: =IF(OR(D21=C21), 0, 1) -> 0 | J21: NOTA
A22: S | B22: =TRIM(UPPER(A22)) -> S | C22: =SUMIF(Reporte!$F$2:$F$632, 'Yape por MZ'!A22, Reporte!$E$2:$E$632) -> 122 | D22: =SUMPRODUCT((UPPER(Cobranza!$C$2:$C$500)=UPPER(A22))*(UPPER(Cobranza!$W$2:$W$500)="C")*(UPPER(Cobranza!$Y$2:$Y$500)="Y")*(Cobranza!$T$2:$T$500)) -> 122 | E22: =C22-D22 -> 0 | G22: =IF(OR(D22=C22), 0, 1) -> 0 | J22: La diferencia entre:
A23: T | B23: =TRIM(UPPER(A23)) -> T | C23: =SUMIF(Reporte!$F$2:$F$632, 'Yape por MZ'!A23, Reporte!$E$2:$E$632) -> 340.5 | D23: =SUMPRODUCT((UPPER(Cobranza!$C$2:$C$500)=UPPER(A23))*(UPPER(Cobranza!$W$2:$W$500)="C")*(UPPER(Cobranza!$Y$2:$Y$500)="Y")*(Cobranza!$T$2:$T$500)) -> 340.5 | E23: =C23-D23 -> 0 | G23: =IF(OR(D23=C23), 0, 1) -> 0
A24: U | B24: =TRIM(UPPER(A24)) -> U | C24: =SUMIF(Reporte!$F$2:$F$632, 'Yape por MZ'!A24, Reporte!$E$2:$E$632) -> 50 | D24: =SUMPRODUCT((UPPER(Cobranza!$C$2:$C$500)=UPPER(A24))*(UPPER(Cobranza!$W$2:$W$500)="C")*(UPPER(Cobranza!$Y$2:$Y$500)="Y")*(Cobranza!$T$2:$T$500)) -> 50 | E24: =C24-D24 -> 0 | G24: =IF(OR(D24=C24), 0, 1) -> 0 | J24: Yape | K24: -82
A25: V | B25: =TRIM(UPPER(A25)) -> V | C25: =SUMIF(Reporte!$F$2:$F$632, 'Yape por MZ'!A25, Reporte!$E$2:$E$632) -> 171 | D25: =SUMPRODUCT((UPPER(Cobranza!$C$2:$C$500)=UPPER(A25))*(UPPER(Cobranza!$W$2:$W$500)="C")*(UPPER(Cobranza!$Y$2:$Y$500)="Y")*(Cobranza!$T$2:$T$500)) -> 171 | E25: =C25-D25 -> 0 | G25: =IF(OR(D25=C25), 0, 1) -> 0 | J25: Efectivo | K25: 40
A26: W | B26: =TRIM(UPPER(A26)) -> W | C26: =SUMIF(Reporte!$F$2:$F$632, 'Yape por MZ'!A26, Reporte!$E$2:$E$632) -> 262 | D26: =SUMPRODUCT((UPPER(Cobranza!$C$2:$C$500)=UPPER(A26))*(UPPER(Cobranza!$W$2:$W$500)="C")*(UPPER(Cobranza!$Y$2:$Y$500)="Y")*(Cobranza!$T$2:$T$500)) -> 262 | E26: =C26-D26 -> 0 | G26: =IF(OR(D26=C26), 0, 1) -> 0
A27: X | B27: =TRIM(UPPER(A27)) -> X | C27: =SUMIF(Reporte!$F$2:$F$632, 'Yape por MZ'!A27, Reporte!$E$2:$E$632) -> 157 | D27: =SUMPRODUCT((UPPER(Cobranza!$C$2:$C$500)=UPPER(A27))*(UPPER(Cobranza!$W$2:$W$500)="C")*(UPPER(Cobranza!$Y$2:$Y$500)="Y")*(Cobranza!$T$2:$T$500)) -> 157 | E27: =C27-D27 -> 0 | G27: =IF(OR(D27=C27), 0, 1) -> 0 | K27: =SUM(K24:K25) -> -42
A28: Y | B28: =TRIM(UPPER(A28)) -> Y | C28: =SUMIF(Reporte!$F$2:$F$632, 'Yape por MZ'!A28, Reporte!$E$2:$E$632) -> 87 | D28: =SUMPRODUCT((UPPER(Cobranza!$C$2:$C$500)=UPPER(A28))*(UPPER(Cobranza!$W$2:$W$500)="C")*(UPPER(Cobranza!$Y$2:$Y$500)="Y")*(Cobranza!$T$2:$T$500)) -> 87 | E28: =C28-D28 -> 0 | G28: =IF(OR(D28=C28), 0, 1) -> 0
A29: Z | B29: =TRIM(UPPER(A29)) -> Z | C29: =SUMIF(Reporte!$F$2:$F$632, 'Yape por MZ'!A29, Reporte!$E$2:$E$632) -> 125 | D29: =SUMPRODUCT((UPPER(Cobranza!$C$2:$C$500)=UPPER(A29))*(UPPER(Cobranza!$W$2:$W$500)="C")*(UPPER(Cobranza!$Y$2:$Y$500)="Y")*(Cobranza!$T$2:$T$500)) -> 133 | E29: =C29-D29 -> -8 | G29: =IF(OR(D29=C29), 0, 1) -> 1 | J29: Conclusion
A30: A1 | B30: =TRIM(UPPER(A30)) -> A1 | C30: =SUMIF(Reporte!$F$2:$F$632, 'Yape por MZ'!A30, Reporte!$E$2:$E$632) -> 50 | D30: =SUMPRODUCT((UPPER(Cobranza!$C$2:$C$500)=UPPER(A30))*(UPPER(Cobranza!$W$2:$W$500)="C")*(UPPER(Cobranza!$Y$2:$Y$500)="Y")*(Cobranza!$T$2:$T$500)) -> 50 | E30: =C30-D30 -> 0 | G30: =IF(OR(D30=C30), 0, 1) -> 0 | J30: Es producto al dinero que sobro el mes anterior | M30: 42
A31: B1 | B31: =TRIM(UPPER(A31)) -> B1 | C31: =SUMIF(Reporte!$F$2:$F$632, 'Yape por MZ'!A31, Reporte!$E$2:$E$632) -> 166 | D31: =SUMPRODUCT((UPPER(Cobranza!$C$2:$C$500)=UPPER(A31))*(UPPER(Cobranza!$W$2:$W$500)="C")*(UPPER(Cobranza!$Y$2:$Y$500)="Y")*(Cobranza!$T$2:$T$500)) -> 166 | E31: =C31-D31 -> 0 | G31: =IF(OR(D31=C31), 0, 1) -> 0 | J31: Y qu este mes se le devolvio al usuario | M31: -42
A32: C1 | B32: =TRIM(UPPER(A32)) -> C1 | C32: =SUMIF(Reporte!$F$2:$F$632, 'Yape por MZ'!A32, Reporte!$E$2:$E$632) -> 162 | D32: =SUMPRODUCT((UPPER(Cobranza!$C$2:$C$500)=UPPER(A32))*(UPPER(Cobranza!$W$2:$W$500)="C")*(UPPER(Cobranza!$Y$2:$Y$500)="Y")*(Cobranza!$T$2:$T$500)) -> 162 | E32: =C32-D32 -> 0 | G32: =IF(OR(D32=C32), 0, 1) -> 0
A33: D1 | B33: =TRIM(UPPER(A33)) -> D1 | C33: =SUMIF(Reporte!$F$2:$F$632, 'Yape por MZ'!A33, Reporte!$E$2:$E$632) -> 38 | D33: =SUMPRODUCT((UPPER(Cobranza!$C$2:$C$500)=UPPER(A33))*(UPPER(Cobranza!$W$2:$W$500)="C")*(UPPER(Cobranza!$Y$2:$Y$500)="Y")*(Cobranza!$T$2:$T$500)) -> 38 | E33: =C33-D33 -> 0 | G33: =IF(OR(D33=C33), 0, 1) -> 0
A34: E1 | B34: =TRIM(UPPER(A34)) -> E1 | C34: =SUMIF(Reporte!$F$2:$F$632, 'Yape por MZ'!A34, Reporte!$E$2:$E$632) -> 58 | D34: =SUMPRODUCT((UPPER(Cobranza!$C$2:$C$500)=UPPER(A34))*(UPPER(Cobranza!$W$2:$W$500)="C")*(UPPER(Cobranza!$Y$2:$Y$500)="Y")*(Cobranza!$T$2:$T$500)) -> 58 | E34: =C34-D34 -> 0 | G34: =IF(OR(D34=C34), 0, 1) -> 0
A35: F1 | B35: =TRIM(UPPER(A35)) -> F1 | C35: =SUMIF(Reporte!$F$2:$F$632, 'Yape por MZ'!A35, Reporte!$E$2:$E$632) -> 105 | D35: =SUMPRODUCT((UPPER(Cobranza!$C$2:$C$500)=UPPER(A35))*(UPPER(Cobranza!$W$2:$W$500)="C")*(UPPER(Cobranza!$Y$2:$Y$500)="Y")*(Cobranza!$T$2:$T$500)) -> 105 | E35: =C35-D35 -> 0 | G35: =IF(OR(D35=C35), 0, 1) -> 0
A36: G1 | B36: =TRIM(UPPER(A36)) -> G1 | C36: =SUMIF(Reporte!$F$2:$F$632, 'Yape por MZ'!A36, Reporte!$E$2:$E$632) -> 68 | D36: =SUMPRODUCT((UPPER(Cobranza!$C$2:$C$500)=UPPER(A36))*(UPPER(Cobranza!$W$2:$W$500)="C")*(UPPER(Cobranza!$Y$2:$Y$500)="Y")*(Cobranza!$T$2:$T$500)) -> 68 | E36: =C36-D36 -> 0 | G36: =IF(OR(D36=C36), 0, 1) -> 0
A37: H1 | B37: =TRIM(UPPER(A37)) -> H1 | C37: =SUMIF(Reporte!$F$2:$F$632, 'Yape por MZ'!A37, Reporte!$E$2:$E$632) -> 218 | D37: =SUMPRODUCT((UPPER(Cobranza!$C$2:$C$501)=UPPER(A37))*(UPPER(Cobranza!$W$2:$W$501)="C")*(UPPER(Cobranza!$Y$2:$Y$501)="Y")*(Cobranza!$T$2:$T$501)) -> 218 | E37: =C37-D37 -> 0 | G37: =IF(OR(D37=C37), 0, 1) -> 0
C39: =SUM(C4:C37) -> 8571.5 | D39: =SUM(D4:D37) -> 8654.5 | E39: =SUM(E4:E37) -> -83
E40: =C39-D39 -> -83
A43: Efectivo por Manzana
A45: Mnz | B45: Llave1 | C45: Efectivo-M | D45: Planilla-A | E45: Saldos | F45: Comentario
A46: A | B46: =TRIM(UPPER(A46)) -> A | C46: =SUMIF(Efectivo!$A$2:$A$333, 'Yape por MZ'!A46, Efectivo!$C$2:$C$333) -> 119 | D46: =SUMPRODUCT((UPPER(Cobranza!$C$2:$C$500)=UPPER(B46))*(UPPER(Cobranza!$W$2:$W$500)="C")*(UPPER(Cobranza!$Y$2:$Y$500)<>"Y")*(Cobranza!$V$2:$V$500)) -> 44 | E46: =C46-D46 -> 75 | F46: A1. Esta en el yape. Dice que ya pago 25 anteriormente y no debe convenio. | G46: =IF(OR(D46=C46), 0, 1) -> 1
A47: B | B47: =TRIM(UPPER(A47)) -> B | C47: =SUMIF(Efectivo!$A$2:$A$333, 'Yape por MZ'!A47, Efectivo!$C$2:$C$333) -> 304 | D47: =SUMPRODUCT((UPPER(Cobranza!$C$2:$C$500)=UPPER(B47))*(UPPER(Cobranza!$W$2:$W$500)="C")*(UPPER(Cobranza!$Y$2:$Y$500)<>"Y")*(Cobranza!$V$2:$V$500)) -> 304 | E47: =C47-D47 -> 0 | G47: =IF(OR(D47=C47), 0, 1) -> 0
A48: C | B48: =TRIM(UPPER(A48)) -> C | C48: =SUMIF(Efectivo!$A$2:$A$333, 'Yape por MZ'!A48, Efectivo!$C$2:$C$333) -> 314 | D48: =SUMPRODUCT((UPPER(Cobranza!$C$2:$C$500)=UPPER(B48))*(UPPER(Cobranza!$W$2:$W$500)="C")*(UPPER(Cobranza!$Y$2:$Y$500)<>"Y")*(Cobranza!$V$2:$V$500)) -> 314 | E48: =C48-D48 -> 0 | G48: =IF(OR(D48=C48), 0, 1) -> 0
A49: D | B49: =TRIM(UPPER(A49)) -> D | C49: =SUMIF(Efectivo!$A$2:$A$333, 'Yape por MZ'!A49, Efectivo!$C$2:$C$333) -> 97 | D49: =SUMPRODUCT((UPPER(Cobranza!$C$2:$C$500)=UPPER(B49))*(UPPER(Cobranza!$W$2:$W$500)="C")*(UPPER(Cobranza!$Y$2:$Y$500)<>"Y")*(Cobranza!$V$2:$V$500)) -> 97 | E49: =C49-D49 -> 0 | G49: =IF(OR(D49=C49), 0, 1) -> 0
...

Sheet Reporte
A1: Tipo de Transacción | B1: Origen | C1: Destino | D1: Monto | E1: Valor | F1: mz | G1: lt | H1: Llave | I1: Mensaje | J1: Fecha de operación | K1: Año | L1: Mes | M1: Dia | N1: Hora
A2: PAGASTE | B2: Janet Vil* | C2: Janet Vil* | D2: 171.00 | E2: =-VALUE(SUBSTITUTE(D2, ".", ",")) -> -171 | I2: compra de cloro | J2: 09/05/2026 12:35:32 | K2: =MID(J2,7,4) -> 2026 | L2: =MID(J2,4,2) -> 05 | M2: =LEFT(J2,2) -> 09 | N2: =RIGHT(J2,8) -> 12:35:32
A3: PAGASTE | B3: Janet Vil* | C3: Wilder Tru* | D3: 300.00 | E3: =-VALUE(SUBSTITUTE(D3, ".", ",")) -> -300 | I3: apoyo de la jass | J3: 09/05/2026 11:39:20 | K3: =MID(J3,7,4) -> 2026 | L3: =MID(J3,4,2) -> 05 | M3: =LEFT(J3,2) -> 09 | N3: =RIGHT(J3,8) -> 11:39:20
A4: TE PAGÓ | B4: Nelly Mor* | C4: Janet Vil* | D4: 8.00 | E4: =VALUE(SUBSTITUTE(D4, ".", ",")) -> 8 | F4: blanco | H4: =TRIM(UPPER(F4)) & "-" & TRIM(UPPER(G4)) -> BLANCO- | J4: 08/05/2026 10:35:55 | K4: =MID(J4,7,4) -> 2026 | L4: =MID(J4,4,2) -> 05 | M4: =LEFT(J4,2) -> 08 | N4: =RIGHT(J4,8) -> 10:35:55
A5: TE PAGÓ | B5: Nelly Mor* | C5: Janet Vil* | D5: 22.00 | E5: =VALUE(SUBSTITUTE(D5, ".", ",")) -> 22 | F5: blanco | H5: =TRIM(UPPER(F5)) & "-" & TRIM(UPPER(G5)) -> BLANCO- | J5: 08/05/2026 10:35:18 | K5: =MID(J5,7,4) -> 2026 | L5: =MID(J5,4,2) -> 05 | M5: =LEFT(J5,2) -> 08 | N5: =RIGHT(J5,8) -> 10:35:18
A6: TE PAGÓ | B6: Violeta Cau* | C6: Janet Vil* | D6: 35.00 | E6: =VALUE(SUBSTITUTE(D6, ".", ",")) -> 35 | F6: D | G6: 9 | H6: =TRIM(UPPER(F6)) & "-" & TRIM(UPPER(G6)) -> D-9 | I6: Mz D lote 9 | J6: 08/05/2026 10:06:11 | K6: =MID(J6,7,4) -> 2026 | L6: =MID(J6,4,2) -> 05 | M6: =LEFT(J6,2) -> 08 | N6: =RIGHT(J6,8) -> 10:06:11
A7: TE PAGÓ | B7: Adolfo Ros* | C7: Janet Vil* | D7: 19.00 | E7: =VALUE(SUBSTITUTE(D7, ".", ",")) -> 19 | F7: I | G7: 16 | H7: =TRIM(UPPER(F7)) & "-" & TRIM(UPPER(G7)) -> I-16 | I7: Adolfo Rosario Rojas, MZ.1, Lt. 16 de los dos meses | J7: 08/05/2026 08:20:08 | K7: =MID(J7,7,4) -> 2026 | L7: =MID(J7,4,2) -> 05 | M7: =LEFT(J7,2) -> 08 | N7: =RIGHT(J7,8) -> 08:20:08
A8: TE PAGÓ | B8: Camile Hid* | C8: Janet Vil* | D8: 45.00 | E8: =VALUE(SUBSTITUTE(D8, ".", ",")) -> 45 | F8: B | G8: 21 | H8: =TRIM(UPPER(F8)) & "-" & TRIM(UPPER(G8)) -> B-21 | J8: 07/05/2026 18:05:28 | K8: =MID(J8,7,4) -> 2026 | L8: =MID(J8,4,2) -> 05 | M8: =LEFT(J8,2) -> 07 | N8: =RIGHT(J8,8) -> 18:05:28
A9: TE PAGÓ | B9: PLIN - Vilma Norma Celestino Villafana | C9: JANET VILLANUEVA ALEGRIA | D9: 41.00 | E9: =VALUE(SUBSTITUTE(D9, ".", ",")) -> 41 | F9: J | G9: 3 | H9: =TRIM(UPPER(F9)) & "-" & TRIM(UPPER(G9)) -> J-3 | J9: 07/05/2026 13:17:23 | K9: =MID(J9,7,4) -> 2026 | L9: =MID(J9,4,2) -> 05 | M9: =LEFT(J9,2) -> 07 | N9: =RIGHT(J9,8) -> 13:17:23
A10: TE PAGÓ | B10: Julio Hue* | C10: Janet Vil* | D10: 63.00 | E10: =VALUE(SUBSTITUTE(D10, ".", ",")) -> 63 | F10: B | G10: 17 | H10: =TRIM(UPPER(F10)) & "-" & TRIM(UPPER(G10)) -> B-17 | J10: 06/05/2026 21:37:25 | K10: =MID(J10,7,4) -> 2026 | L10: =MID(J10,4,2) -> 05 | M10: =LEFT(J10,2) -> 06 | N10: =RIGHT(J10,8) -> 21:37:25
A11: TE PAGÓ | B11: Victor Sol* | C11: Janet Vil* | D11: 65.00 | E11: =VALUE(SUBSTITUTE(D11, ".", ",")) -> 65 | F11: P | G11: 11 | H11: =TRIM(UPPER(F11)) & "-" & TRIM(UPPER(G11)) -> P-11 | J11: 06/05/2026 21:20:42 | K11: =MID(J11,7,4) -> 2026 | L11: =MID(J11,4,2) -> 05 | M11: =LEFT(J11,2) -> 06 | N11: =RIGHT(J11,8) -> 21:20:42
A12: TE PAGÓ | B12: Jessica Mor* | C12: Janet Vil* | D12: 20.00 | E12: =VALUE(SUBSTITUTE(D12, ".", ",")) -> 20 | F12: Q | G12: 12 | H12: =TRIM(UPPER(F12)) & "-" & TRIM(UPPER(G12)) -> Q-12 | I12: MZ.Q LT 12 | J12: 06/05/2026 15:55:48 | K12: =MID(J12,7,4) -> 2026 | L12: =MID(J12,4,2) -> 05 | M12: =LEFT(J12,2) -> 06 | N12: =RIGHT(J12,8) -> 15:55:48
A13: TE PAGÓ | B13: Rosmery San* | C13: Janet Vil* | D13: 38.00 | E13: =VALUE(SUBSTITUTE(D13, ".", ",")) -> 38 | F13: B | G13: 12A | H13: =TRIM(UPPER(F13)) & "-" & TRIM(UPPER(G13)) -> B-12A | I13: mz.b lt.12 rosmery sanchez | J13: 06/05/2026 14:50:50 | K13: =MID(J13,7,4) -> 2026 | L13: =MID(J13,4,2) -> 05 | M13: =LEFT(J13,2) -> 06 | N13: =RIGHT(J13,8) -> 14:50:50
A14: TE PAGÓ | B14: Leslye Bur* | C14: Janet Vil* | D14: 20.00 | E14: =VALUE(SUBSTITUTE(D14, ".", ",")) -> 20 | F14: H1 | G14: 10 | H14: =TRIM(UPPER(F14)) & "-" & TRIM(UPPER(G14)) -> H1-10 | I14: felicia zapata Mz h1 Lt 10 | J14: 06/05/2026 11:34:56 | K14: =MID(J14,7,4) -> 2026 | L14: =MID(J14,4,2) -> 05 | M14: =LEFT(J14,2) -> 06 | N14: =RIGHT(J14,8) -> 11:34:56
A15: PAGASTE | B15: Janet Vil* | C15: Juana Coc* | D15: 95.00 | E15: =-VALUE(SUBSTITUTE(D15, ".", ",")) -> -95 | I15: compartir en la posta (supervisión) | J15: 06/05/2026 07:24:35 | K15: =MID(J15,7,4) -> 2026 | L15: =MID(J15,4,2) -> 05 | M15: =LEFT(J15,2) -> 06 | N15: =RIGHT(J15,8) -> 07:24:35
A16: TE PAGÓ | B16: Carmen Lop* | C16: Janet Vil* | D16: 11.00 | E16: =VALUE(SUBSTITUTE(D16, ".", ",")) -> 11 | F16: L | G16: 13 | H16: =TRIM(UPPER(F16)) & "-" & TRIM(UPPER(G16)) -> L-13 | I16: MARIA ROSITA HUACANCA HUAROMA ( Mz L Lt 13 ) | J16: 05/05/2026 17:59:10 | K16: =MID(J16,7,4) -> 2026 | L16: =MID(J16,4,2) -> 05 | M16: =LEFT(J16,2) -> 05 | N16: =RIGHT(J16,8) -> 17:59:10
A17: TE PAGÓ | B17: Leslye Bur* | C17: Janet Vil* | D17: 16.00 | E17: =VALUE(SUBSTITUTE(D17, ".", ",")) -> 16 | F17: H1 | G17: 10 | H17: =TRIM(UPPER(F17)) & "-" & TRIM(UPPER(G17)) -> H1-10 | I17: felicia zapata Mz h1 Lt 10 | J17: 05/05/2026 17:37:37 | K17: =MID(J17,7,4) -> 2026 | L17: =MID(J17,4,2) -> 05 | M17: =LEFT(J17,2) -> 05 | N17: =RIGHT(J17,8) -> 17:37:37
A18: TE PAGÓ | B18: Juana Bau* | C18: Janet Vil* | D18: 17.00 | E18: =VALUE(SUBSTITUTE(D18, ".", ",")) -> 17 | F18: T | G18: 19 | H18: =TRIM(UPPER(F18)) & "-" & TRIM(UPPER(G18)) -> T-19 | I18: Miguel Ángel romero valladares MZ T lote 19 | J18: 05/05/2026 16:42:49 | K18: =MID(J18,7,4) -> 2026 | L18: =MID(J18,4,2) -> 05 | M18: =LEFT(J18,2) -> 05 | N18: =RIGHT(J18,8) -> 16:42:49
A19: TE PAGÓ | B19: Elizabeth Hue* | C19: Janet Vil* | D19: 41.00 | E19: =VALUE(SUBSTITUTE(D19, ".", ",")) -> 41 | F19: A | G19: 4 | H19: =TRIM(UPPER(F19)) & "-" & TRIM(UPPER(G19)) -> A-4 | I19: yolanda Espinoza JAIMES | J19: 05/05/2026 16:35:28 | K19: =MID(J19,7,4) -> 2026 | L19: =MID(J19,4,2) -> 05 | M19: =LEFT(J19,2) -> 05 | N19: =RIGHT(J19,8) -> 16:35:28
A20: TE PAGÓ | B20: Jose Mel* | C20: Janet Vil* | D20: 51.00 | E20: =VALUE(SUBSTITUTE(D20, ".", ",")) -> 51 | F20: A | G20: 9 | H20: =TRIM(UPPER(F20)) & "-" & TRIM(UPPER(G20)) -> A-9 | I20: pago de agua, usuario Alejandro Melgarejo. Mz A Lt | J20: 05/05/2026 15:40:40 | K20: =MID(J20,7,4) -> 2026 | L20: =MID(J20,4,2) -> 05 | M20: =LEFT(J20,2) -> 05 | N20: =RIGHT(J20,8) -> 15:40:40
A21: TE PAGÓ | B21: Erika Amb* | C21: Janet Vil* | D21: 10.00 | E21: =VALUE(SUBSTITUTE(D21, ".", ",")) -> 10 | F21: A1 | G21: 8 | H21: =TRIM(UPPER(F21)) & "-" & TRIM(UPPER(G21)) -> A1-8 | I21: Mz.A1 lt .8 | J21: 05/05/2026 07:51:48 | K21: =MID(J21,7,4) -> 2026 | L21: =MID(J21,4,2) -> 05 | M21: =LEFT(J21,2) -> 05 | N21: =RIGHT(J21,8) -> 07:51:48
A22: TE PAGÓ | B22: Milagros Sig* | C22: Janet Vil* | D22: 16.00 | E22: =VALUE(SUBSTITUTE(D22, ".", ",")) -> 16 | F22: Z | G22: 13 | H22: =TRIM(UPPER(F22)) & "-" & TRIM(UPPER(G22)) -> Z-13 | J22: 04/05/2026 16:32:03 | K22: =MID(J22,7,4) -> 2026 | L22: =MID(J22,4,2) -> 05 | M22: =LEFT(J22,2) -> 04 | N22: =RIGHT(J22,8) -> 16:32:03
A23: TE PAGÓ | B23: Luis Rio* | C23: Janet Vil* | D23: 42.00 | E23: =VALUE(SUBSTITUTE(D23, ".", ",")) -> 42 | F23: C | G23: 14 | H23: =TRIM(UPPER(F23)) & "-" & TRIM(UPPER(G23)) -> C-14 | I23: mz C lote 14 | J23: 04/05/2026 09:59:15 | K23: =MID(J23,7,4) -> 2026 | L23: =MID(J23,4,2) -> 05 | M23: =LEFT(J23,2) -> 04 | N23: =RIGHT(J23,8) -> 09:59:15
A24: TE PAGÓ | B24: Junior Tru* | C24: Janet Vil* | D24: 20.00 | E24: =VALUE(SUBSTITUTE(D24, ".", ",")) -> 20 | F24: V | G24: 9 | H24: =TRIM(UPPER(F24)) & "-" & TRIM(UPPER(G24)) -> V-9 | I24: Mz. V lt. 9 Norma vega | J24: 04/05/2026 09:46:00 | K24: =MID(J24,7,4) -> 2026 | L24: =MID(J24,4,2) -> 05 | M24: =LEFT(J24,2) -> 04 | N24: =RIGHT(J24,8) -> 09:46:00
A25: TE PAGÓ | B25: Jessica Mor* | C25: Janet Vil* | D25: 43.00 | E25: =VALUE(SUBSTITUTE(D25, ".", ",")) -> 43 | F25: Q | G25: 12 | H25: =TRIM(UPPER(F25)) & "-" & TRIM(UPPER(G25)) -> Q-12 | J25: 04/05/2026 08:33:12 | K25: =MID(J25,7,4) -> 2026 | L25: =MID(J25,4,2) -> 05 | M25: =LEFT(J25,2) -> 04 | N25: =RIGHT(J25,8) -> 08:33:12
A26: TE PAGÓ | B26: BCP - MONTALVO JULCA FABIAN FELIPE | C26: JANET VILLANUEVA ALEGRIA | D26: 110.00 | E26: =VALUE(SUBSTITUTE(D26, ".", ",")) -> 110 | F26: K | G26: 15 | H26: =TRIM(UPPER(F26)) & "-" & TRIM(UPPER(G26)) -> K-15 | I26: Calle Bolognesi Mz. K LT.15 | J26: 04/05/2026 06:56:43 | K26: =MID(J26,7,4) -> 2026 | L26: =MID(J26,4,2) -> 05 | M26: =LEFT(J26,2) -> 04 | N26: =RIGHT(J26,8) -> 06:56:43
A27: TE PAGÓ | B27: Eloy Sig* | C27: Janet Vil* | D27: 50.00 | E27: =VALUE(SUBSTITUTE(D27, ".", ",")) -> 50 | F27: L | G27: 10 | H27: =TRIM(UPPER(F27)) & "-" & TRIM(UPPER(G27)) -> L-10 | I27: eloy sigueñas ugarte mz: L lote:10 | J27: 03/05/2026 21:24:26 | K27: =MID(J27,7,4) -> 2026 | L27: =MID(J27,4,2) -> 05 | M27: =LEFT(J27,2) -> 03 | N27: =RIGHT(J27,8) -> 21:24:26
A28: TE PAGÓ | B28: Alberto Rod* | C28: Janet Vil* | D28: 41.00 | E28: =VALUE(SUBSTITUTE(D28, ".", ",")) -> 41 | F28: H | G28: 9 | H28: =TRIM(UPPER(F28)) & "-" & TRIM(UPPER(G28)) -> H-9 | I28: Mz H lote9 Clemente Rodriguez Rojas | J28: 03/05/2026 20:44:22 | K28: =MID(J28,7,4) -> 2026 | L28: =MID(J28,4,2) -> 05 | M28: =LEFT(J28,2) -> 03 | N28: =RIGHT(J28,8) -> 20:44:22
A29: TE PAGÓ | B29: Melissa Pil* | C29: Janet Vil* | D29: 19.00 | E29: =VALUE(SUBSTITUTE(D29, ".", ",")) -> 19 | F29: B | G29: 15 | H29: =TRIM(UPPER(F29)) & "-" & TRIM(UPPER(G29)) -> B-15 | I29: MZB LT15 Melissa Pillaca | J29: 03/05/2026 20:03:26 | K29: =MID(J29,7,4) -> 2026 | L29: =MID(J29,4,2) -> 05 | M29: =LEFT(J29,2) -> 03 | N29: =RIGHT(J29,8) -> 20:03:26
A30: TE PAGÓ | B30: Ditmar Dia* | C30: Janet Vil* | D30: 25.00 | E30: =VALUE(SUBSTITUTE(D30, ".", ",")) -> 25 | F30: S | G30: 2 | H30: =TRIM(UPPER(F30)) & "-" & TRIM(UPPER(G30)) -> S-2 | I30: MZ. S lote 02 Miriam Diaz | J30: 03/05/2026 19:40:34 | K30: =MID(J30,7,4) -> 2026 | L30: =MID(J30,4,2) -> 05 | M30: =LEFT(J30,2) -> 03 | N30: =RIGHT(J30,8) -> 19:40:34
A31: TE PAGÓ | B31: Ani Cru* | C31: Janet Vil* | D31: 8.00 | E31: =VALUE(SUBSTITUTE(D31, ".", ",")) -> 8 | F31: F1 | G31: 2 | H31: =TRIM(UPPER(F31)) & "-" & TRIM(UPPER(G31)) -> F1-2 | I31: mz F1_lote 2 | J31: 03/05/2026 18:56:56 | K31: =MID(J31,7,4) -> 2026 | L31: =MID(J31,4,2) -> 05 | M31: =LEFT(J31,2) -> 03 | N31: =RIGHT(J31,8) -> 18:56:56
A32: TE PAGÓ | B32: Pool Cal* | C32: Janet Vil* | D32: 8.00 | E32: =VALUE(SUBSTITUTE(D32, ".", ",")) -> 8 | F32: D1 | G32: 2 | H32: =TRIM(UPPER(F32)) & "-" & TRIM(UPPER(G32)) -> D1-2 | I32: Elami Azucena Ulloa olivo MZ: D1 LT:2 | J32: 03/05/2026 18:44:29 | K32: =MID(J32,7,4) -> 2026 | L32: =MID(J32,4,2) -> 05 | M32: =LEFT(J32,2) -> 03 | N32: =RIGHT(J32,8) -> 18:44:29
A33: TE PAGÓ | B33: Magda Bla* | C33: Janet Vil* | D33: 34.00 | E33: =VALUE(SUBSTITUTE(D33, ".", ",")) -> 34 | F33: M | G33: 14 | H33: =TRIM(UPPER(F33)) & "-" & TRIM(UPPER(G33)) -> M-14 | I33: Mz M lote 14 | J33: 03/05/2026 16:15:51 | K33: =MID(J33,7,4) -> 2026 | L33: =MID(J33,4,2) -> 05 | M33: =LEFT(J33,2) -> 03 | N33: =RIGHT(J33,8) -> 16:15:51
A34: TE PAGÓ | B34: Walter Sol* | C34: Janet Vil* | D34: 8.00 | E34: =VALUE(SUBSTITUTE(D34, ".", ",")) -> 8 | F34: S | G34: 8 | H34: =TRIM(UPPER(F34)) & "-" & TRIM(UPPER(G34)) -> S-8 | I34: s 8 Solorzano Melgarejo Walter | J34: 03/05/2026 16:09:12 | K34: =MID(J34,7,4) -> 2026 | L34: =MID(J34,4,2) -> 05 | M34: =LEFT(J34,2) -> 03 | N34: =RIGHT(J34,8) -> 16:09:12
A35: TE PAGÓ | B35: Walter Sol* | C35: Janet Vil* | D35: 22.00 | E35: =VALUE(SUBSTITUTE(D35, ".", ",")) -> 22 | F35: I | G35: 13 | H35: =TRIM(UPPER(F35)) & "-" & TRIM(UPPER(G35)) -> I-13 | I35: i 13 solorzano estrada julio | J35: 03/05/2026 16:07:30 | K35: =MID(J35,7,4) -> 2026 | L35: =MID(J35,4,2) -> 05 | M35: =LEFT(J35,2) -> 03 | N35: =RIGHT(J35,8) -> 16:07:30
A36: TE PAGÓ | B36: Janet Vil* | C36: Janet Vil* | D36: 8.00 | E36: =VALUE(SUBSTITUTE(D36, ".", ",")) -> 8 | F36: V | G36: 2 | H36: =TRIM(UPPER(F36)) & "-" & TRIM(UPPER(G36)) -> V-2 | I36: mz V lt 2 | J36: 03/05/2026 15:26:55 | K36: =MID(J36,7,4) -> 2026 | L36: =MID(J36,4,2) -> 05 | M36: =LEFT(J36,2) -> 03 | N36: =RIGHT(J36,8) -> 15:26:55
A37: TE PAGÓ | B37: Janet Vil* | C37: Janet Vil* | D37: 8.00 | E37: =VALUE(SUBSTITUTE(D37, ".", ",")) -> 8 | F37: C1 | G37: 15 | H37: =TRIM(UPPER(F37)) & "-" & TRIM(UPPER(G37)) -> C1-15 | I37: mz C1 lt 15 | J37: 03/05/2026 15:26:18 | K37: =MID(J37,7,4) -> 2026 | L37: =MID(J37,4,2) -> 05 | M37: =LEFT(J37,2) -> 03 | N37: =RIGHT(J37,8) -> 15:26:18
